Workbook

Sheet BOM list
B2: Item | C2: Top | D2: Down | E2: P/N | F2: 판매자 | G2: Maker | H2: 단가 | I2: 합계 | J2: 납기일정 | K2: 납품일 | L2: 납품수량 | M2: Remarks
B3: 1 | C3: MOP | E3: RES14001BS0
D4: =MOP!D3 -> Main Frame | E4: =MOP!E3 -> R1C001384 | F4: =MOP!N3 -> 세일엔지니어링 | G4: =MOP!O3 -> 세일엔지니어링 | H4: =MOP!L3 -> 440100 | I4: =MOP!M3 -> 22445100
D5: =MOP!D4 -> Left Cover | E5: =MOP!E4 -> R1C001385 | F5: =MOP!N4 -> 세일엔지니어링 | G5: =MOP!O4 -> 세일엔지니어링 | H5: =MOP!L4 -> - | I5: =MOP!M4 -> -
D6: =MOP!D5 -> Right Cover | E6: =MOP!E5 -> R1C001386 | F6: =MOP!N5 -> 세일엔지니어링 | G6: =MOP!O5 -> 세일엔지니어링 | H6: =MOP!L5 -> - | I6: =MOP!M5 -> -
D7: =MOP!D6 -> Upper Cover | E7: =MOP!E6 -> R1C001387 | F7: =MOP!N6 -> 세일엔지니어링 | G7: =MOP!O6 -> 세일엔지니어링 | H7: =MOP!L6 -> - | I7: =MOP!M6 -> -
D8: =MOP!D7 -> Lower Cover | E8: =MOP!E7 -> R1B002159 | F8: =MOP!N7 -> 세일엔지니어링 | G8: =MOP!O7 -> 세일엔지니어링 | H8: =MOP!L7 -> - | I8: =MOP!M7 -> -
D9: =MOP!D8 -> Rear Cover | E9: =MOP!E8 -> R1B002160 | F9: =MOP!N8 -> 세일엔지니어링 | G9: =MOP!O8 -> 세일엔지니어링 | H9: =MOP!L8 -> - | I9: =MOP!M8 -> -
D10: =MOP!D9 -> Push Button | E10: =MOP!E9 -> 84-1201.7 | F10: =MOP!N9 -> 아이닉스 | G10: =MOP!O9 -> EAO | H10: =MOP!L9 -> 28800 | I10: =MOP!M9 -> 6336000
D11: =MOP!D10 -> Push Button | E11: =MOP!E10 -> 84-7111.200 | F11: =MOP!N10 -> 아이닉스 | G11: =MOP!O10 -> EAO | H11: =MOP!L10 -> 4650 | I11: =MOP!M10 -> 1023000
D12: =MOP!D11 -> Push Button | E12: =MOP!E11 -> 84-8511.2320 | F12: =MOP!N11 -> 아이닉스 | G12: =MOP!O11 -> EAO | H12: =MOP!L11 -> 39000 | I12: =MOP!M11 -> 8580000
D13: =MOP!D12 -> Microphone | E13: =MOP!E12 -> KCM-30(55 JACK) | F13: =MOP!N12 -> 아이닉스 | G13: =MOP!O12 -> REAN | H13: =MOP!L12 -> 2800 | I13: =MOP!M12 -> 154000 | J13: 45497 | K13: 45497 | L13: 55EA
D14: =MOP!D13 -> LCD | E14: =MOP!E13 -> "HL035T002T-02(단종) HL035T11-01 + RTC" | F14: =MOP!N13 -> 티렉스아이엔씨 | G14: =MOP!O13 -> Shenzhen | H14: =MOP!L13 -> 23000 | I14: =MOP!M13 -> 1380000 | J14: 45503
D15: =MOP!D14 -> LCD Mount Bracket | E15: =MOP!E14 -> R1D005930 | F15: =MOP!N14 -> 세일엔지니어링 | G15: =MOP!O14 -> 세일엔지니어링 | H15: =MOP!L14 -> - | I15: =MOP!M14 -> -
D16: =MOP!D15 -> LCD Control Board | E16: =MOP!E15 -> R1C001402 Rev.1 | F16: =MOP!N15 -> BEUPSYS | G16: =MOP!O15 -> BEUPSYS | H16: =MOP!L15 -> 425213 | I16: =MOP!M15 -> 21685863
D17: =MOP!D16 -> Main Control Board | E17: =MOP!E16 -> R1C001388 | F17: =MOP!N16 -> BEUPSYS | G17: =MOP!O16 -> BEUPSYS | H17: =MOP!L16 -> 473650 | I17: =MOP!M16 -> 24156150
D18: =MOP!D17 -> Power Board | E18: =MOP!E17 -> R1C001574 | F18: =MOP!N17 -> 이지파워 | G18: =MOP!O17 -> 이지파워 | H18: =MOP!L17 -> 89000 | I18: =MOP!M17 -> 4539000
D19: =MOP!D18 -> 3P Connector Male | E19: =MOP!E18 -> 770-213 | F19: =MOP!N18 -> 아이닉스 | G19: =MOP!O18 -> WAGO | H19: =MOP!L18 -> 2800 | I19: =MOP!M18 -> 154000 | J19: 45497 | K19: 45497 | L19: 55EA
D20: =MOP!D19 -> 3P Connector Female | E20: =MOP!E19 -> 770-293 | F20: =MOP!N19 -> 아이닉스 | G20: =MOP!O19 -> WAGO | H20: =MOP!L19 -> 4250 | I20: =MOP!M19 -> 233750 | M20: 추가 진행 필요
D21: =MOP!D20 -> Locking | E21: =MOP!E20 -> 770-101 | F21: =MOP!N20 -> 아이닉스 | G21: =MOP!O20 -> WAGO | H21: =MOP!L20 -> 350 | I21: =MOP!M20 -> 19250 | J21: 45497 | K21: 45497 | L21: 55EA
D22: =MOP!D21 -> 4P Connector | E22: =MOP!E21 -> 21 03 882 2405 | F22: =MOP!N21 -> 아이닉스 | G22: =MOP!O21 -> HARTING | H22: =MOP!L21 -> 32300 | I22: =MOP!M21 -> 1776500 | J22: 45497 | K22: 45497 | L22: 55EA
D23: =MOP!D22 -> Pin | E23: =MOP!E22 -> 09 67 000 5476 | F23: =MOP!N22 -> 아이닉스 | G23: =MOP!O22 -> HARTING | H23: =MOP!L22 -> 1300 | I23: =MOP!M22 -> 286000 | J23: 45497 | K23: 45497 | L23: 55EA
D24: =MOP!D23 -> 12P Connector | E24: =MOP!E23 -> UTG11412S | F24: =MOP!N23 -> 아이닉스 | G24: =MOP!O23 -> SOURIAU | H24: =MOP!L23 -> 23900 | I24: =MOP!M23 -> 1195000 | J24: 45497 | K24: 45497 | L24: 55EA
D25: =MOP!D24 -> Pin | E25: =MOP!E24 -> RC16M23K | F25: =MOP!N24 -> 아이닉스 | G25: =MOP!O24 -> SOURIAU | H25: =MOP!L24 -> 1250 | I25: =MOP!M24 -> 750000 | J25: 45497 | K25: 45497 | L25: 55EA
D26: =MOP!D25 -> Cable Clamp | E26: =MOP!E25 -> UTG14AC | F26: =MOP!N25 -> 아이닉스 | G26: =MOP!O25 -> SOURIAU | H26: =MOP!L25 -> 12000 | I26: =MOP!M25 -> 660000 | J26: 45497 | K26: 45497 | L26: 55EA
D27: =MOP!D26 -> Name Plate, AL, T1 | E27: =MOP!E26 -> R1C001342_6 | F27: =MOP!N26 -> - | G27: =MOP!O26 -> - | H27: =MOP!L26 -> - | I27: =MOP!M26 -> -
D28: =MOP!D27 -> SPEAKER | E28: =MOP!E27 -> PMB4070N-0240 / 8 Ω 5W | F28: =MOP!N27 -> 아이닉스 | G28: =MOP!O27 -> - | H28: =MOP!L27 -> 4800 | I28: =MOP!M27 -> 264000 | M28: 추가 진행 필요
D30: 내부 하네스 자재 | F30: 아이닉스 | G30: 아이닉스 | I30: =MOP!M51 -> 112860 | J30: 45497 | K30: 45497
B31: 2 | C31: MSR | E31: RES13001BS0
D32: =MSR!D3 -> PWR Board | E32: =MSR!E3 -> R1C001323 | F32: =MSR!N3 -> 이지파워 | G32: =MSR!O3 -> 이지파워 | H32: =MSR!L3 -> 136000 | I32: =MSR!M3 -> 6936000
D33: =MSR!D4 -> M_TX Board | E33: =MSR!E4 -> R1B002190 | F33: =MSR!N4 -> BEUPSYS | G33: =MSR!O4 -> BEUPSYS | H33: =MSR!L4 -> 610566 | I33: =MSR!M4 -> 31138866
D34: =MSR!D5 -> Hub Board | E34: =MSR!E5 -> R1B002192 | F34: =MSR!N5 -> BEUPSYS | G34: =MSR!O5 -> BEUPSYS | H34: =MSR!L5 -> 664363 | I34: =MSR!M5 -> 33882513
D35: =MSR!D6 -> TCIU Board | E35: =MSR!E6 -> R1B002187 | F35: =MSR!N6 -> BEUPSYS | G35: =MSR!O6 -> BEUPSYS | H35: =MSR!L6 -> 1129222 | I35: =MSR!M6 -> 57590322
D36: =MSR!D7 -> PA_PBX Board | E36: =MSR!E7 -> R1B002188 | F36: =MSR!N7 -> BEUPSYS | G36: =MSR!O7 -> BEUPSYS | H36: =MSR!L7 -> 289000 | I36: =MSR!M7 -> 14739000
D37: =MSR!D8 -> PA_ETX Board | E37: =MSR!E8 -> R1B002189 | F37: =MSR!N8 -> BEUPSYS | G37: =MSR!O8 -> BEUPSYS | H37: =MSR!L8 -> 474791 | I37: =MSR!M8 -> 24214341
D38: =MSR!D9 -> NVR Board | E38: =MSR!E9 -> R1B002193 Rev.1 | F38: =MSR!N9 -> BEUPSYS | G38: =MSR!O9 -> BEUPSYS | H38: 913923 | I38: =MSR!M9 -> 46610073 | L38: 51
D39: =MSR!D10 -> CPU TC170/i5-6300U | E39: =MSR!E10 -> - | F39: =MSR!N10 -> 이엔엠테크놀로지 | G39: =MSR!O10 -> CONGA | H39: =MSR!L10 -> 763 | I39: =MSR!M10 -> 45780
D40: =MSR!D11 -> CPU BRACKET TC170/CSP-B | E40: =MSR!E11 -> - | F40: =MSR!N11 -> 이엔엠테크놀로지 | G40: =MSR!O11 -> CONGA | H40: =MSR!L11 -> 43.3 | I40: =MSR!M11 -> 2598
D41: =MSR!D12 -> DDR4 (DDR4 4GB SODIMM 2400MT/S) | E41: =MSR!E12 -> - | F41: =MSR!N12 -> 이노디스크 | G41: =MSR!O12 -> 이노디스크 | H41: =MSR!L12 -> 36000 | I41: =MSR!M12 -> 2160000 | M41: 추가 진행 필요
D42: =MSR!D13 -> SSD Board | E42: =MSR!E13 -> R1B002191 | F42: =MSR!N13 -> BEUPSYS | G42: =MSR!O13 -> BEUPSYS | H42: =MSR!L13 -> 339000 | I42: =MSR!M13 -> 34578000
...

Sheet MOP
B1: Item | C1: Top | D1: Down | E1: P/N | F1: 의뢰일자 | G1: 공급예정 | H1: 구매일자 | I1: 대당소요량 | J1: 제작수량 | K1: 총 필요 수량 | L1: 단가 | M1: 합계 | N1: 판매자 | O1: Maker | P1: 담당자 및 연락처 | Q1: Remarks
B2: 1 | C2: MOP | E2: RES14001BS0
C3: 1 | D3: Main Frame | E3: R1C001384 | I3: 1 | J3: 51 | K3: =I3*J3 -> 51 | L3: 440100 | M3: =I3*J3*L3 -> 22445100 | N3: 세일엔지니어링 | O3: 세일엔지니어링
C4: 2 | D4: Left Cover | E4: R1C001385 | I4: 1 | J4: 51 | K4: =I4*J4 -> 51 | L4: - | M4: - | N4: 세일엔지니어링 | O4: 세일엔지니어링
C5: 3 | D5: Right Cover | E5: R1C001386 | I5: 1 | J5: 51 | K5: =I5*J5 -> 51 | L5: - | M5: - | N5: 세일엔지니어링 | O5: 세일엔지니어링
C6: 4 | D6: Upper Cover | E6: R1C001387 | I6: 1 | J6: 51 | K6: =I6*J6 -> 51 | L6: - | M6: - | N6: 세일엔지니어링 | O6: 세일엔지니어링
C7: 5 | D7: Lower Cover | E7: R1B002159 | I7: 1 | J7: 51 | K7: =I7*J7 -> 51 | L7: - | M7: - | N7: 세일엔지니어링 | O7: 세일엔지니어링
C8: 6 | D8: Rear Cover | E8: R1B002160 | I8: 1 | J8: 51 | K8: =I8*J8 -> 51 | L8: - | M8: - | N8: 세일엔지니어링 | O8: 세일엔지니어링
C9: 7 | D9: Push Button | E9: 84-1201.7 | I9: 4 | J9: 55 | K9: =I9*J9 -> 220 | L9: 28800 | M9: =I9*J9*L9 -> 6336000 | N9: 아이닉스 | O9: EAO
C10: 8 | D10: Push Button | E10: 84-7111.200 | I10: 4 | J10: 55 | K10: =I10*J10 -> 220 | L10: 4650 | M10: =I10*J10*L10 -> 1023000 | N10: 아이닉스 | O10: EAO
C11: 9 | D11: Push Button | E11: 84-8511.2320 | I11: 4 | J11: 55 | K11: =I11*J11 -> 220 | L11: 39000 | M11: =I11*J11*L11 -> 8580000 | N11: 아이닉스 | O11: EAO
C12: 10 | D12: Microphone | E12: KCM-30(55 JACK) | I12: 1 | J12: 55 | K12: =I12*J12 -> 55 | L12: 2800 | M12: =I12*J12*L12 -> 154000 | N12: 아이닉스 | O12: REAN
C13: 11 | D13: LCD | E13: "HL035T002T-02(단종) HL035T11-01 + RTC" | I13: 1 | J13: 60 | K13: =I13*J13 -> 60 | L13: 23000 | M13: =I13*J13*L13 -> 1380000 | N13: 티렉스아이엔씨 | O13: Shenzhen | Q13: BEUPSYS 정산
C14: 12 | D14: LCD Mount Bracket | E14: R1D005930 | I14: 1 | J14: 51 | K14: =I14*J14 -> 51 | L14: - | M14: - | N14: 세일엔지니어링 | O14: 세일엔지니어링
C15: 13 | D15: LCD Control Board | E15: R1C001402 Rev.1 | I15: 1 | J15: 51 | K15: =I15*J15 -> 51 | L15: 425213 | M15: =I15*J15*L15 -> 21685863 | N15: BEUPSYS | O15: BEUPSYS
C16: 14 | D16: Main Control Board | E16: R1C001388 | I16: 1 | J16: 51 | K16: =I16*J16 -> 51 | L16: 473650 | M16: =I16*J16*L16 -> 24156150 | N16: BEUPSYS | O16: BEUPSYS
C17: 15 | D17: Power Board | E17: R1C001574 | I17: 1 | J17: 51 | K17: =I17*J17 -> 51 | L17: 89000 | M17: =I17*J17*L17 -> 4539000 | N17: 이지파워 | O17: 이지파워
C18: 16 | D18: 3P Connector Male | E18: 770-213 | I18: 1 | J18: 55 | K18: =I18*J18 -> 55 | L18: 2800 | M18: =I18*J18*L18 -> 154000 | N18: 아이닉스 | O18: WAGO
C19: 17 | D19: 3P Connector Female | E19: 770-293 | I19: 1 | J19: 55 | K19: =I19*J19 -> 55 | L19: 4250 | M19: =I19*J19*L19 -> 233750 | N19: 아이닉스 | O19: WAGO
C20: 18 | D20: Locking | E20: 770-101 | I20: 1 | J20: 55 | K20: =I20*J20 -> 55 | L20: 350 | M20: =I20*J20*L20 -> 19250 | N20: 아이닉스 | O20: WAGO
C21: 19 | D21: 4P Connector | E21: 21 03 882 2405 | I21: 1 | J21: 55 | K21: =I21*J21 -> 55 | L21: 32300 | M21: =I21*J21*L21 -> 1776500 | N21: 아이닉스 | O21: HARTING
C22: 20 | D22: Pin | E22: 09 67 000 5476 | I22: 4 | J22: 55 | K22: =I22*J22 -> 220 | L22: 1300 | M22: =I22*J22*L22 -> 286000 | N22: 아이닉스 | O22: HARTING
C23: 21 | D23: 12P Connector | E23: UTG11412S | I23: 1 | J23: 50 | K23: =I23*J23 -> 50 | L23: 23900 | M23: =I23*J23*L23 -> 1195000 | N23: 아이닉스 | O23: SOURIAU | Q23: 수량 확인
C24: 22 | D24: Pin | E24: RC16M23K | I24: 12 | J24: 50 | K24: =I24*J24 -> 600 | L24: 1250 | M24: =I24*J24*L24 -> 750000 | N24: 아이닉스 | O24: SOURIAU
C25: 23 | D25: Cable Clamp | E25: UTG14AC | I25: 1 | J25: 55 | K25: =I25*J25 -> 55 | L25: 12000 | M25: =I25*J25*L25 -> 660000 | N25: 아이닉스 | O25: SOURIAU
C26: 24 | D26: Name Plate, AL, T1 | E26: R1C001342_6 | I26: 1 | J26: 55 | K26: =I26*J26 -> 55 | L26: - | M26: - | N26: - | O26: -
C27: 25 | D27: SPEAKER | E27: PMB4070N-0240 / 8 Ω 5W | I27: 1 | J27: 55 | K27: =I27*J27 -> 55 | L27: 4800 | M27: =I27*J27*L27 -> 264000 | N27: 아이닉스 | O27: -
C28: 26 | D28: Cable Gland | E28: DAM-25 | I28: 1 | J28: 55 | K28: =I28*J28 -> 55 | Q28: 추가발주
C29: 27 | D29: Cable Gland | E29: DAM-20 | I29: 1 | J29: 55 | K29: =I29*J29 -> 55 | Q29: 추가발주
C30: 28 | D30: 55 JACK | E30: 292S 55 Stereo Phone Plug | I30: 1 | J30: 55 | K30: =I30*J30 -> 55 | L30: 4000 | M30: =I30*J30*L30 -> 220000 | N30: - | Q30: 추가발주
B33: 1-1 (내부 하네스) | C33: 1 | D33: EMC 가스켓 | I33: 1 | J33: 55 | K33: =I33*J33 -> 55 | M33: 1680000 | N33: 이송이엠씨 | O33: 이송이엠씨 | Q33: BEUPSYS 정산
C34: 2 | D34: SPEAKER SHEET | E34: T1 | I34: 1 | J34: 55 | K34: =I34*J34 -> 55 | M34: =I34*J34*L34 -> 0 | N34: 화인테크
C35: 3 | D35: SPEAKER RUBBER SHEET | E35: t=6 | I35: 1 | J35: 55 | K35: =I35*J35 -> 55 | M35: =I35*J35*L35 -> 0 | N35: 화인테크
C36: 4 | D36: RUBBER SHEET | E36: HARDNESS 50,T6 | I36: 1 | J36: 55 | K36: =I36*J36 -> 55 | M36: =I36*J36*L36 -> 0 | N36: 화인테크
C37: 5 | D37: CAPTIVE BOLT | E37: SW3DPS-52-49-21-4 | I37: 1 | J37: 55 | K37: =I37*J37 -> 55 | M37: =I37*J37*L37 -> 0 | N37: 아이닉스
C38: 9 | D38: CONNECTOR | E38: 35155-0300 | I38: 1 | J38: 55 | K38: =I38*J38 -> 55 | L38: 50 | M38: =I38*J38*L38 -> 2750 | N38: 아이닉스
C39: 10 | D39: CONNECTOR | E39: 35155-0400 | I39: 2 | J39: 55 | K39: =I39*J39 -> 110 | L39: 50 | M39: =I39*J39*L39 -> 5500 | N39: 아이닉스
C40: 11 | D40: CONNECTOR | E40: 35155-0500 | I40: 1 | J40: 55 | K40: =I40*J40 -> 55 | L40: 70 | M40: =I40*J40*L40 -> 3850 | N40: 아이닉스
C41: 12 | D41: CONNECTOR | E41: 35155-0600 | I41: 2 | J41: 55 | K41: =I41*J41 -> 110 | L41: 80 | M41: =I41*J41*L41 -> 8800 | N41: 아이닉스
C42: 13 | D42: CONNECTOR | E42: 35155-0800 | I42: 1 | J42: 55 | K42: =I42*J42 -> 55 | L42: 120 | M42: =I42*J42*L42 -> 6600 | N42: 아이닉스
...

Sheet MSR
B1: Item | C1: Top | D1: Down | E1: P/N | F1: 의뢰일자 | G1: 공급예정 | H1: 구매일자 | I1: 대당소요량 | J1: 제작수량 | K1: 총 필요 수량 | L1: 단가 | M1: 합계 | N1: 판매자 | O1: Maker | P1: 담당자 및 연락처 | Q1: Remarks
B2: 2 | C2: MSR | E2: RES13001BS0
C3: 1 | D3: PWR Board | E3: R1C001323 | I3: 1 | J3: 51 | K3: =J3*I3 -> 51 | L3: 136000 | M3: =I3*J3*L3 -> 6936000 | N3: 이지파워 | O3: 이지파워
C4: 2 | D4: M_TX Board | E4: R1B002190 | I4: 1 | J4: 51 | K4: =J4*I4 -> 51 | L4: 610566 | M4: =I4*J4*L4 -> 31138866 | N4: BEUPSYS | O4: BEUPSYS
C5: 3 | D5: Hub Board | E5: R1B002192 | I5: 1 | J5: 51 | K5: =J5*I5 -> 51 | L5: 664363 | M5: =I5*J5*L5 -> 33882513 | N5: BEUPSYS | O5: BEUPSYS
C6: 4 | D6: TCIU Board | E6: R1B002187 | I6: 1 | J6: 51 | K6: =J6*I6 -> 51 | L6: 1129222 | M6: =I6*J6*L6 -> 57590322 | N6: BEUPSYS | O6: BEUPSYS
C7: 5 | D7: PA_PBX Board | E7: R1B002188 | I7: 1 | J7: 51 | K7: =J7*I7 -> 51 | L7: 289000 | M7: =I7*J7*L7 -> 14739000 | N7: BEUPSYS | O7: BEUPSYS
C8: 6 | D8: PA_ETX Board | E8: R1B002189 | I8: 1 | J8: 51 | K8: =J8*I8 -> 51 | L8: 474791 | M8: =I8*J8*L8 -> 24214341 | N8: BEUPSYS | O8: BEUPSYS
C9: 7 | D9: NVR Board | E9: R1B002193 Rev.1 | I9: 1 | J9: 51 | K9: =J9*I9 -> 51 | L9: 913923 | M9: =I9*J9*L9 -> 46610073 | N9: BEUPSYS | O9: BEUPSYS
D10: CPU TC170/i5-6300U | E10: - | I10: 1 | J10: 60 | K10: =J10*I10 -> 60 | L10: 763 | M10: =L10*(J10*I10) -> 45780 | N10: 이엔엠테크놀로지 | O10: CONGA
D11: CPU BRACKET TC170/CSP-B | E11: - | I11: 1 | J11: 60 | K11: =J11*I11 -> 60 | L11: 43.3 | M11: =L11*(J11*I11) -> 2598 | N11: 이엔엠테크놀로지 | O11: CONGA
D12: DDR4 (DDR4 4GB SODIMM 2400MT/S) | E12: - | I12: 1 | J12: 60 | K12: =J12*I12 -> 60 | L12: 36000 | M12: =L12*(J12*I12) -> 2160000 | N12: 이노디스크 | O12: 이노디스크
C13: 8 | D13: SSD Board | E13: R1B002191 | I13: 2 | J13: 51 | K13: =J13*I13 -> 102 | L13: 339000 | M13: =I13*J13*L13 -> 34578000 | N13: BEUPSYS | O13: BEUPSYS
C14: 9 | D14: MSR Back Plane | E14: R1D007456 | I14: 1 | J14: 55 | K14: =J14*I14 -> 55 | L14: 300000 | M14: =I14*J14*L14 -> 16500000 | N14: 앤츠 | O14: 앤츠
C15: 10 | D15: Frame | E15: R1B002086 | I15: 1 | J15: 51 | K15: =J15*I15 -> 51 | L15: 630000 | M15: =I15*J15*L15 -> 32130000 | N15: USK | O15: USK
C16: 11 | D16: Name Plate, AL, T1 | E16: R1C001342_4 | I16: 1 | J16: 51 | K16: =J16*I16 -> 51 | L16: - | M16: - | N16: - | O16: -
C17: 12 | D17: SSD(2T) | E17: - | I17: 2 | J17: 52 | K17: =J17*I17 -> 104 | L17: 490000 | M17: =I17*J17*L17 -> 50960000 | N17: 이노디스크 | O17: 이노디스크
B21: 2-1(내부 하네스) | C21: 1 | D21: TCIU Board | Q21: 내부 배선도
C22: 1-1 | D22: -Connector | E22: 2103 371 2403 | I22: 8 | J22: 53 | K22: =I22*J22 -> 424 | L22: 21500 | M22: =I22*J22*L22 -> 9116000 | N22: 아이닉스
C23: 1-2 | D23: CONNECTOR | E23: 35155-0400 | I23: 7 | J23: 55 | K23: =I23*J23 -> 385 | L23: 50 | M23: =I23*J23*L23 -> 19250 | N23: 아이닉스
C24: 1-3 | D24: CONNECTOR | E24: 35155-0800 | I24: 1 | J24: 55 | K24: =I24*J24 -> 55 | L24: 120 | M24: =I24*J24*L24 -> 6600 | N24: 아이닉스
C25: 1-4 | D25: TERMINAL | E25: 5103, AWG22-28 | I25: 36 | J25: 55 | K25: =I25*J25 -> 1980 | L25: 11 | M25: =I25*J25*L25 -> 21780 | N25: 아이닉스
C26: 2 | D26: Hub Board
C27: 2-1 | D27: -Connector | E27: 2103 371 2403 | I27: 6 | J27: 53 | K27: =I27*J27 -> 318 | L27: 21500 | M27: =I27*J27*L27 -> 6837000 | N27: 아이닉스
C28: 2-2 | D28: CONNECTOR | E28: 35155-0400 | I28: 4 | J28: 55 | K28: =I28*J28 -> 220 | L28: 50 | M28: =I28*J28*L28 -> 11000 | N28: 아이닉스
C29: 2-3 | D29: CONNECTOR | E29: 35155-0800 | I29: 1 | J29: 55 | K29: =I29*J29 -> 55 | L29: 120 | M29: =I29*J29*L29 -> 6600 | N29: 아이닉스
C30: 2-4 | D30: TERMINAL | E30: 5103, AWG22-28 | I30: 24 | J30: 55 | K30: =I30*J30 -> 1320 | L30: 11 | M30: =I30*J30*L30 -> 14520 | N30: 아이닉스
C31: 3 | D31: PWR Board
C32: 3-1 | D32: -Connector | E32: 770-713 | I32: 1 | J32: 55 | K32: =I32*J32 -> 55 | L32: 3350 | M32: =I32*J32*L32 -> 184250 | N32: 아이닉스
C33: 3-3 | D33: CONNECTOR | E33: YH396-05V | I33: 1 | J33: 55 | K33: =I33*J33 -> 55 | L33: 45 | M33: =I33*J33*L33 -> 2475 | N33: 아이닉스
C34: 3-4 | D34: TERMINAL | E34: YT396J | I34: 5 | J34: 55 | K34: =I34*J34 -> 275 | L34: 25 | M34: =I34*J34*L34 -> 6875 | N34: 아이닉스
C35: 4 | D35: PA_ETX Board
C36: 4-1 | D36: -Connector | E36: UTG01412S | I36: 1 | J36: 50 | K36: =I36*J36 -> 50 | L36: 14350 | M36: =I36*J36*L36 -> 717500 | N36: 아이닉스 | Q36: 수량 확인
C37: 4-2 | D37: -Connector | E37: UTG01619S | I37: 1 | J37: 55 | K37: =I37*J37 -> 55 | L37: 17850 | M37: =I37*J37*L37 -> 981750 | N37: 아이닉스 | Q37: 추가 진행 필요
C38: 4-3 | D38: -Connector | E38: RC16M23K | I38: 31 | J38: 50 | K38: =I38*J38 -> 1550 | L38: 1250 | M38: =I38*J38*L38 -> 1937500 | N38: 아이닉스 | Q38: 수량 확인
C39: 4-4 | D39: HOUSING | E39: 35155-0600 | I39: 1 | J39: 55 | K39: =I39*J39 -> 55 | L39: 80 | M39: =I39*J39*L39 -> 4400 | N39: 아이닉스
C40: 4-5 | D40: HOUSING | E40: 35155-1200 | I40: 1 | J40: 55 | K40: =I40*J40 -> 55 | L40: 200 | M40: =I40*J40*L40 -> 11000 | N40: 아이닉스
C41: 4-6 | D41: TERMINAL | E41: 5103, AWG22-28 | I41: 18 | J41: 55 | K41: =I41*J41 -> 990 | L41: 11 | M41: =I41*J41*L41 -> 10890 | N41: 아이닉스
M42: =SUM(M22:M41) -> 19889390
N47: 513363 | O47: 615859 | Q47: =N47+O47 -> 1129222

Sheet CTM
B1: Item | C1: Top | D1: Down | E1: P/N | F1: 의뢰일자 | G1: 공급예정 | H1: 구매일자 | I1: 대당소요량 | J1: 제작수량 | K1: 총 필요 수량 | L1: 단가 | M1: 합계 | N1: 판매자 | O1: Maker | P1: 담당자 및 연락처 | Q1: Remarks
B2: 3 | C2: CTM | E2: RES40001BS0
C3: 1 | D3: Main Frame | E3: R1B002140 | I3: 1 | J3: 51 | K3: =I3*J3 -> 51 | L3: 304800 | M3: =I3*J3*L3 -> 15544800 | N3: 세일엔지니어링 | O3: 세일엔지니어링
C4: 2 | D4: Lower Cover | E4: R1C001370 | I4: 1 | J4: 51 | K4: =I4*J4 -> 51 | L4: - | M4: - | N4: 세일엔지니어링 | O4: 세일엔지니어링
C5: 3 | D5: Rear Cover | E5: R1B002142 | I5: 1 | J5: 51 | K5: =I5*J5 -> 51 | L5: - | M5: - | N5: 세일엔지니어링 | O5: 세일엔지니어링
C6: 4 | D6: 10.4" LCD | E6: RES40001002 | I6: 1 | J6: 60 | K6: =I6*J6 -> 60 | L6: 185000 | M6: =I6*J6*L6 -> 11100000 | N6: 티렉스아이엔씨 | O6: CPT | Q6: CLAA104XA02CW / M104ZA-AD00
C7: 5 | D7: Control Board Bracket | E7: R1C001371 | I7: 1 | J7: 51 | K7: =I7*J7 -> 51 | L7: - | M7: - | N7: 세일엔지니어링 | O7: 세일엔지니어링
C8: 6 | D8: Control Board | E8: R1C001372 Rev.1 | I8: 1 | J8: 51 | K8: =I8*J8 -> 51 | L8: 923923 | M8: =I8*J8*L8 -> 47120073 | N8: BEUPSYS | O8: BEUPSYS
D9: CPU TCA3/i-E3845 | E9: - | I9: 1 | J9: 70 | K9: =I9*J9 -> 70 | L9: 327 | M9: =L9*(J9*I9) -> 22890 | N9: 이엔엠테크놀로지 | O9: CONGA | Q9: 수요량 51EA
D10: CPU BRACKET TCA3/CSP-B | E10: - | I10: 1 | J10: 70 | K10: =I10*J10 -> 70 | L10: 40.6 | M10: =L10*(J10*I10) -> 2842 | N10: 이엔엠테크놀로지 | O10: CONGA | Q10: 수요량 51EA
D11: DDR4 (DDR3L 4GB SODIMM 1600MT/S) | E11: - | I11: 1 | J11: 70 | K11: =I11*J11 -> 70 | L11: 36000 | M11: =L11*(J11*I11) -> 2520000 | N11: 이노디스크 | O11: 이노디스크
C12: 7 | D12: Power Board | E12: R1C001369 | I12: 1 | J12: 60 | K12: =I12*J12 -> 60 | L12: 112000 | M12: =I12*J12*L12 -> 6720000 | N12: 이지파워 | O12: 이지파워
C13: 8 | D13: 3P Connector | E13: 770-213 | I13: 1 | J13: 55 | K13: =I13*J13 -> 55 | L13: 2800 | M13: =I13*J13*L13 -> 154000 | N13: 아이닉스 | O13: WAGO
C14: 9 | D14: Locking | E14: 770-101 | I14: 1 | J14: 55 | K14: =I14*J14 -> 55 | L14: 350 | M14: =I14*J14*L14 -> 19250 | N14: 아이닉스 | O14: WAGO
C15: 10 | D15: 4P Connector | E15: 21 03 882 2405 | I15: 4 | J15: 51 | K15: =I15*J15 -> 204 | L15: 32300 | M15: =I15*J15*L15 -> 6589200 | N15: 아이닉스 | O15: HARTING | Q15: 통신 컨넥터 4EA
C16: 11 | D16: Pin | E16: 09 67 000 5476 | I16: 16 | J16: 51 | K16: =I16*J16 -> 816 | L16: 1300 | M16: =I16*J16*L16 -> 1060800 | N16: 아이닉스 | O16: HARTING
C17: 12 | D17: Cable Gland | E17: DAM-25 | I17: 2 | J17: 55 | K17: =I17*J17 -> 110 | L17: 1000 | M17: =I17*J17*L17 -> 110000 | N17: 아이닉스 | O17: DONGA
C18: 13 | D18: USB Adapter | E18: ECF504-12AAS (600mm) | I18: 1 | J18: 55 | K18: =I18*J18 -> 55 | L18: 28900 | M18: =I18*J18*L18 -> 1589500 | N18: 아이닉스 | O18: L-COM
C19: 14 | D19: Name Plate | E19: R1C001342_12 | I19: 1 | J19: 51 | K19: =I19*J19 -> 51 | L19: - | M19: - | N19: - | O19: -
B23: 3-1 | C23: 1 | D23: CTM WIRRING DIAGRAM
C24: 3 | D24: CONNECTOR | E24: SMH200-08 | I24: 4 | J24: 55 | K24: =I24*J24 -> 220 | L24: 60 | M24: =I24*J24*L24 -> 13200 | N24: 아이닉스
C25: 4 | D25: TERMINAL | E25: YST200 ( 확인 필요) | I25: 32 | J25: 55 | K25: =I25*J25 -> 1760 | M25: =I25*J25*L25 -> 0 | N25: 아이닉스 | Q25: 추가 진행 필요
C26: 5 | D26: CONNECTOR | E26: 0039012025/MOLEX | I26: 1 | J26: 55 | K26: =I26*J26 -> 55 | L26: 80 | M26: =I26*J26*L26 -> 4400 | N26: 아이닉스
C27: 6 | D27: TERMINAL | E27: 5556, 18-24 AWG/MOLEX | I27: 2 | J27: 55 | K27: =I27*J27 -> 110 | L27: 25 | M27: =I27*J27*L27 -> 2750 | N27: 아이닉스
C28: 7 | D28: CONNECTOR | E28: YH396-08V | I28: 1 | J28: 55 | K28: =I28*J28 -> 55 | L28: 60 | M28: =I28*J28*L28 -> 3300 | N28: 아이닉스
C29: 8 | D29: TERMINAL | E29: YT396/YEONHO ELEC. | I29: 13 | J29: 55 | K29: =I29*J29 -> 715 | L29: 25 | M29: =I29*J29*L29 -> 17875 | N29: 아이닉스
C30: 9 | D30: CONNECTOR | E30: YH396-05V | I30: 1 | J30: 55 | K30: =I30*J30 -> 55 | L30: 45 | M30: =I30*J30*L30 -> 2475 | N30: 아이닉스
C31: 10 | D31: CONNECTOR | E31: 5264-02/MOLEX | I31: 1 | J31: 55 | K31: =I31*J31 -> 55 | L31: 40 | M31: =I31*J31*L31 -> 2200 | N31: 아이닉스 | Q31: 추가 진행 필요
C32: 11 | D32: TERMINAL | E32: 5263PBT9/MOLEX | I32: 2 | J32: 55 | K32: =I32*J32 -> 110 | M32: =I32*J32*L32 -> 0 | N32: 아이닉스 | Q32: 추가 진행 필요
C33: 12 | D33: MICRO SPEAKER | E33: PMB4070N-0240 /8Ω /5W | I33: 1 | J33: 55 | K33: =I33*J33 -> 55 | L33: 4800 | M33: =I33*J33*L33 -> 264000 | N33: 아이닉스 | Q33: 추가 진행 필요
M34: =SUM(M24:M33) -> 310200

Sheet 부자재list
