Workbook

Sheet Sheet1
B2: 년도별 수주 실적(단위 : 억원)
B3: 구분 | C3: 수주액 | D3: 매출_완료 | E3: 매출_미수 | F3: 매출_선수 | G3: 비고
B4: 2024년 | C4: =MAX(Total!J:J)/100000000 -> 12.425749 | D4: =SUM(Total!Q:Q)/100000000 -> 10.005746 | E4: 0 | F4: 0 | G4: 1. 지아이씨 일부 제품 납품 미완료 2. 무한테크 진행사항 확인 필요(입금액 0원)
B5: 2025년 | C5: =MAX(Total!K:K)/100000000 -> 7.1584448 | D5: 0 | E5: 0 | F5: 0
B6: 2026년 | C6: - | D6: 0 | E6: 0 | F6: 0
B7: 2027년 | C7: - | D7: 0 | E7: 0 | F7: 0
B8: … | C8: - | D8: 0 | E8: 0 | F8: 0
B10: 2024년 예상 손익(단위 : 억원)
C11: 구분 | D11: 구분 상세 | F11: 금액 | G11: 비고
C12: 매출 | D12: 매출손익 | F12: =C4*0.5 -> 6.2128747 | G12: 수주 실적의 50% (가정)
C13: 지출 | D13: 지출 합계 | F13: =SUM(F14,F23) -> 5.263
D14: 급여 | E14: 계 | F14: =SUM(F15:F22) -> 4.263 | G14: 개인별 근무기간 상이, 1년 근무 기준 금액으로 산정
E15: 최순섭 | F15: =0.01*12 -> 0.12
E16: 최성필 | F16: =0.01*12 -> 0.12
E17: 강남궐 | F17: 0.9
E18: 장덕수 | F18: 0.9
E19: 김용종 | F19: 0.9
E20: 최수연 | F20: 0.65
E21: 홍성준 | F21: =0.01*12 -> 0.12
E22: 김대양 | F22: 0.553 | I22: 2024년 진행방향
D23: 경비 | F23: 1 | G23: 1년 경비 1억원 가정 | I23: 1. TMS 및 PA/PIS의 기본모델을 개발/제작한다.
C24: 손익 | D24: 매출 - 지출 | F24: =F12-F13 -> 0.94987472 | I24: 1). 홍콩의 제품을 기본모델로 하여 시제품을 만든다.
I25: 2. 기존고객관리를 철저히한다.
B26: 2025년 예상 손익(단위 : 억원) | I26: 1). 지아이씨 수주를 최대로 해야 함.
C27: 구분 | D27: 구분 상세 | F27: 금액 | G27: 비고 | I27: 2). 다원시스 수주가 원활히 이루어지도록 해야 함.
C28: 매출 | D28: 매출손익 | F28: =C5*0.5 -> 3.5792224 | G28: 수주 실적의 50% (가정) | I28: 3). 실리콘큐브와 티램의 수주가 되도록 영업활동을 해야 함.
C29: 지출 | D29: 지출 합계 | F29: =SUM(F30,F40) -> 6.456 | I29: 5. 국내외 업체의 수주처를 발굴한다.
D30: 급여 | E30: 계 | F30: =SUM(F31:F39) -> 5.456 | G30: 개인별 근무기간 상이, 1년 근무 기준 금액으로 산정 | I30: 1). 교통공사 수주 목표로 한다.
E31: 최순섭 | F31: =0.01*12 -> 0.12 | I31: 2). 김포골드라인 수주목표로 한다.
E32: 최성필 | F32: =0.01*12 -> 0.12
E33: 강남궐 | F33: 0.9 | I33: 2025년 경영 RISK
E34: 장덕수 | F34: 0.9 | I34: 1. 2024년 대비 수주 실적 악화 및 지출비용 증가가 예상되고 있어, 적자 전환의 우려가 있음
E35: 김용종 | F35: 0.9 | I35: 2. 매출실적을 수주 실적의 50%로 가정 시, 2025년 추가 수주가 없다면 8개월 이후 차입경영으로 전환 예상
E36: 이동진 | F36: 0.663 | I36: 3. 차입경영을 피하기 위해서는 최소 약 4억원 이상의 추가 수주가 필요할 것을로 판단됨
E37: 최수연 | F37: 0.65
E38: 홍성준 | F38: 0.65
E39: 김대양 | F39: 0.553
D40: 경비 | F40: 1 | G40: 1년 경비 1억원 가정
C41: 손익 | D41: 매출 - 지출 | F41: =F28-F29 -> -2.8767776
B43: 2025년 누적예상 손익(단위 : 억원)
...

Sheet Total
E2: 견적가 | I2: 수주가
B3: 구분 | C3: 순 | D3: 고객명 | E3: Total | F3: AB | G3: CD | I3: 전체수주가 | J3: 2024년 수주가 | K3: 2025년 수주가 | L3: 수주율 | M3: 제작사원가 | N3: 매출손익 | O3: 손익율 | P3: 비고 | Q3: 입금 총액 | R3: 입금 비율(전체) | S3: 입금 비율(2024)
B4: 생산 | C4: 1 | D4: ='1.지아이씨'!D4 -> 지아이씨 | E4: ='1.지아이씨'!M49 -> 1488279419 | F4: ='1.지아이씨'!N49 -> 1488279419 | G4: ='1.지아이씨'!O49 -> 0 | I4: ='1.지아이씨'!P49 -> 1488279419 | J4: ='1.지아이씨'!Q49 -> 1.0594349e+09 | K4: ='1.지아이씨'!R49 -> 4.2884448e+08 | L4: =I4/E4 -> 1 | M4: ='1.지아이씨'!S49 -> 0 | Q4: =MAX('1.지아이씨'!U:U) -> 8.2883455e+08 | R4: =$Q4/I4 -> 0.55690789 | S4: =$Q4/J4 -> 0.78233643
C5: 2 | D5: 김포골드라인 | E5: ='2.김포골드라인'!L23 -> 957811200 | F5: ='2.김포골드라인'!M23 -> 957811200
C6: 3 | D6: 교통공사 | E6: ='3.교통공사'!L23 -> 209154910 | F6: ='3.교통공사'!M23 -> 207254910 | I6: ='3.교통공사'!O23 -> 1900000 | J6: ='3.교통공사'!P23 -> 1900000 | K6: ='3.교통공사'!Q23 -> 0 | L6: =I6/E6 -> 0.0090841759 | Q6: =MAX('3.교통공사'!T:T) -> 1900000 | R6: =$Q6/I6 -> 1 | S6: =$Q6/J6 -> 1
C7: 4 | D7: 실리콘큐브 | E7: ='4.실리콘큐브'!N26 -> 46840000 | F7: ='4.실리콘큐브'!O26 -> 46840000 | I7: ='4.실리콘큐브'!Q26 -> 46840000 | J7: ='4.실리콘큐브'!R26 -> 46840000 | Q7: =MAX('4.실리콘큐브'!V:V) -> 46840000 | R7: =$Q7/I7 -> 1 | S7: =$Q7/J7 -> 1
C8: 5 | D8: 무한테크 | E8: ='5.무한테크 (우진산전)'!M3 -> 20350000 | F8: ='5.무한테크 (우진산전)'!N25 -> 0 | G8: =I8 -> 11400000 | I8: ='5.무한테크 (우진산전)'!P25 -> 11400000 | J8: ='5.무한테크 (우진산전)'!Q25 -> 11400000 | K8: ='5.무한테크 (우진산전)'!R25 -> 0 | L8: =I8/E8 -> 0.56019656 | Q8: =MAX('5.무한테크 (우진산전)'!U:U) -> 0 | R8: =$Q8/I8 -> 0 | S8: =$Q8/J8 -> 0
C9: 6 | D9: 다원시스 | E9: ='6.다원시스'!L26 -> 923145936 | F9: ='6.다원시스'!M26 -> 895178562 | G9: ='1.지아이씨'!O49 -> 0 | I9: ='6.다원시스'!O26 -> 410000000 | J9: ='6.다원시스'!P26 -> 123000000 | K9: ='6.다원시스'!Q26 -> 287000000 | L9: =I9/E9 -> 0.44413346 | M9: ='6.다원시스'!R26 -> 0 | Q9: =MAX('6.다원시스'!T:T) -> 123000000 | R9: =$Q9/I9 -> 0.3 | S9: =$Q9/J9 -> 1
C10: 7 | D10: 티랩 | E10: ='7.티랩'!L25 -> 0 | F10: ='7.티랩'!M25 -> 0 | G10: ='7.티랩'!N25 -> 0 | I10: ='7.티랩'!O25 -> 0 | J10: ='7.티랩'!P25 -> 0 | K10: ='7.티랩'!Q25 -> 0 | L10: =I10/E10 -> #DIV/0! | M10: ='7.티랩'!R25 -> 0
C11: 8 | D11: 마루소프트 | E11: ='8.마루소프트'!L25 -> 20350000 | F11: ='8.마루소프트'!M25 -> 20350000 | I11: ='8.마루소프트'!O25 -> 0 | J11: ='8.마루소프트'!P25 -> 0 | K11: ='8.마루소프트'!Q25 -> 0 | L11: =I11/E11 -> 0
C12: 9 | D12: 신진금고 | E12: ='9.신진금고'!L25 -> 169299200 | F12: ='9.신진금고'!M25 -> 169299200 | I12: ='9.신진금고'!O25 -> 0 | J12: ='9.신진금고'!P25 -> 0 | K12: ='9.신진금고'!Q25 -> 0 | L12: =I12/E12 -> 0
D20: 소계 | E20: =SUM(E4:E12) -> 3835230665 | F20: =SUM(F4:F12) -> 3785013291 | G20: =SUM(G4:G12) -> 11400000 | I20: =SUM(I4:I12) -> 1958419419 | J20: =SUM(J4:J12) -> 1.2425749e+09 | K20: =SUM(K4:K11) -> 7.1584448e+08 | L20: =I20/E20 -> 0.51063928 | M20: =SUM(M4:M12) -> 0 | N20: =SUM(N4:N12) -> 0 | O20: =N20/I20 -> 0

Sheet 1.지아이씨
B3: 순 | C3: 국가 | D3: 고객 | E3: 견적번호 | F3: RFQ no. | G3: 견적일 | H3: 유효일 | I3: Item | J3: 구분 | K3: 수량 | L3: 견적금액(외화) | M3: 견적금액(KRW) | N3: AB 등급 | O3: CD등급 | P3: 수주금액 (전체) | Q3: 수주금액 (2024년) | R3: 수주금액 (2025년) | S3: 원가 | T3: 비고 | U3: 입금 총액 | V3: 입금 비율(전체) | W3: 입금 비율(2024)
A4: ok | B4: 1 | C4: 한국 | D4: 지아이씨 | E4: CSP24-0409-1 | G4: 240409 | H4: 240930 | J4: PAB, EID, PSR, ETND, EDD 생산 | K4: 51 / 41 / 41 / 21 / 21 | M4: 423083700 | N4: =M4 -> 423083700 | P4: =N4 -> 423083700 | Q4: =P4 -> 423083700 | T4: 1. 계약시 30% (126,925,110 KRW) 2. 제작 후 검사 전 30% 3. 검사 합격 후 납품 시 30% 4. 고객으로부터 물품대금 수령 후 잔금 10% | U4: 310664307 | V4: =$U4/P4 -> 0.73428569 | W4: =$U4/Q4 -> 0.73428569 | X4: 241104 납품분 및 중도금 125,716,299 KRW (품목 ???) | Y4: 240925 2차 중도금 29,011,454 KRW (PSR & EID 각 20EA) | Z4: 240906 1차 중도금 29,011,454 KRW (PSR & EID 각 20EA) | AA4: 240411 선급금 126,925,100 KRW
A5: ok | B5: 2 | C5: 한국 | D5: 지아이씨 | E5: CSP24-0409-2 | G5: 240409 | H5: 240412 | I5: 1 | J5: MOP 수리(17031, R1C001388) | K5: 1 | M5: 270000 | N5: =M5 -> 270000 | P5: =N5 -> 270000 | Q5: =P5 -> 270000 | U5: =P5 -> 270000 | V5: =$U5/P5 -> 1 | W5: =$U5/Q5 -> 1 | X5: 계약 종료 / 24년 수주금액 입금 완료 | Y5: 240411 전자세금계산서
H6: 240412 | I6: 2 | J6: MOP 수리(19067, R1C001388) | K6: 1 | M6: 900000 | N6: =M6 -> 900000 | P6: =N6 -> 900000 | Q6: =P6 -> 900000 | U6: =P6 -> 900000 | V6: =U6/$P6 -> 1 | W6: =U6/$Q6 -> 1
H7: 240412 | I7: 3 | J7: MSR HUB 수리(16006, R1B002192) | K7: 1 | M7: 1386000 | N7: =M7 -> 1386000 | P7: =N7 -> 1386000 | Q7: =P7 -> 1386000 | U7: =P7 -> 1386000 | V7: =U7/$P7 -> 1 | W7: =U7/$Q7 -> 1
H8: 240412 | I8: 4 | J8: MSR HUB 수리(19002, R1B002192) | K8: 1 | M8: 1386000 | N8: =M8 -> 1386000 | P8: =N8 -> 1386000 | Q8: =P8 -> 1386000 | U8: =P8 -> 1386000 | V8: =U8/$P8 -> 1 | W8: =U8/$Q8 -> 1
B9: 3 | C9: 한국 | D9: 지아이씨 | E9: CSP24-0524-1 | G9: 240524 | H9: 250227 | J9: MOP, MSR, CTM 생산 | K9: 51 / 51 / 51 | M9: 350710750 | N9: =M9 -> 350710750 | P9: =N9 -> 350710750 | Q9: =P9*0.3 -> 105213225 | R9: =P9*0.7 -> 2.4549752e+08 | T9: 1. 계약시 30% (105,213,225 KRW) 2. 제작 후 검사 전 30% 3. 검사 합격 후 납품 시 30% 4. 고객으로부터 물품대금 수령 후 잔금 10% | U9: 105213225 | V9: =U9/$P9 -> 0.3 | W9: =U9/$Q9 -> 1 | X9: 240524 선급금 105,213,225 KRW 전자세금계산서
A10: ok | B10: 4 | C10: 한국 | D10: 지아이씨 | E10: CSP24-0524-2 | G10: 240524 | H10: 240726 | I10: 1 | J10: PSR-HUB Board | K10: 82 | M10: 35260000 | N10: =M10 -> 35260000 | P10: =N10 -> 35260000 | Q10: =P10 -> 35260000 | T10: 1. 계약 시 선금 70% | U10: =P10*0.7 -> 24682000 | V10: =$U10/P10 -> 0.7 | W10: =$U10/Q10 -> 0.7 | X10: 240524 선급금 138,467,000 KRW 전자세금계산서
I11: 2 | J11: PSR-VOIP Board | K11: 82 | M11: 27060000 | N11: =M11 -> 27060000 | P11: =N11 -> 27060000 | Q11: =P11 -> 27060000 | T11: 2. 제작하고 검사 후 잔금 30% | U11: =P11*0.7 -> 18942000 | V11: =$U11/P11 -> 0.7 | W11: =$U11/Q11 -> 0.7
I12: 3 | J12: PSR-PA-AMP1 Board | K12: 82 | M12: 27060000 | N12: =M12 -> 27060000 | P12: =N12 -> 27060000 | Q12: =P12 -> 27060000 | U12: =P12*0.7 -> 18942000 | V12: =$U12/P12 -> 0.7 | W12: =$U12/Q12 -> 0.7
I13: 4 | J13: PSR-PA-AMP2 Board | K13: 82 | M13: 15580000 | N13: =M13 -> 15580000 | P13: =N13 -> 15580000 | Q13: =P13 -> 15580000 | U13: =P13*0.7 -> 10906000 | V13: =$U13/P13 -> 0.7 | W13: =$U13/Q13 -> 0.7
I14: 5 | J14: PSR-BPB | K14: 82 | M14: 27060000 | N14: =M14 -> 27060000 | P14: =N14 -> 27060000 | Q14: =P14 -> 27060000 | U14: =P14*0.7 -> 18942000 | V14: =$U14/P14 -> 0.7 | W14: =$U14/Q14 -> 0.7
I15: 6 | J15: PAB-CONTROL Board | K15: 51 | M15: 16830000 | N15: =M15 -> 16830000 | P15: =N15 -> 16830000 | Q15: =P15 -> 16830000 | U15: =P15*0.7 -> 11781000 | V15: =$U15/P15 -> 0.7 | W15: =$U15/Q15 -> 0.7
I16: 7 | J16: EID-CONTROL Board | K16: 41 | M16: 22550000 | N16: =M16 -> 22550000 | P16: =N16 -> 22550000 | Q16: =P16 -> 22550000 | U16: =P16*0.7 -> 15785000 | V16: =$U16/P16 -> 0.7 | W16: =$U16/Q16 -> 0.7
I17: 8 | J17: EID-SENSOR Board | K17: 41 | M17: 2050000 | N17: =M17 -> 2050000 | P17: =N17 -> 2050000 | Q17: =P17 -> 2050000 | U17: =P17*0.7 -> 1435000 | V17: =$U17/P17 -> 0.7 | W17: =$U17/Q17 -> 0.7
I18: 9 | J18: EDD-CONTROL Board | K18: 21 | M18: 12180000 | N18: =M18 -> 12180000 | P18: =N18 -> 12180000 | Q18: =P18 -> 12180000 | U18: =P18*0.7 -> 8526000 | V18: =$U18/P18 -> 0.7 | W18: =$U18/Q18 -> 0.7
I19: 10 | J19: ETND-CONTROL Board | K19: 21 | M19: 12180000 | N19: =M19 -> 12180000 | P19: =N19 -> 12180000 | Q19: =P19 -> 12180000 | U19: =P19*0.7 -> 8526000 | V19: =$U19/P19 -> 0.7 | W19: =$U19/Q19 -> 0.7
B20: 5 | C20: 한국 | D20: 지아이씨 | E20: CSP24-0913-1 | G20: 240913 | H20: 250131 | I20: 1 | J20: MSR NVR | K20: 51 | M20: 46610077 | N20: =M20 -> 46610077 | P20: =N20 -> 46610077 | Q20: =P20*0.7 -> 32627054 | R20: =P20*0.3 -> 13983023 | T20: 1. 계약 시 선금 70% | U20: =Q20 -> 32627054 | V20: =U20/$P20 -> 0.7 | W20: =U20/$Q20 -> 1 | X20: 24년 수주금액 입금 완료 | Y20: 240913 선금 70% 전자세금계산서
I21: 2 | J21: MSR HUB | K21: 51 | M21: 33882518 | N21: =M21 -> 33882518 | P21: =N21 -> 33882518 | Q21: =P21*0.7 -> 23717763 | R21: =P21*0.3 -> 10164755 | T21: 2. 제작하고 검사 후 잔금 30% | U21: =Q21 -> 23717763 | V21: =U21/$P21 -> 0.7 | W21: =U21/$Q21 -> 1
I22: 3 | J22: MSR MTX | K22: 51 | M22: 31138841 | N22: =M22 -> 31138841 | P22: =N22 -> 31138841 | Q22: =P22*0.7 -> 21797189 | R22: =P22*0.3 -> 9341652.3 | U22: =Q22 -> 21797189 | V22: =U22/$P22 -> 0.7 | W22: =U22/$Q22 -> 1
I23: 4 | J23: MSR TCIU HUB | K23: 51 | M23: 26181518 | N23: =M23 -> 26181518 | P23: =N23 -> 26181518 | Q23: =P23*0.7 -> 18327063 | R23: =P23*0.3 -> 7854455.4 | U23: =Q23 -> 18327063 | V23: =U23/$P23 -> 0.7 | W23: =U23/$Q23 -> 1
I24: 5 | J24: MSR TCIU CTL | K24: 51 | M24: 31408809 | N24: =M24 -> 31408809 | P24: =N24 -> 31408809 | Q24: =P24*0.7 -> 21986166 | R24: =P24*0.3 -> 9422642.7 | U24: =Q24 -> 21986166 | V24: =U24/$P24 -> 0.7 | W24: =U24/$Q24 -> 1
I25: 6 | J25: MSR PBX | K25: 51 | M25: 14739000 | N25: =M25 -> 14739000 | P25: =N25 -> 14739000 | Q25: =P25*0.7 -> 10317300 | R25: =P25*0.3 -> 4421700 | U25: =Q25 -> 10317300 | V25: =U25/$P25 -> 0.7 | W25: =U25/$Q25 -> 1
I26: 7 | J26: MSR SSD | K26: 102 | M26: 34578000 | N26: =M26 -> 34578000 | P26: =N26 -> 34578000 | Q26: =P26*0.7 -> 24204600 | R26: =P26*0.3 -> 10373400 | U26: =Q26 -> 24204600 | V26: =U26/$P26 -> 0.7 | W26: =U26/$Q26 -> 1
I27: 8 | J27: MSR ETX | K27: 51 | M27: 24214341 | N27: =M27 -> 24214341 | P27: =N27 -> 24214341 | Q27: =P27*0.7 -> 16950039 | R27: =P27*0.3 -> 7264302.3 | U27: =Q27 -> 16950039 | V27: =U27/$P27 -> 0.7 | W27: =U27/$Q27 -> 1
I28: 9 | J28: MSR Back Plane | K28: 51 | M28: 15300000 | N28: =M28 -> 15300000 | P28: =N28 -> 15300000 | Q28: =P28*0.7 -> 10710000 | R28: =P28*0.3 -> 4590000 | U28: =Q28 -> 10710000 | V28: =U28/$P28 -> 0.7 | W28: =U28/$Q28 -> 1
I29: 10 | J29: MOP CTL | K29: 51 | M29: 24156125 | N29: =M29 -> 24156125 | P29: =N29 -> 24156125 | Q29: =P29*0.7 -> 16909288 | R29: =P29*0.3 -> 7246837.5 | U29: =Q29 -> 16909288 | V29: =U29/$P29 -> 0.7 | W29: =U29/$Q29 -> 1
I30: 11 | J30: MOP LCD | K30: 51 | M30: 21685863 | N30: =M30 -> 21685863 | P30: =N30 -> 21685863 | Q30: =P30*0.7 -> 15180104 | R30: =P30*0.3 -> 6505758.9 | U30: =Q30 -> 15180104 | V30: =U30/$P30 -> 0.7 | W30: =U30/$Q30 -> 1
I31: 12 | J31: CTM CTL | K31: 51 | M31: 47120077 | N31: =M31 -> 47120077 | P31: =N31 -> 47120077 | Q31: =P31*0.7 -> 32984054 | R31: =P31*0.3 -> 14136023 | U31: =Q31 -> 32984054 | V31: =U31/$P31 -> 0.7 | W31: =U31/$Q31 -> 1
B32: 6 | C32: 한국 | D32: 지아이씨 | E32: CSP24-0923-1 | G32: 240923 | H32: 241231 | I32: 1 | J32: MSR PWR BOARD. FOR MSR. | K32: 10 | M32: =291760*K32 -> 2917600 | N32: =M32 -> 2917600 | P32: =N32 -> 2917600 | Q32: =P32 -> 2917600 | U32: 0 | V32: =U32/$P32 -> 0 | W32: =U32/$Q32 -> 0
H33: 241231 | I33: 2 | J33: LCD CONTROL BOARD. FOR MOP. | K33: 10 | M33: =818880*K33 -> 8188800 | N33: =M33 -> 8188800 | P33: =N33 -> 8188800 | Q33: =P33 -> 8188800 | U33: 0 | V33: =U33/$P33 -> 0 | W33: =U33/$Q33 -> 0
H34: 241231 | I34: 3 | J34: MAIN CONTROL BOARD. FOR MOP. | K34: 20 | M34: =938410*K34 -> 18768200 | N34: =M34 -> 18768200 | P34: =N34 -> 18768200 | Q34: =P34 -> 18768200 | U34: 0 | V34: =U34/$P34 -> 0 | W34: =U34/$Q34 -> 0
H35: 241231 | I35: 4 | J35: POWER BOARD. FOR MOP. | K35: 10 | M35: =187450*K35 -> 1874500 | N35: =M35 -> 1874500 | P35: =N35 -> 1874500 | Q35: =P35 -> 1874500 | U35: 0 | V35: =U35/$P35 -> 0 | W35: =U35/$Q35 -> 0
H36: 241231 | I36: 5 | J36: POWER BOARD. FOR CTM. | K36: 10 | M36: =224480*K36 -> 2244800 | N36: =M36 -> 2244800 | P36: =N36 -> 2244800 | Q36: =P36 -> 2244800 | U36: 0 | V36: =U36/$P36 -> 0 | W36: =U36/$Q36 -> 0
H37: 241231 | I37: 6 | J37: MSR HUB BOARD. FOR MSR. | K37: 10 | M37: =936830*K37 -> 9368300 | N37: =M37 -> 9368300 | P37: =N37 -> 9368300 | Q37: =P37 -> 9368300 | U37: =Q37 -> 9368300 | V37: =U37/$P37 -> 1 | W37: =U37/$Q37 -> 1 | X37: 24년 수주금액 입금 완료 | Y37: 241017 10개 전자세금계산서
H38: 241231 | I38: 7 | J38: MSR MTX BOARD. FOR MSR. | K38: 10 | M38: =1035220*K38 -> 10352200 | N38: =M38 -> 10352200 | P38: =N38 -> 10352200 | Q38: =P38 -> 10352200 | U38: =Q38*0.5 -> 5176100 | V38: =U38/$P38 -> 0.5 | W38: =U38/$Q38 -> 0.5 | X38: 240925 5개 전자세금계산서
H39: 250430 | I39: 8 | J39: MSR NVR BOARD. FOR MSR. | K39: 10 | M39: =3233680*K39 -> 32336800 | N39: =M39 -> 32336800 | P39: =N39 -> 32336800 | R39: =P39 -> 32336800 | U39: 0 | V39: =U39/$P39 -> 0 | W39: =U39/$Q39 -> #DIV/0!
H40: 241231 | I40: 9 | J40: MSR TCIU BOARD. FOR MSR. | K40: 10 | M40: =2058600*K40 -> 20586000 | N40: =M40 -> 20586000 | P40: =N40 -> 20586000 | Q40: =P40 -> 20586000 | U40: =Q40*0.5 -> 10293000 | V40: =U40/$P40 -> 0.5 | W40: =U40/$Q40 -> 0.5 | X40: 241017 2개 전자세금계산서 | Y40: 240925 3개 전자세금계산서
H41: 250430 | I41: 10 | J41: PSR HUB BOARD FOR PSR. | K41: 10 | M41: =937500*K41 -> 9375000 | N41: =M41 -> 9375000 | P41: =N41 -> 9375000 | Q41: =P41 -> 9375000 | U41: 0 | V41: =U41/$P41 -> 0 | W41: =U41/$Q41 -> 0
H42: 241231 | I42: 11 | J42: CONTROL BOARD. FOR CTM. | K42: 20 | M42: =2285280*K42 -> 45705600 | N42: =M42 -> 45705600 | P42: =N42 -> 45705600 | R42: =P42 -> 45705600 | U42: 0 | V42: =U42/$P42 -> 0 | W42: =U42/$Q42 -> #DIV/0!
...

Sheet 2.김포골드라인
B3: 순 | C3: 국가 | D3: 고객 | E3: 견적번호 | F3: RFQ no. | G3: 견적일 | H3: 유효일 | I3: Item | J3: 수량 | K3: 견적금액(외화) | L3: 견적금액(KRW) | M3: AB 등급 | N3: CD등급 | O3: 수주금액 (전체) | P3: 수주금액 (2024년) | Q3: 수주금액 (2025년) | R3: 원가 | S3: 비고
B4: 1 | C4: 한국 | D4: 김포골드라인 | E4: 202410041 | G4: 241004 | H4: 241019 | I4: 김포골드라인 10량분 | L4: 957811200 | M4: =L4 -> 957811200
C23: Sub-Amount | L23: =SUM(L4:L22) -> 957811200 | M23: =SUM(M4:M22) -> 957811200 | O23: =SUM(O4:O22) -> 0 | P23: =SUM(P4:P22) -> 0 | Q23: =SUM(Q4:Q22) -> 0 | R23: =SUM(R4:R22) -> 0

Sheet 3.교통공사
B3: 순 | C3: 국가 | D3: 고객 | E3: 견적번호 | F3: RFQ no. | G3: 견적일 | H3: 유효일 | I3: Item | J3: 수량 | K3: 견적금액(외화) | L3: 견적금액(KRW) | M3: AB 등급 | N3: CD등급 | O3: 수주금액 (전체) | P3: 수주금액 (2024년) | Q3: 수주금액 (2025년) | R3: 원가 | S3: 비고 | T3: 입금 총액 | U3: 입금 비율(전체) | V3: 입금 비율(2024)
B4: 1 | C4: 한국 | D4: 교통공사 | E4: 202408114 | G4: 240509 | H4: 240524 | I4: 7호선3차분 CSC교체품 | L4: 207254910 | M4: =L4 -> 207254910
B5: 2 | C5: 한국 | D5: 교통공사 | E5: 202411031 | G5: 241029 | H5: 241115 | I5: 7호선3차분CSC수리비 | L5: 1900000 | O5: =L5 -> 1900000 | P5: =O5 -> 1900000 | S5: PO 없음 | T5: 1900000 | U5: =$T5/O5 -> 1 | V5: =$T5/P5 -> 1 | W5: 계약 종료 / 24년 수주금액 입금 완료 | X5: 241126 전자세금계산서
C23: Sub-Amount | K23: =SUM(K4:K22) -> 0 | L23: =SUM(L4:L22) -> 209154910 | M23: =SUM(M4:M22) -> 207254910 | O23: =SUM(O4:O22) -> 1900000 | P23: =SUM(P4:P22) -> 1900000 | Q23: =SUM(Q4:Q22) -> 0 | R23: =SUM(R4:R22) -> 0 | T23: =SUM(T5:T22) -> 1900000 | U23: =$T23/O23 -> 1 | V23: =$T23/P23 -> 1

Sheet 4.실리콘큐브
B3: 순 | C3: 국가 | D3: 고객 | E3: 견적번호 | F3: RFQ no. | G3: 견적일 | H3: 유효일 | I3: Item | J3: 구분 | K3: 구분 | L3: 수량 | M3: 견적금액(외화) | N3: 견적금액(KRW) | O3: AB 등급 | P3: CD등급 | Q3: 수주금액 (전체) | R3: 수주금액 (2024년) | S3: 수주금액 (2025년) | T3: 원가 | U3: 비고 | V3: 입금 총액 | W3: 입금 비율(전체) | X3: 입금 비율(2024)
B4: 1 | C4: 한국 | D4: 실리콘큐브 | E4: 뉴펄스진행 | I4: 홍콩수리품 | J4: MSR/PSR/MOP/CTM 수리 | K4: MSR/PSR/MOP/CTM 수리 | N4: 46840000 | O4: =N4 -> 46840000 | Q4: =O4 -> 46840000 | R4: =Q4 -> 46840000 | U4: Total 반영 전 / PO없음 | V4: 46840000 | W4: =$V4/Q4 -> 1 | X4: =$V4/R4 -> 1 | Y4: 계약 종료 / 24년 수주금액 입금 완료 | Z4: 240717 전자세금계산서
C26: Sub-Amount | M26: =SUM(M4:M25) -> 0 | N26: =SUM(N4:N25) -> 46840000 | O26: =SUM(O4:O25) -> 46840000 | Q26: =SUM(Q4:Q25) -> 46840000 | R26: =SUM(R4:R25) -> 46840000 | S26: =SUM(S4:S25) -> 0 | T26: =SUM(T4:T25) -> 0 | V26: =SUM(V4:V25) -> 46840000 | W26: =$V26/Q26 -> 1 | X26: =$V26/R26 -> 1

Sheet 5.무한테크 (우진산전)
B2: 순 | C2: 국가 | D2: 고객 | E2: 견적번호 | F2: RFQ no. | G2: 견적일 | H2: 유효일 | I2: Item | J2: 구분 | K2: 수량 | L2: 견적금액(외화) | M2: 견적금액(KRW) | N2: AB 등급 | O2: CD등급 | P2: 수주금액 (전체) | Q2: 수주금액 (2024년) | R2: 수주금액 (2025년) | S2: 원가 | T2: 비고 | U2: 입금 총액 | V2: 입금 비율(전체) | W2: 입금 비율(2024)
B3: 1 | C3: 한국 | D3: 무한테크 | E3: 202409271 | G3: 240927 | H3: 241013 | I3: 인도네시아 MTX/MRX | K3: 10 | M3: 20350000 | O3: =M3 -> 20350000 | P3: 11400000 | Q3: 11400000 | U3: 0 | V3: =$U3/P3 -> 0 | W3: =$U3/Q3 -> 0
C25: Sub-Amount | L25: =SUM(L3:L24) -> 0 | M25: =SUM(M3:M24) -> 20350000 | N25: =SUM(N3:N24) -> 0 | O25: =SUM(O3:O24) -> 20350000 | P25: =SUM(P3:P24) -> 11400000 | Q25: =SUM(Q3:Q24) -> 11400000 | R25: =SUM(R3:R24) -> 0 | S25: =SUM(S3:S24) -> 0 | U25: =SUM(U3:U24) -> 0 | V25: =$U25/P25 -> 0 | W25: =$U25/Q25 -> 0

Sheet 6.다원시스
B3: 순 | C3: 국가 | D3: 고객 | E3: 견적번호 | F3: RFQ no. | G3: 견적일 | H3: 유효일 | I3: Item | J3: 수량 | K3: 견적금액(외화) | L3: 견적금액(KRW) | M3: AB 등급 | N3: CD등급 | O3: 수주금액 (전체) | P3: 수주금액 (2024년) | Q3: 수주금액 (2025년) | R3: 원가 | S3: 비고 | T3: 입금 총액 | U3: 입금 비율(전체) | V3: 입금 비율(2024)
B4: 1 | C4: 한국 | D4: 다원시스 | E4: DWE-2024-JUN-11-001 | G4: 240611 | H4: 250331 | I4: 서울 7호선 3차분 TCMS 개조 | L4: 270843306 | M4: =L4 -> 270843306 | O4: 270000000 | P4: 81000000 | Q4: =O4-P4 -> 189000000 | S4: 1. 선급금 30% (81,000,000 KRW) 2. 초도편성 검사완료 시(~240715) 30% 3. 초도 시운점검사 완료 시(~240915) 30% 4. 양산편성 완료 시(~250315) 10% | T4: 81000000 | U4: =$T4/O4 -> 0.3 | V4: =$T4/P4 -> 1 | W4: 240630 선급금 81,000,000 KRW 전자세금계산서
B5: 2 | C5: 한국 | D5: 다원시스 | E5: DWE-2024-AUG-29-001 | G5: 240829 | H5: 250630 | I5: 4호선 방송편집기 소프트웨어개발 | L5: 156423296 | M5: =L5 -> 156423296 | O5: 140000000 | P5: 42000000 | Q5: =O5-P5 -> 98000000 | S5: 1. 선급금 30% (42,000,000 KRW) 2. 1차 산출물 제출 후 실행팀 확인 서명 완료본 제출 시 30% 3. 발주처 승인 완료 시 40% | T5: 42000000 | U5: =$T5/O5 -> 0.3 | V5: =$T5/P5 -> 1 | W5: 240906 선급금 42,000,000 KRW 전자세금계산서
B6: 3 | C6: 한국 | D6: 다원시스 | G6: 240812 | H6: 240827 | I6: 7호선3차분TCMS개조관련외주용역 | L6: 349398820 | M6: =L6 -> 349398820
B7: 4 | C7: 한국 | D7: 다원시스 | G7: 241118 | H7: 241206 | I7: 고장분석기기고정용RACK시험기 | L7: 118513140 | M7: =L7 -> 118513140
B8: 5 | C8: 한국 | D8: 다원시스 | G8: 241118 | H8: 241206 | I8: 4호선210량 소프트웨어 개선비 | L8: 27967374 | N8: 27967374
C26: Sub-Amount | K26: =SUM(K4:K25) -> 0 | L26: =SUM(L4:L25) -> 923145936 | M26: =SUM(M4:M25) -> 895178562 | O26: =SUM(O4:O25) -> 410000000 | P26: =SUM(P4:P25) -> 123000000 | Q26: =SUM(Q4:Q25) -> 287000000 | R26: =SUM(R4:R25) -> 0 | T26: =SUM(T4:T25) -> 123000000 | U26: =$T26/O26 -> 0.3 | V26: =$T26/P26 -> 1

Sheet 7.티랩
B2: 순 | C2: 국가 | D2: 고객 | E2: 견적번호 | F2: RFQ no. | G2: 견적일 | H2: 유효일 | I2: Item | J2: 수량 | K2: 견적금액(외화) | L2: 견적금액(KRW) | M2: AB 등급 | N2: CD등급 | O2: 수주금액 (전체) | P2: 수주금액 (2024년) | Q2: 수주금액 (2025년) | R2: 원가 | S2: 비고
C25: Sub-Amount | K25: =SUM(K3:K24) -> 0 | L25: =SUM(L3:L24) -> 0 | M25: =SUM(M3:M24) -> 0 | N25: =SUM(N3:N24) -> 0 | O25: =SUM(O3:O24) -> 0 | P25: =SUM(P3:P24) -> 0 | Q25: =SUM(Q3:Q24) -> 0 | R25: =SUM(R3:R24) -> 0

Sheet 8.마루소프트
B2: 순 | C2: 국가 | D2: 고객 | E2: 견적번호 | F2: RFQ no. | G2: 견적일 | H2: 유효일 | I2: Item | J2: 수량 | K2: 견적금액(외화) | L2: 견적금액(KRW) | M2: AB 등급 | N2: CD등급 | O2: 수주금액 (전체) | P2: 수주금액 (2024년) | Q2: 수주금액 (2025년) | R2: 원가 | S2: 비고
B3: 1 | C3: 한국 | D3: 마루소프트 | E3: 202409061 | G3: 240906 | H3: 240921 | I3: 인도네시아LRT_CTM_견적_240906 | L3: 20350000 | M3: =L3 -> 20350000
C25: Sub-Amount | K25: =SUM(K3:K24) -> 0 | L25: =SUM(L3:L24) -> 20350000 | M25: =SUM(M3:M24) -> 20350000 | N25: =SUM(N3:N24) -> 0 | O25: =SUM(O3:O24) -> 0 | P25: =SUM(P3:P24) -> 0 | Q25: =SUM(Q3:Q24) -> 0 | R25: =SUM(R3:R24) -> 0

Sheet 9.신진금고
B2: 순 | C2: 국가 | D2: 고객 | E2: 견적번호 | F2: RFQ no. | G2: 견적일 | H2: 유효일 | I2: Item | J2: 수량 | K2: 견적금액(외화) | L2: 견적금액(KRW) | M2: AB 등급 | N2: CD등급 | O2: 수주금액 (전체) | P2: 수주금액 (2024년) | Q2: 수주금액 (2025년) | R2: 원가 | S2: 비고
B3: 1 | C3: 한국 | D3: 신진금고 | E3: 2024110701 | G3: 241107 | H3: 241122 | I3: 티렉디바이스(신진금고)_LCDDISPLAY | L3: 169299200 | M3: =L3 -> 169299200
C25: Sub-Amount | K25: =SUM(K3:K24) -> 0 | L25: =SUM(L3:L24) -> 169299200 | M25: =SUM(M3:M24) -> 169299200 | N25: =SUM(N3:N24) -> 0 | O25: =SUM(O3:O24) -> 0 | P25: =SUM(P3:P24) -> 0 | Q25: =SUM(Q3:Q24) -> 0 | R25: =SUM(R3:R24) -> 0
