Workbook

Sheet Total
B2: 순 | C2: 고객명 | D2: 전체수주가 | E2: 2024년 수주가 | F2: 2025년 수주가 | G2: 입금 총액 | H2: 미수금 | I2: 비고
B3: 1 | C3: ='1.지아이씨'!D4 -> 지아이씨 | D3: ='1.지아이씨'!L49 -> 1488279419 | E3: ='1.지아이씨'!M49 -> 1.0512461e+09 | F3: ='1.지아이씨'!N49 -> 4.3703328e+08 | G3: ='1.지아이씨'!O49 -> 1.0512461e+09 | H3: ='1.지아이씨'!P49 -> 0
B4: 2 | C4: 김포골드라인 | D4: ='2.김포골드라인'!L49 -> 0 | E4: ='2.김포골드라인'!M49 -> 0 | F4: ='2.김포골드라인'!N49 -> 0 | G4: ='2.김포골드라인'!O49 -> 0 | H4: ='2.김포골드라인'!P49 -> 0
B5: 3 | C5: 서울교통공사 | D5: ='3.서울교통공사'!L49 -> 1900000 | E5: ='3.서울교통공사'!M49 -> 1900000 | F5: ='3.서울교통공사'!N49 -> 0 | G5: ='3.서울교통공사'!O49 -> 1900000 | H5: ='3.서울교통공사'!P49 -> 0
B6: 4 | C6: 현대로템 | D6: ='4.현대로템'!L49 -> 0 | E6: ='4.현대로템'!M49 -> 0 | F6: ='4.현대로템'!N49 -> 0 | G6: ='4.현대로템'!O49 -> 0 | H6: ='4.현대로템'!P49 -> 0
B7: 5 | C7: 실리콘큐브 | D7: ='5.실리콘큐브'!L49 -> 46840000 | E7: ='5.실리콘큐브'!M49 -> 46840000 | F7: ='5.실리콘큐브'!N49 -> 0 | G7: ='5.실리콘큐브'!O49 -> 46840000 | H7: ='5.실리콘큐브'!P49 -> 0
B8: 6 | C8: 무한테크 | D8: ='6.무한테크(우진산전)'!L49 -> 11400000 | E8: ='6.무한테크(우진산전)'!M49 -> 11400000 | F8: ='6.무한테크(우진산전)'!N49 -> 0 | G8: ='6.무한테크(우진산전)'!O49 -> 11400000 | H8: ='6.무한테크(우진산전)'!P49 -> 0
B9: 7 | C9: 다원시스 | D9: ='7.다원시스'!L49 -> 410000000 | E9: ='7.다원시스'!M49 -> 123000000 | F9: ='7.다원시스'!N49 -> 287000000 | G9: ='7.다원시스'!O49 -> 123000000 | H9: ='7.다원시스'!P49 -> 0
B10: 8 | C10: 티랩 | D10: ='8.티랩'!L49 -> 0 | E10: ='8.티랩'!M49 -> 0 | F10: ='8.티랩'!N49 -> 0 | G10: ='8.티랩'!O49 -> 0 | H10: ='8.티랩'!P49 -> 0
B11: 9 | C11: 마루소프트 | D11: ='9.마루소프트'!L49 -> 0 | E11: ='9.마루소프트'!M49 -> 0 | F11: ='9.마루소프트'!N49 -> 0 | G11: ='9.마루소프트'!O49 -> 0 | H11: ='9.마루소프트'!P49 -> 0
B12: 10 | C12: 신진금고 | D12: ='10.신진금고'!L49 -> 0 | E12: ='10.신진금고'!M49 -> 0 | F12: ='10.신진금고'!N49 -> 0 | G12: ='10.신진금고'!O49 -> 0 | H12: ='10.신진금고'!P49 -> 0
C20: 소계 | D20: =SUM(D3:D12) -> 1958419419 | E20: =SUM(E3:E12) -> 1.2343861e+09 | F20: =SUM(F3:F11) -> 7.2403328e+08 | G20: =SUM(G3:G12) -> 1.2343861e+09 | H20: =SUM(H3:H12) -> 0

Sheet 1.지아이씨
B3: 순 | C3: 국가 | D3: 고객 | E3: PO | F3: RFQ no. | G3: 수주일 | H3: 납기 | I3: Item | J3: 구분 | K3: 수량 | L3: 수주금액 (전체) | M3: 수주금액 (2024년) | N3: 수주금액 (2025년) | O3: 입금 총액 | P3: 미수금 | Q3: 비고 | R3: 대금지불조건
B4: 1 | C4: 한국 | D4: 지아이씨 | E4: CSP24-0409-1 | G4: 240409 | H4: 240930 | J4: PAB, EID, PSR, ETND, EDD 생산 | L4: 423083700 | M4: 423083700 | O4: 423083700 | P4: =M4-O4 -> 0 | Q4: 1. 계약시 30% (126,925,110 KRW) 2. 제작 후 검사 전 30% 3. 검사 합격 후 납품 시 30% 4. 고객으로부터 물품대금 수령 후 잔금 10% | S4: 계약 종료 / 24년 수주금액 입금 완료 | T4: 241226 잔금 8,461,684 KRW | U4: 241216 납품분 및 잔금 103,957,709 KRW (EID 20, PSR 20, ETND 20, EDD 20 (잔금 10%), PAB 잔금(60%)) | V4: 241104 납품분 및 중도금 125,716,299 KRW (품목 ???) | W4: 240925 2차 중도금 29,011,454 KRW (PSR & EID 각 20EA) | X4: 240906 1차 중도금 29,011,454 KRW (PSR & EID 각 20EA) | Y4: 240411 선급금 126,925,100 KRW
B5: 2 | C5: 한국 | D5: 지아이씨 | E5: CSP24-0409-2 | G5: 240409 | H5: 240412 | I5: 1 | J5: MOP 수리(17031, R1C001388) | K5: 1 | L5: 270000 | M5: 270000 | O5: =L5 -> 270000 | P5: =M5-O5 -> 0 | S5: 계약 종료 / 24년 수주금액 입금 완료 | T5: 240411 전자세금계산서
H6: 240412 | I6: 2 | J6: MOP 수리(19067, R1C001388) | K6: 1 | L6: 900000 | M6: 900000 | O6: =L6 -> 900000 | P6: =M6-O6 -> 0
H7: 240412 | I7: 3 | J7: MSR HUB 수리(16006, R1B002192) | K7: 1 | L7: 1386000 | M7: 1386000 | O7: =L7 -> 1386000 | P7: =M7-O7 -> 0
H8: 240412 | I8: 4 | J8: MSR HUB 수리(19002, R1B002192) | K8: 1 | L8: 1386000 | M8: 1386000 | O8: =L8 -> 1386000 | P8: =M8-O8 -> 0
B9: 3 | C9: 한국 | D9: 지아이씨 | E9: CSP24-0524-1 | G9: 240524 | H9: 250227 | J9: MOP, MSR, CTM 생산 | L9: 350710750 | M9: 105213225 | N9: 2.4549752e+08 | O9: 105213225 | P9: =M9-O9 -> 0 | Q9: 1. 계약시 30% (105,213,225 KRW) 2. 제작 후 검사 전 30% 3. 검사 합격 후 납품 시 30% 4. 고객으로부터 물품대금 수령 후 잔금 10% | R9: 납품 후 계약조건 관계없이 정산 추진 | S9: 240524 선급금 105,213,225 KRW 전자세금계산서
B10: 4 | C10: 한국 | D10: 지아이씨 | E10: CSP24-0524-2 | G10: 240524 | H10: 240726 | I10: 1 | J10: PSR-HUB Board | K10: 82 | L10: 35260000 | M10: 35260000 | O10: =M10 -> 35260000 | P10: =M10-O10 -> 0 | S10: 계약 종료 / 24년 수주금액 입금 완료 | T10: 241209 잔금 59,343,000 KRW 전자세금계산서 | U10: 240524 선급금 138,467,000 KRW 전자세금계산서
I11: 2 | J11: PSR-VOIP Board | K11: 82 | L11: 27060000 | M11: 27060000 | O11: =M11 -> 27060000 | P11: =M11-O11 -> 0
I12: 3 | J12: PSR-PA-AMP1 Board | K12: 82 | L12: 27060000 | M12: 27060000 | O12: =M12 -> 27060000 | P12: =M12-O12 -> 0
I13: 4 | J13: PSR-PA-AMP2 Board | K13: 82 | L13: 15580000 | M13: 15580000 | O13: =M13 -> 15580000 | P13: =M13-O13 -> 0
I14: 5 | J14: PSR-BPB | K14: 82 | L14: 27060000 | M14: 27060000 | O14: =M14 -> 27060000 | P14: =M14-O14 -> 0
I15: 6 | J15: PAB-CONTROL Board | K15: 51 | L15: 16830000 | M15: 16830000 | O15: =M15 -> 16830000 | P15: =M15-O15 -> 0
I16: 7 | J16: EID-CONTROL Board | K16: 41 | L16: 22550000 | M16: 22550000 | O16: =M16 -> 22550000 | P16: =M16-O16 -> 0
I17: 8 | J17: EID-SENSOR Board | K17: 41 | L17: 2050000 | M17: 2050000 | O17: =M17 -> 2050000 | P17: =M17-O17 -> 0
I18: 9 | J18: EDD-CONTROL Board | K18: 21 | L18: 12180000 | M18: 12180000 | O18: =M18 -> 12180000 | P18: =M18-O18 -> 0
I19: 10 | J19: ETND-CONTROL Board | K19: 21 | L19: 12180000 | M19: 12180000 | O19: =M19 -> 12180000 | P19: =M19-O19 -> 0
B20: 5 | C20: 한국 | D20: 지아이씨 | E20: CSP24-0913-1 | G20: 240913 | H20: 250131 | I20: 1 | J20: MSR NVR | K20: 51 | L20: 46610077 | M20: 32627054 | N20: 13983023 | O20: =M20 -> 32627054 | P20: =M20-O20 -> 0 | Q20: 1. 계약 시 선금 70% | S20: 24년 수주금액 입금 완료 | T20: 240913 선금 70% 전자세금계산서
I21: 2 | J21: MSR HUB | K21: 51 | L21: 33882518 | M21: 23717763 | N21: 10164755 | O21: =M21 -> 23717763 | P21: =M21-O21 -> 0 | Q21: 2. 제작하고 검사 후 잔금 30%
I22: 3 | J22: MSR MTX | K22: 51 | L22: 31138841 | M22: 21797189 | N22: 9341652.3 | O22: =M22 -> 21797189 | P22: =M22-O22 -> 0
I23: 4 | J23: MSR TCIU HUB | K23: 51 | L23: 26181518 | M23: 18327063 | N23: 7854455.4 | O23: =M23 -> 18327063 | P23: =M23-O23 -> 0
I24: 5 | J24: MSR TCIU CTL | K24: 51 | L24: 31408809 | M24: 21986166 | N24: 9422642.7 | O24: =M24 -> 21986166 | P24: =M24-O24 -> 0
I25: 6 | J25: MSR PBX | K25: 51 | L25: 14739000 | M25: 10317300 | N25: 4421700 | O25: =M25 -> 10317300 | P25: =M25-O25 -> 0
I26: 7 | J26: MSR SSD | K26: 102 | L26: 34578000 | M26: 24204600 | N26: 10373400 | O26: =M26 -> 24204600 | P26: =M26-O26 -> 0
I27: 8 | J27: MSR ETX | K27: 51 | L27: 24214341 | M27: 16950039 | N27: 7264302.3 | O27: =M27 -> 16950039 | P27: =M27-O27 -> 0
I28: 9 | J28: MSR Back Plane | K28: 51 | L28: 15300000 | M28: 10710000 | N28: 4590000 | O28: =M28 -> 10710000 | P28: =M28-O28 -> 0
I29: 10 | J29: MOP CTL | K29: 51 | L29: 24156125 | M29: 16909288 | N29: 7246837.5 | O29: =M29 -> 16909288 | P29: =M29-O29 -> 0
I30: 11 | J30: MOP LCD | K30: 51 | L30: 21685863 | M30: 15180104 | N30: 6505758.9 | O30: =M30 -> 15180104 | P30: =M30-O30 -> 0
I31: 12 | J31: CTM CTL | K31: 51 | L31: 47120077 | M31: 32984054 | N31: 14136023 | O31: =M31 -> 32984054 | P31: =M31-O31 -> 0
B32: 6 | C32: 한국 | D32: 지아이씨 | E32: CSP24-0923-1 | G32: 240923 | H32: 241231 | I32: 1 | J32: MSR PWR BOARD. FOR MSR. | K32: 10 | L32: 2917600 | M32: 2917600 | O32: 2917600 | P32: =M32-O32 -> 0 | S32: 24년 수주금액 입금 완료 | T32: 241224 전자세금계산서
H33: 241231 | I33: 2 | J33: LCD CONTROL BOARD. FOR MOP. | K33: 10 | L33: 8188800 | M33: 0 | N33: 8188800 | O33: 0 | P33: =M33-O33 -> 0
H34: 241231 | I34: 3 | J34: MAIN CONTROL BOARD. FOR MOP. | K34: 20 | L34: 18768200 | M34: 18768200 | O34: 18768200 | P34: =M34-O34 -> 0 | S34: 24년 수주금액 입금 완료 | T34: 241224 전자세금계산서
H35: 241231 | I35: 4 | J35: POWER BOARD. FOR MOP. | K35: 10 | L35: 1874500 | M35: 1874500 | O35: 1874500 | P35: =M35-O35 -> 0 | S35: 24년 수주금액 입금 완료 | T35: 241224 전자세금계산서
H36: 241231 | I36: 5 | J36: POWER BOARD. FOR CTM. | K36: 10 | L36: 2244800 | M36: 2244800 | O36: 2244800 | P36: =M36-O36 -> 0 | S36: 24년 수주금액 입금 완료 | T36: 241224 전자세금계산서
H37: 241231 | I37: 6 | J37: MSR HUB BOARD. FOR MSR. | K37: 10 | L37: 9368300 | M37: 9368300 | O37: =M37 -> 9368300 | P37: =M37-O37 -> 0 | S37: 24년 수주금액 입금 완료 | T37: 241017 10개 전자세금계산서
H38: 241231 | I38: 7 | J38: MSR MTX BOARD. FOR MSR. | K38: 10 | L38: 10352200 | M38: 10352200 | O38: =M38*0.5*2 -> 10352200 | P38: =M38-O38 -> 0 | S38: 24년 수주금액 입금 완료 | T38: 241224 5개 전자세금계산서 | U38: 240925 5개 전자세금계산서
H39: 250430 | I39: 8 | J39: MSR NVR BOARD. FOR MSR. | K39: 10 | L39: 32336800 | N39: 32336800 | O39: 0 | P39: =M39-O39 -> 0
H40: 241231 | I40: 9 | J40: MSR TCIU BOARD. FOR MSR. | K40: 10 | L40: 20586000 | M40: 20586000 | O40: =M40*0.5*2 -> 20586000 | P40: =M40-O40 -> 0 | S40: 24년 수주금액 입금 완료 | T40: 241224 5개 전자세금계산서 | U40: 241017 2개 전자세금계산서 | V40: 240925 3개 전자세금계산서
H41: 250430 | I41: 10 | J41: PSR HUB BOARD FOR PSR. | K41: 10 | L41: 9375000 | M41: 9375000 | O41: 9375000 | P41: =M41-O41 -> 0 | S41: 24년 수주금액 입금 완료 | T41: 241224 5개 전자세금계산서
H42: 241231 | I42: 11 | J42: CONTROL BOARD. FOR CTM. | K42: 20 | L42: 45705600 | N42: 45705600 | O42: 0 | P42: =M42-O42 -> 0
...

Sheet 2.김포골드라인
B3: 순 | C3: 국가 | D3: 고객 | E3: PO | F3: RFQ no. | G3: 수주일 | H3: 납기 | I3: Item | J3: 구분 | K3: 수량 | L3: 수주금액 (전체) | M3: 수주금액 (2024년) | N3: 수주금액 (2025년) | O3: 입금 총액 | P3: 미수금 | Q3: 비고 | R3: 대금지불조건
B4: 1 | C4: 한국 | D4: 김포골드라인
C49: Sub-Amount | L49: =SUM(L4:L48) -> 0 | M49: =SUM(M4:M48) -> 0 | N49: =SUM(N4:N48) -> 0 | O49: =SUM(O4:O48) -> 0 | P49: =SUM(P4:P48) -> 0

Sheet 3.서울교통공사
B3: 순 | C3: 국가 | D3: 고객 | E3: PO | F3: RFQ no. | G3: 수주일 | H3: 납기 | I3: Item | J3: 구분 | K3: 수량 | L3: 수주금액 (전체) | M3: 수주금액 (2024년) | N3: 수주금액 (2025년) | O3: 입금 총액 | P3: 미수금 | Q3: 비고 | R3: 대금지불조건
B4: 1 | C4: 한국 | D4: 서울교통공사 | G4: 241029 | H4: 241115 | I4: 1 | J4: 7호선3차분CSC수리비 | L4: 1900000 | M4: 1900000 | N4: =L4-M4 -> 0 | O4: 1900000 | P4: =M4-O4 -> 0 | S4: 계약 종료 / 24년 수주금액 입금 완료 | T4: 241126 전자세금계산서
C49: Sub-Amount | L49: =SUM(L4:L48) -> 1900000 | M49: =SUM(M4:M48) -> 1900000 | N49: =SUM(N4:N48) -> 0 | O49: =SUM(O4:O48) -> 1900000 | P49: =SUM(P4:P48) -> 0

Sheet 4.현대로템
B3: 순 | C3: 국가 | D3: 고객 | E3: PO | F3: RFQ no. | G3: 수주일 | H3: 납기 | I3: Item | J3: 구분 | K3: 수량 | L3: 수주금액 (전체) | M3: 수주금액 (2024년) | N3: 수주금액 (2025년) | O3: 입금 총액 | P3: 미수금 | Q3: 비고 | R3: 대금지불조건
B4: 1 | C4: 한국 | D4: 현대로템
C49: Sub-Amount | L49: =SUM(L4:L48) -> 0 | M49: =SUM(M4:M48) -> 0 | N49: =SUM(N4:N48) -> 0 | O49: =SUM(O4:O48) -> 0 | P49: =SUM(P4:P48) -> 0

Sheet 5.실리콘큐브
B3: 순 | C3: 국가 | D3: 고객 | E3: PO | F3: RFQ no. | G3: 수주일 | H3: 납기 | I3: Item | J3: 구분 | K3: 수량 | L3: 수주금액 (전체) | M3: 수주금액 (2024년) | N3: 수주금액 (2025년) | O3: 입금 총액 | P3: 미수금 | Q3: 비고 | R3: 대금지불조건
B4: 1 | C4: 한국 | D4: 실리콘큐브 | I4: 1 | J4: 홍콩 MSR/PSR/MOP/CTM 수리 | L4: 46840000 | M4: 46840000 | N4: =L4-M4 -> 0 | O4: 46840000 | P4: =M4-O4 -> 0 | S4: 계약 종료 / 24년 수주금액 입금 완료 | T4: 240717 전자세금계산서
C49: Sub-Amount | L49: =SUM(L4:L48) -> 46840000 | M49: =SUM(M4:M48) -> 46840000 | N49: =SUM(N4:N48) -> 0 | O49: =SUM(O4:O48) -> 46840000 | P49: =SUM(P4:P48) -> 0

Sheet 6.무한테크(우진산전)
B3: 순 | C3: 국가 | D3: 고객 | E3: PO | F3: RFQ no. | G3: 수주일 | H3: 납기 | I3: Item | J3: 구분 | K3: 수량 | L3: 수주금액 (전체) | M3: 수주금액 (2024년) | N3: 수주금액 (2025년) | O3: 입금 총액 | P3: 미수금 | Q3: 비고 | R3: 대금지불조건
B4: 1 | C4: 한국 | D4: 무한테크 | E4: MT-241007-A | G4: 240927 | H4: 241013 | I4: 1 | J4: 인도네시아 MTX/MRX | L4: 11400000 | M4: 11400000 | N4: =L4-M4 -> 0 | O4: 11400000 | P4: =M4-O4 -> 0 | S4: 계약 종료 / 24년 수주금액 입금 완료 | T4: 241218 전자세금계산서
C49: Sub-Amount | L49: =SUM(L4:L48) -> 11400000 | M49: =SUM(M4:M48) -> 11400000 | N49: =SUM(N4:N48) -> 0 | O49: =SUM(O4:O48) -> 11400000 | P49: =SUM(P4:P48) -> 0

Sheet 7.다원시스
B3: 순 | C3: 국가 | D3: 고객 | E3: PO | F3: RFQ no. | G3: 수주일 | H3: 납기 | I3: Item | J3: 구분 | K3: 수량 | L3: 수주금액 (전체) | M3: 수주금액 (2024년) | N3: 수주금액 (2025년) | O3: 입금 총액 | P3: 미수금 | Q3: 비고 | R3: 대금지불조건
B4: 1 | C4: 한국 | D4: 다원시스 | E4: DWE-2024-JUN-11-001 | G4: 240611 | H4: 250331 | I4: 1 | J4: 서울 7호선 3차분 TCMS 개조 | L4: 270000000 | M4: 81000000 | N4: =L4-M4 -> 189000000 | O4: 81000000 | P4: =M4-O4 -> 0 | Q4: 1. 선급금 30% (81,000,000 KRW) 2. 초도편성 검사완료 시(~240715) 30% (25년 1월 초중순으로 연기됨) 3. 초도 시운점검사 완료 시(~240915) 30% 4. 양산편성 완료 시(~250315) 10% | S4: 240630 선급금 81,000,000 KRW 전자세금계산서
B5: 2 | C5: 한국 | D5: 다원시스 | E5: DWE-2024-AUG-29-001 | G5: 240829 | H5: 250630 | I5: 1 | J5: 4호선 방송편집기 소프트웨어개발 | L5: 140000000 | M5: 42000000 | N5: =L5-M5 -> 98000000 | O5: 42000000 | P5: =M5-O5 -> 0 | Q5: 1. 선급금 30% (42,000,000 KRW) 2. 1차 산출물 제출 후 실행팀 확인 서명 완료본 제출 시 30% (전자세금계산서 미수취) 3. 발주처 승인 완료 시 40% | S5: 240906 선급금 42,000,000 KRW 전자세금계산서
C49: Sub-Amount | L49: =SUM(L4:L48) -> 410000000 | M49: =SUM(M4:M48) -> 123000000 | N49: =SUM(N4:N48) -> 287000000 | O49: =SUM(O4:O48) -> 123000000 | P49: =SUM(P4:P48) -> 0

Sheet 8.티랩
B3: 순 | C3: 국가 | D3: 고객 | E3: PO | F3: RFQ no. | G3: 수주일 | H3: 납기 | I3: Item | J3: 구분 | K3: 수량 | L3: 수주금액 (전체) | M3: 수주금액 (2024년) | N3: 수주금액 (2025년) | O3: 입금 총액 | P3: 미수금 | Q3: 비고 | R3: 대금지불조건
B4: 1 | C4: 한국 | D4: 티랩
C49: Sub-Amount | L49: =SUM(L4:L48) -> 0 | M49: =SUM(M4:M48) -> 0 | N49: =SUM(N4:N48) -> 0 | O49: =SUM(O4:O48) -> 0 | P49: =SUM(P4:P48) -> 0

Sheet 9.마루소프트
B3: 순 | C3: 국가 | D3: 고객 | E3: PO | F3: RFQ no. | G3: 수주일 | H3: 납기 | I3: Item | J3: 구분 | K3: 수량 | L3: 수주금액 (전체) | M3: 수주금액 (2024년) | N3: 수주금액 (2025년) | O3: 입금 총액 | P3: 미수금 | Q3: 비고 | R3: 대금지불조건
B4: 1 | C4: 한국 | D4: 마루소프트
C49: Sub-Amount | L49: =SUM(L4:L48) -> 0 | M49: =SUM(M4:M48) -> 0 | N49: =SUM(N4:N48) -> 0 | O49: =SUM(O4:O48) -> 0 | P49: =SUM(P4:P48) -> 0

Sheet 10.신진금고
B3: 순 | C3: 국가 | D3: 고객 | E3: PO | F3: RFQ no. | G3: 수주일 | H3: 납기 | I3: Item | J3: 구분 | K3: 수량 | L3: 수주금액 (전체) | M3: 수주금액 (2024년) | N3: 수주금액 (2025년) | O3: 입금 총액 | P3: 미수금 | Q3: 비고 | R3: 대금지불조건
B4: 1 | C4: 한국 | D4: 신진금고
C49: Sub-Amount | L49: =SUM(L4:L48) -> 0 | M49: =SUM(M4:M48) -> 0 | N49: =SUM(N4:N48) -> 0 | O49: =SUM(O4:O48) -> 0 | P49: =SUM(P4:P48) -> 0
