Workbook

Sheet Total
D2: 견적가 | G2: 수주가
B3: 순 | C3: 고객명 | D3: 전체 | E3: AB등급 | F3: CD등급 | G3: 전체 | H3: 2024년 | I3: 수주율(%) | J3: 제조원가 | K3: 손익(%) | L3: 비고
B4: 1 | C4: 지아이씨 | D4: ='1.지아이씨'!Q49 -> 1446481819 | E4: ='1.지아이씨'!R49 -> 1446481819 | F4: ='1.지아이씨'!S49 -> 0 | G4: ='1.지아이씨'!O49 -> 1446481819 | H4: ='1.지아이씨'!P49 -> 1.0512461e+09 | I4: =G4/D4 -> 1 | L4: 2025년 1월 31일 수정계약 (사급 금액 제외)
B5: 2 | C5: 김포골드라인 | D5: ='2.김포골드라인'!Q49 -> 957811200 | E5: ='2.김포골드라인'!R49 -> 957811200 | F5: ='2.김포골드라인'!S49 -> 0 | G5: ='2.김포골드라인'!O49 -> 0 | H5: ='2.김포골드라인'!P49 -> 0 | I5: =G5/D5 -> 0
B6: 3 | C6: 서울교통공사 | D6: ='3.서울교통공사'!Q49 -> 209154910 | E6: ='3.서울교통공사'!R49 -> 209154910 | F6: ='3.서울교통공사'!S49 -> 0 | G6: ='3.서울교통공사'!O49 -> 1900000 | H6: ='3.서울교통공사'!P49 -> 1900000 | I6: =G6/D6 -> 0.0090841759
B7: 4 | C7: 현대로템 | D7: ='4.현대로템'!Q49 -> 11092600 | E7: ='4.현대로템'!R49 -> 11092600 | F7: ='4.현대로템'!S49 -> 0 | G7: ='4.현대로템'!O49 -> 0 | H7: ='4.현대로템'!P49 -> 0 | I7: =G7/D7 -> 0
B8: 5 | C8: 실리콘큐브 | D8: ='5.실리콘큐브'!Q49 -> 46840000 | E8: ='5.실리콘큐브'!R49 -> 46840000 | F8: ='5.실리콘큐브'!S49 -> 0 | G8: ='5.실리콘큐브'!O49 -> 46840000 | H8: ='5.실리콘큐브'!P49 -> 46840000 | I8: =G8/D8 -> 1
B9: 6 | C9: 무한테크 | D9: ='6.무한테크'!Q49 -> 20350000 | E9: ='6.무한테크'!R49 -> 20350000 | F9: ='6.무한테크'!S49 -> 0 | G9: ='6.무한테크'!O49 -> 11400000 | H9: ='6.무한테크'!P49 -> 11400000 | I9: =G9/D9 -> 0.56019656
B10: 7 | C10: 다원시스 | D10: ='7.다원시스'!Q49 -> 993145936 | E10: ='7.다원시스'!R49 -> 965178562 | F10: ='7.다원시스'!S49 -> 27967374 | G10: ='7.다원시스'!O49 -> 410000000 | H10: ='7.다원시스'!P49 -> 123000000 | I10: =G10/D10 -> 0.41282956
B11: 8 | C11: 티랩 | D11: ='8.티랩'!Q49 -> 482560000 | E11: ='8.티랩'!R49 -> 0 | F11: ='8.티랩'!S49 -> 482560000 | G11: ='8.티랩'!O49 -> 0 | H11: ='8.티랩'!P49 -> 0 | I11: =G11/D11 -> 0
B12: 9 | C12: 마루소프트 | D12: ='9.마루소프트'!Q49 -> 20350000 | E12: ='9.마루소프트'!R49 -> 20350000 | F12: ='9.마루소프트'!S49 -> 0 | G12: ='9.마루소프트'!O49 -> 0 | H12: ='9.마루소프트'!P49 -> 0 | I12: =G12/D12 -> 0
B13: 10 | C13: 신진금고 | D13: ='10.신진금고'!Q49 -> 169299200 | E13: ='10.신진금고'!R49 -> 169299200 | F13: ='10.신진금고'!S49 -> 0 | G13: ='10.신진금고'!O49 -> 0 | H13: ='10.신진금고'!P49 -> 0 | I13: =G13/D13 -> 0
B14: 11 | C14: 인터모빌리티 | D14: ='11.인터모빌리티'!Q49 -> 216099460 | E14: ='11.인터모빌리티'!R49 -> 216099460 | F14: ='11.인터모빌리티'!S49 -> 0 | G14: ='11.인터모빌리티'!O49 -> 0 | H14: ='11.인터모빌리티'!P49 -> 0 | I14: =G14/D14 -> 0
C15: 합계 | D15: =SUM(D4:D14) -> 4573185125 | E15: =SUM(E4:E14) -> 4062657751 | F15: =SUM(F4:F14) -> 510527374 | G15: =SUM(G4:G14) -> 1916621819 | H15: =SUM(H4:H14) -> 1.2343861e+09 | I15: =G15/D15 -> 0.41909999

Sheet 1.지아이씨
B3: 순 | C3: 국가 | D3: 고객 | E3: 견적번호 | F3: RFQ no. | G3: 견적일 | H3: 유효일 | I3: PO no. | J3: 수주일 | K3: 납기 | L3: Item | M3: 구분 | N3: 수량 | O3: 수주금액 (전체) | P3: 수주금액 (2024년) | Q3: 목표가 | R3: 견적가(AB) | S3: 견적가(CD) | T3: 제조원가 | U3: 손익(%) | V3: 입금 총액 | W3: 미수금 | X3: 비고
B4: 1 | C4: 한국 | D4: 지아이씨 | G4: 240409 | H4: 240930 | I4: CSP24-0409-1 | J4: 240409 | K4: 240930 | M4: PAB, EID, PSR, ETND, EDD 생산 | O4: 423083700 | P4: 423083700 | Q4: 423083700 | R4: 423083700 | V4: 423083700 | W4: =P4-V4 -> 0
B5: 2 | C5: 한국 | D5: 지아이씨 | G5: 240409 | H5: 240412 | I5: CSP24-0409-2 | J5: 240409 | K5: 240412 | L5: 1 | M5: MOP 수리(17031, R1C001388) | N5: 1 | O5: 270000 | P5: 270000 | Q5: 270000 | R5: 270000 | V5: 270000 | W5: =P5-V5 -> 0
L6: 2 | M6: MOP 수리(19067, R1C001388) | N6: 1 | O6: 900000 | P6: 900000 | Q6: 900000 | R6: 900000 | V6: 900000 | W6: =P6-V6 -> 0
L7: 3 | M7: MSR HUB 수리(16006, R1B002192) | N7: 1 | O7: 1386000 | P7: 1386000 | Q7: 1386000 | R7: 1386000 | V7: 1386000 | W7: =P7-V7 -> 0
L8: 4 | M8: MSR HUB 수리(19002, R1B002192) | N8: 1 | O8: 1386000 | P8: 1386000 | Q8: 1386000 | R8: 1386000 | V8: 1386000 | W8: =P8-V8 -> 0
B9: 3 | C9: 한국 | D9: 지아이씨 | G9: 240524 | H9: 250227 | I9: CSP24-0524-1 | J9: 240524 | K9: 250227 | M9: MOP, MSR, CTM 생산 | O9: 350710750 | P9: 105213225 | Q9: 350710750 | R9: 350710750 | V9: 105213225 | W9: =P9-V9 -> 0
B10: 4 | C10: 한국 | D10: 지아이씨 | G10: 240524 | H10: 240726 | I10: CSP24-0524-2 | J10: 240524 | K10: 240726 | L10: 1 | M10: PSR-HUB Board | N10: 82 | O10: 35260000 | P10: 35260000 | Q10: 35260000 | R10: 35260000 | V10: 35260000 | W10: =P10-V10 -> 0
L11: 2 | M11: PSR-VOIP Board | N11: 82 | O11: 27060000 | P11: 27060000 | Q11: 27060000 | R11: 27060000 | V11: 27060000 | W11: =P11-V11 -> 0
L12: 3 | M12: PSR-PA-AMP1 Board | N12: 82 | O12: 27060000 | P12: 27060000 | Q12: 27060000 | R12: 27060000 | V12: 27060000 | W12: =P12-V12 -> 0
L13: 4 | M13: PSR-PA-AMP2 Board | N13: 82 | O13: 15580000 | P13: 15580000 | Q13: 15580000 | R13: 15580000 | V13: 15580000 | W13: =P13-V13 -> 0
L14: 5 | M14: PSR-BPB | N14: 82 | O14: 27060000 | P14: 27060000 | Q14: 27060000 | R14: 27060000 | V14: 27060000 | W14: =P14-V14 -> 0
L15: 6 | M15: PAB-CONTROL Board | N15: 51 | O15: 16830000 | P15: 16830000 | Q15: 16830000 | R15: 16830000 | V15: 16830000 | W15: =P15-V15 -> 0
L16: 7 | M16: EID-CONTROL Board | N16: 41 | O16: 22550000 | P16: 22550000 | Q16: 22550000 | R16: 22550000 | V16: 22550000 | W16: =P16-V16 -> 0
L17: 8 | M17: EID-SENSOR Board | N17: 41 | O17: 2050000 | P17: 2050000 | Q17: 2050000 | R17: 2050000 | V17: 2050000 | W17: =P17-V17 -> 0
L18: 9 | M18: EDD-CONTROL Board | N18: 21 | O18: 12180000 | P18: 12180000 | Q18: 12180000 | R18: 12180000 | V18: 12180000 | W18: =P18-V18 -> 0
L19: 10 | M19: ETND-CONTROL Board | N19: 21 | O19: 12180000 | P19: 12180000 | Q19: 12180000 | R19: 12180000 | V19: 12180000 | W19: =P19-V19 -> 0
B20: 5 | C20: 한국 | D20: 지아이씨 | G20: 240913 | H20: 250131 | I20: CSP24-0913-1 | J20: 240913 | K20: 250131 | L20: 1 | M20: MSR NVR | N20: 51 | O20: 46610077 | P20: 32627054 | Q20: 46610077 | R20: 46610077 | V20: 32627054 | W20: =P20-V20 -> 0
L21: 2 | M21: MSR HUB | N21: 51 | O21: 33882518 | P21: 23717763 | Q21: 33882518 | R21: 33882518 | V21: 23717763 | W21: =P21-V21 -> 0
L22: 3 | M22: MSR MTX | N22: 51 | O22: 31138841 | P22: 21797189 | Q22: 31138841 | R22: 31138841 | V22: 21797189 | W22: =P22-V22 -> 0
L23: 4 | M23: MSR TCIU HUB | N23: 51 | O23: 26181518 | P23: 18327063 | Q23: 26181518 | R23: 26181518 | V23: 18327063 | W23: =P23-V23 -> 0
L24: 5 | M24: MSR TCIU CTL | N24: 51 | O24: 31408809 | P24: 21986166 | Q24: 31408809 | R24: 31408809 | V24: 21986166 | W24: =P24-V24 -> 0
L25: 6 | M25: MSR PBX | N25: 51 | O25: 14739000 | P25: 10317300 | Q25: 14739000 | R25: 14739000 | V25: 10317300 | W25: =P25-V25 -> 0
L26: 7 | M26: MSR SSD | N26: 102 | O26: 34578000 | P26: 24204600 | Q26: 34578000 | R26: 34578000 | V26: 24204600 | W26: =P26-V26 -> 0
L27: 8 | M27: MSR ETX | N27: 51 | O27: 24214341 | P27: 16950039 | Q27: 24214341 | R27: 24214341 | V27: 16950039 | W27: =P27-V27 -> 0
L28: 9 | M28: MSR Back Plane | N28: 51 | O28: 15300000 | P28: 10710000 | Q28: 15300000 | R28: 15300000 | V28: 10710000 | W28: =P28-V28 -> 0
L29: 10 | M29: MOP CTL | N29: 51 | O29: 24156125 | P29: 16909288 | Q29: 24156125 | R29: 24156125 | V29: 16909288 | W29: =P29-V29 -> 0
L30: 11 | M30: MOP LCD | N30: 51 | O30: 21685863 | P30: 15180104 | Q30: 21685863 | R30: 21685863 | V30: 15180104 | W30: =P30-V30 -> 0
L31: 12 | M31: CTM CTL | N31: 51 | O31: 47120077 | P31: 32984054 | Q31: 47120077 | R31: 47120077 | V31: 32984054 | W31: =P31-V31 -> 0
B32: 6 | C32: 한국 | D32: 지아이씨 | G32: 240923 | H32: 241231 | I32: CSP24-0923-1 | J32: 240923 | K32: 241231 | L32: 1 | M32: MSR PWR BOARD. FOR MSR. | N32: 10 | O32: 2917600 | P32: 2917600 | Q32: 2917600 | R32: 2917600 | V32: 2917600 | W32: =P32-V32 -> 0
H33: 241231 | K33: 241231 | L33: 2 | M33: LCD CONTROL BOARD. FOR MOP. | N33: 10 | O33: 8188800 | Q33: 8188800 | R33: 8188800 | V33: 0 | W33: =P33-V33 -> 0
H34: 241231 | K34: 241231 | L34: 3 | M34: MAIN CONTROL BOARD. FOR MOP. | N34: 20 | O34: 18768200 | P34: 18768200 | Q34: 18768200 | R34: 18768200 | V34: 18768200 | W34: =P34-V34 -> 0
H35: 241231 | K35: 241231 | L35: 4 | M35: POWER BOARD. FOR MOP. | N35: 10 | O35: 1874500 | P35: 1874500 | Q35: 1874500 | R35: 1874500 | V35: 1874500 | W35: =P35-V35 -> 0
H36: 241231 | K36: 241231 | L36: 5 | M36: POWER BOARD. FOR CTM. | N36: 10 | O36: 2244800 | P36: 2244800 | Q36: 2244800 | R36: 2244800 | V36: 2244800 | W36: =P36-V36 -> 0
H37: 241231 | K37: 241231 | L37: 6 | M37: MSR HUB BOARD. FOR MSR. | N37: 10 | O37: 9368300 | P37: 9368300 | Q37: 9368300 | R37: 9368300 | V37: 9368300 | W37: =P37-V37 -> 0
H38: 241231 | K38: 241231 | L38: 7 | M38: MSR MTX BOARD. FOR MSR. | N38: 10 | O38: 10352200 | P38: 10352200 | Q38: 10352200 | R38: 10352200 | V38: 10352200 | W38: =P38-V38 -> 0
H39: 250430 | K39: 250430 | L39: 8 | M39: MSR NVR BOARD. FOR MSR. | N39: 10 | O39: 12435200 | Q39: 12435200 | R39: 12435200 | V39: 0 | W39: =P39-V39 -> 0 | X39: 2025년 1월 31일 수정계약 (사급 금액 제외)
H40: 241231 | K40: 241231 | L40: 9 | M40: MSR TCIU BOARD. FOR MSR. | N40: 10 | O40: 20586000 | P40: 20586000 | Q40: 20586000 | R40: 20586000 | V40: 20586000 | W40: =P40-V40 -> 0
H41: 250430 | K41: 250430 | L41: 10 | M41: PSR HUB BOARD FOR PSR. | N41: 10 | O41: 9375000 | P41: 9375000 | Q41: 9375000 | R41: 9375000 | V41: 9375000 | W41: =P41-V41 -> 0
H42: 241231 | K42: 241231 | L42: 11 | M42: CONTROL BOARD. FOR CTM. | N42: 20 | O42: 23809600 | Q42: 23809600 | R42: 23809600 | V42: 0 | W42: =P42-V42 -> 0 | X42: 2025년 1월 31일 수정계약 (사급 금액 제외)
...

Sheet 2.김포골드라인
B3: 순 | C3: 국가 | D3: 고객 | E3: 견적번호 | F3: RFQ no. | G3: 견적일 | H3: 유효일 | I3: PO no. | J3: 수주일 | K3: 납기 | L3: Item | M3: 구분 | N3: 수량 | O3: 수주금액 (전체) | P3: 수주금액 (2024년) | Q3: 목표가 | R3: 견적가(AB) | S3: 견적가(CD) | T3: 제조원가 | U3: 손익(%) | V3: 입금 총액 | W3: 미수금 | X3: 비고
B4: 1 | C4: 한국 | D4: 김포골드라인 | E4: 202410041 | G4: 241004 | H4: 241019 | M4: 김포골드라인 10량분 | Q4: 957811200 | R4: 957811200
C49: Sub-Amount | O49: =SUM(O4:O48) -> 0 | P49: =SUM(P4:P48) -> 0 | Q49: =SUM(Q4:Q48) -> 957811200 | R49: =SUM(R4:R48) -> 957811200 | S49: =SUM(S4:S48) -> 0 | T49: =SUM(T4:T48) -> 0 | U49: =SUM(U4:U48) -> 0 | V49: =SUM(V4:V48) -> 0 | W49: =SUM(W4:W48) -> 0

Sheet 3.서울교통공사
B3: 순 | C3: 국가 | D3: 고객 | E3: 견적번호 | F3: RFQ no. | G3: 견적일 | H3: 유효일 | I3: PO no. | J3: 수주일 | K3: 납기 | L3: Item | M3: 구분 | N3: 수량 | O3: 수주금액 (전체) | P3: 수주금액 (2024년) | Q3: 목표가 | R3: 견적가(AB) | S3: 견적가(CD) | T3: 제조원가 | U3: 손익(%) | V3: 입금 총액 | W3: 미수금 | X3: 비고
B4: 1 | C4: 한국 | D4: 서울교통공사 | E4: 202408114 | G4: 240509 | H4: 240524 | M4: 7호선3차분 CSC교체품 | Q4: 207254910 | R4: 207254910
B5: 2 | C5: 한국 | D5: 서울교통공사 | E5: 202411031 | G5: 241029 | H5: 241115 | M5: 7호선3차분CSC수리비 | O5: 1900000 | P5: 1900000 | Q5: 1900000 | R5: 1900000 | V5: 1900000 | W5: =P5-V5 -> 0
C49: Sub-Amount | O49: =SUM(O4:O48) -> 1900000 | P49: =SUM(P4:P48) -> 1900000 | Q49: =SUM(Q4:Q48) -> 209154910 | R49: =SUM(R4:R48) -> 209154910 | S49: =SUM(S4:S48) -> 0 | T49: =SUM(T4:T48) -> 0 | U49: =SUM(U4:U48) -> 0 | V49: =SUM(V4:V48) -> 1900000 | W49: =SUM(W4:W48) -> 0

Sheet 4.현대로템
B3: 순 | C3: 국가 | D3: 고객 | E3: 견적번호 | F3: RFQ no. | G3: 견적일 | H3: 유효일 | I3: PO no. | J3: 수주일 | K3: 납기 | L3: Item | M3: 구분 | N3: 수량 | O3: 수주금액 (전체) | P3: 수주금액 (2024년) | Q3: 목표가 | R3: 견적가(AB) | S3: 견적가(CD) | T3: 제조원가 | U3: 손익(%) | V3: 입금 총액 | W3: 미수금 | X3: 비고
B4: 1 | C4: 한국 | D4: 현대로템 | E4: 2024122401 | G4: 241224 | H4: 250108 | M4: EIDS 수리비 및 보수품 | Q4: 11092600 | R4: 11092600
C49: Sub-Amount | O49: =SUM(O4:O48) -> 0 | P49: =SUM(P4:P48) -> 0 | Q49: =SUM(Q4:Q48) -> 11092600 | R49: =SUM(R4:R48) -> 11092600 | S49: =SUM(S4:S48) -> 0 | T49: =SUM(T4:T48) -> 0 | U49: =SUM(U4:U48) -> 0 | V49: =SUM(V4:V48) -> 0 | W49: =SUM(W4:W48) -> 0

Sheet 5.실리콘큐브
B3: 순 | C3: 국가 | D3: 고객 | E3: 견적번호 | F3: RFQ no. | G3: 견적일 | H3: 유효일 | I3: PO no. | J3: 수주일 | K3: 납기 | L3: Item | M3: 구분 | N3: 수량 | O3: 수주금액 (전체) | P3: 수주금액 (2024년) | Q3: 목표가 | R3: 견적가(AB) | S3: 견적가(CD) | T3: 제조원가 | U3: 손익(%) | V3: 입금 총액 | W3: 미수금 | X3: 비고
B4: 1 | C4: 한국 | D4: 실리콘큐브 | E4: 뉴펄스진행 | M4: 홍콩 수리품 | O4: 46840000 | P4: 46840000 | Q4: 46840000 | R4: 46840000 | V4: 46840000 | W4: =P4-V4 -> 0
C49: Sub-Amount | O49: =SUM(O4:O48) -> 46840000 | P49: =SUM(P4:P48) -> 46840000 | Q49: =SUM(Q4:Q48) -> 46840000 | R49: =SUM(R4:R48) -> 46840000 | S49: =SUM(S4:S48) -> 0 | T49: =SUM(T4:T48) -> 0 | U49: =SUM(U4:U48) -> 0 | V49: =SUM(V4:V48) -> 46840000 | W49: =SUM(W4:W48) -> 0

Sheet 6.무한테크
B3: 순 | C3: 국가 | D3: 고객 | E3: 견적번호 | F3: RFQ no. | G3: 견적일 | H3: 유효일 | I3: PO no. | J3: 수주일 | K3: 납기 | L3: Item | M3: 구분 | N3: 수량 | O3: 수주금액 (전체) | P3: 수주금액 (2024년) | Q3: 목표가 | R3: 견적가(AB) | S3: 견적가(CD) | T3: 제조원가 | U3: 손익(%) | V3: 입금 총액 | W3: 미수금 | X3: 비고
B4: 1 | C4: 한국 | D4: 무한테크 | E4: 202409271 | G4: 240927 | H4: 241013 | M4: 인도네시아 MTX/MRX | N4: 10 | O4: 11400000 | P4: 11400000 | Q4: 20350000 | R4: 20350000 | V4: 11400000 | W4: =P4-V4 -> 0
C49: Sub-Amount | O49: =SUM(O4:O48) -> 11400000 | P49: =SUM(P4:P48) -> 11400000 | Q49: =SUM(Q4:Q48) -> 20350000 | R49: =SUM(R4:R48) -> 20350000 | S49: =SUM(S4:S48) -> 0 | T49: =SUM(T4:T48) -> 0 | U49: =SUM(U4:U48) -> 0 | V49: =SUM(V4:V48) -> 11400000 | W49: =SUM(W4:W48) -> 0

Sheet 7.다원시스
B3: 순 | C3: 국가 | D3: 고객 | E3: 견적번호 | F3: RFQ no. | G3: 견적일 | H3: 유효일 | I3: PO no. | J3: 수주일 | K3: 납기 | L3: Item | M3: 구분 | N3: 수량 | O3: 수주금액 (전체) | P3: 수주금액 (2024년) | Q3: 목표가 | R3: 견적가(AB) | S3: 견적가(CD) | T3: 제조원가 | U3: 손익(%) | V3: 입금 총액 | W3: 미수금 | X3: 비고
B4: 1 | C4: 한국 | D4: 다원시스 | G4: 240611 | H4: 250331 | I4: DWE-2024-JUN-11-001 | M4: 서울7호선 3차분 TCMS 개조 | O4: 270000000 | P4: 81000000 | Q4: 270843306 | R4: 270843306 | V4: 81000000 | W4: =P4-V4 -> 0
B5: 2 | C5: 한국 | D5: 다원시스 | E5: 202406241 | G5: 240829 | H5: 250630 | I5: DWE-2024-AUG-29-001 | M5: 4호선 방송편집기 소프트웨어개발 | O5: 140000000 | P5: 42000000 | Q5: 156423296 | R5: 156423296 | V5: 42000000 | W5: =P5-V5 -> 0
B6: 3 | C6: 한국 | D6: 다원시스 | E6: 202408111 | G6: 240812 | H6: 240827 | M6: 7호선3차분TCMS개조관련외주용역 | Q6: 349398820 | R6: 349398820
B7: 4 | C7: 한국 | D7: 다원시스 | E7: 2024111802 | G7: 241118 | H7: 241206 | M7: 고장분석기기고정용RACK시험기 | Q7: 118513140 | R7: 118513140
B8: 5 | C8: 한국 | D8: 다원시스 | E8: 2024111901 | G8: 241119 | H8: 241207 | M8: 4호선210량 방송 소프트웨어 개선비 | Q8: 27967374 | S8: 27967374
B9: 6 | C9: 한국 | D9: 다원시스 | E9: 2024121901 | G9: 241219 | H9: 250103 | M9: 4호선210량 소프트웨어 1년 개선비 + 기존 업데이트 빙용 | Q9: 70000000 | R9: 70000000
C49: Sub-Amount | O49: =SUM(O4:O48) -> 410000000 | P49: =SUM(P4:P48) -> 123000000 | Q49: =SUM(Q4:Q48) -> 993145936 | R49: =SUM(R4:R48) -> 965178562 | S49: =SUM(S4:S48) -> 27967374 | T49: =SUM(T4:T48) -> 0 | U49: =SUM(U4:U48) -> 0 | V49: =SUM(V4:V48) -> 123000000 | W49: =SUM(W4:W48) -> 0

Sheet 8.티랩
B3: 순 | C3: 국가 | D3: 고객 | E3: 견적번호 | F3: RFQ no. | G3: 견적일 | H3: 유효일 | I3: PO no. | J3: 수주일 | K3: 납기 | L3: Item | M3: 구분 | N3: 수량 | O3: 수주금액 (전체) | P3: 수주금액 (2024년) | Q3: 목표가 | R3: 견적가(AB) | S3: 견적가(CD) | T3: 제조원가 | U3: 손익(%) | V3: 입금 총액 | W3: 미수금 | X3: 비고
B4: 1 | C4: 한국 | D4: 티랩 | E4: 202407031 | G4: 240703 | H4: 240718 | M4: 인도네시아 TCMS 개량 | Q4: 482560000 | S4: 482560000
C49: Sub-Amount | O49: =SUM(O4:O48) -> 0 | P49: =SUM(P4:P48) -> 0 | Q49: =SUM(Q4:Q48) -> 482560000 | R49: =SUM(R4:R48) -> 0 | S49: =SUM(S4:S48) -> 482560000 | T49: =SUM(T4:T48) -> 0 | U49: =SUM(U4:U48) -> 0 | V49: =SUM(V4:V48) -> 0 | W49: =SUM(W4:W48) -> 0

Sheet 9.마루소프트
B3: 순 | C3: 국가 | D3: 고객 | E3: 견적번호 | F3: RFQ no. | G3: 견적일 | H3: 유효일 | I3: PO no. | J3: 수주일 | K3: 납기 | L3: Item | M3: 구분 | N3: 수량 | O3: 수주금액 (전체) | P3: 수주금액 (2024년) | Q3: 목표가 | R3: 견적가(AB) | S3: 견적가(CD) | T3: 제조원가 | U3: 손익(%) | V3: 입금 총액 | W3: 미수금 | X3: 비고
B4: 1 | C4: 한국 | D4: 마루소프트 | E4: 202409061 | G4: 240906 | H4: 240921 | M4: 인도네시아LRT_CTM | Q4: 20350000 | R4: 20350000
C49: Sub-Amount | O49: =SUM(O4:O48) -> 0 | P49: =SUM(P4:P48) -> 0 | Q49: =SUM(Q4:Q48) -> 20350000 | R49: =SUM(R4:R48) -> 20350000 | S49: =SUM(S4:S48) -> 0 | T49: =SUM(T4:T48) -> 0 | U49: =SUM(U4:U48) -> 0 | V49: =SUM(V4:V48) -> 0 | W49: =SUM(W4:W48) -> 0

Sheet 10.신진금고
B3: 순 | C3: 국가 | D3: 고객 | E3: 견적번호 | F3: RFQ no. | G3: 견적일 | H3: 유효일 | I3: PO no. | J3: 수주일 | K3: 납기 | L3: Item | M3: 구분 | N3: 수량 | O3: 수주금액 (전체) | P3: 수주금액 (2024년) | Q3: 목표가 | R3: 견적가(AB) | S3: 견적가(CD) | T3: 제조원가 | U3: 손익(%) | V3: 입금 총액 | W3: 미수금 | X3: 비고
B4: 1 | C4: 한국 | D4: 신진금고 | E4: 2024110701 | G4: 241107 | H4: 241122 | M4: 티렉디바이스(신진금고)_LCDDISPLAY | Q4: 169299200 | R4: 169299200
C49: Sub-Amount | O49: =SUM(O4:O48) -> 0 | P49: =SUM(P4:P48) -> 0 | Q49: =SUM(Q4:Q48) -> 169299200 | R49: =SUM(R4:R48) -> 169299200 | S49: =SUM(S4:S48) -> 0 | T49: =SUM(T4:T48) -> 0 | U49: =SUM(U4:U48) -> 0 | V49: =SUM(V4:V48) -> 0 | W49: =SUM(W4:W48) -> 0

Sheet 11.인터모빌리티
B3: 순 | C3: 국가 | D3: 고객 | E3: 견적번호 | F3: RFQ no. | G3: 견적일 | H3: 유효일 | I3: PO no. | J3: 수주일 | K3: 납기 | L3: Item | M3: 구분 | N3: 수량 | O3: 수주금액 (전체) | P3: 수주금액 (2024년) | Q3: 목표가 | R3: 견적가(AB) | S3: 견적가(CD) | T3: 제조원가 | U3: 손익(%) | V3: 입금 총액 | W3: 미수금 | X3: 비고
B4: 1 | C4: 한국 | D4: 인터모빌리티 | E4: 2024111901 | G4: 241119 | H4: 241204 | M4: 인도네시아 자카르타 LRT 16량 | Q4: 216099460 | R4: 216099460
C49: Sub-Amount | O49: =SUM(O4:O48) -> 0 | P49: =SUM(P4:P48) -> 0 | Q49: =SUM(Q4:Q48) -> 216099460 | R49: =SUM(R4:R48) -> 216099460 | S49: =SUM(S4:S48) -> 0 | T49: =SUM(T4:T48) -> 0 | U49: =SUM(U4:U48) -> 0 | V49: =SUM(V4:V48) -> 0 | W49: =SUM(W4:W48) -> 0
