Workbook

Sheet 요약
B1: ■ 업체-PO 구매비용 요약 (입고 금액 기준) | U1: (단위 원화, VAT 별도) | X1: ■ 업체-현황 구매비용 요약 (입고 금액 기준) | AE1: (단위 원화, VAT 별도)
B2: 공급업체 \ PO | C2: GIC CSP24-0409-1호 | D2: GIC CSP24-0409-2호 | E2: GIC CSP24-0524-1호 | F2: GIC CSP24-0524-2호 | G2: GIC CSP24-0913-1호 | H2: GIC CSP24-0923-1호 | I2: DWE-2024-JUN-11-001 | J2: DWE-2024-AUG-29-001 | K2: 임시-7호선CSC-241029 | L2: 임시-7호선표시기-250107 | M2: HRCPO20250226-001 | N2: 임시-홍콩-시험기 | O2: 임시-IDN- 보수품 | P2: 20250711001 (현대자동차) | Q2: 신촌시험장치_20250728 | R2: 20250728001 (포스코) | S2: DH-비업시스-250731-1 | T2: 없음 | U2: 소계 | V2: 비율 (%) | X2: 공급업체 \ 현황 | Y2: 발주예정 | Z2: 발주완료 | AA2: 발주취소 | AB2: 선금지급 | AC2: 입고완료 | AD2: 결제완료 | AE2: 소계 | AF2: 비율 (%)
A3: 1 | B3: 고은효 | C3: =SUMIFS('구매 입고 현황'!$U$4:$U$189,'구매 입고 현황'!$E$4:$E$189,$B3,'구매 입고 현황'!$H$4:$H$189,C$2) -> 0 | D3: =SUMIFS('구매 입고 현황'!$U$4:$U$189,'구매 입고 현황'!$E$4:$E$189,$B3,'구매 입고 현황'!$H$4:$H$189,D$2) -> 0 | E3: =SUMIFS('구매 입고 현황'!$U$4:$U$189,'구매 입고 현황'!$E$4:$E$189,$B3,'구매 입고 현황'!$H$4:$H$189,E$2) -> 0 | F3: =SUMIFS('구매 입고 현황'!$U$4:$U$189,'구매 입고 현황'!$E$4:$E$189,$B3,'구매 입고 현황'!$H$4:$H$189,F$2) -> 0 | G3: =SUMIFS('구매 입고 현황'!$U$4:$U$189,'구매 입고 현황'!$E$4:$E$189,$B3,'구매 입고 현황'!$H$4:$H$189,G$2) -> 800000 | H3: =SUMIFS('구매 입고 현황'!$U$4:$U$189,'구매 입고 현황'!$E$4:$E$189,$B3,'구매 입고 현황'!$H$4:$H$189,H$2) -> 0 | I3: =SUMIFS('구매 입고 현황'!$U$4:$U$189,'구매 입고 현황'!$E$4:$E$189,$B3,'구매 입고 현황'!$H$4:$H$189,I$2) -> 0 | J3: =SUMIFS('구매 입고 현황'!$U$4:$U$189,'구매 입고 현황'!$E$4:$E$189,$B3,'구매 입고 현황'!$H$4:$H$189,J$2) -> 0 | ... T3: =SUMIFS('구매 입고 현황'!$U$4:$U$189,'구매 입고 현황'!$E$4:$E$189,$B3,'구매 입고 현황'!$H$4:$H$189,T$2) -> 0 | U3: =SUM(C3:T3) -> 800000 | V3: =U3/$U$46 -> 0.0011551976 | W3: 1 | X3: 고은효 | Y3: =SUMIFS('구매 입고 현황'!$U$4:$U$189,'구매 입고 현황'!$E$4:$E$189,$X3,'구매 입고 현황'!$L$4:$L$189,Y$2) -> 0 | Z3: =SUMIFS('구매 입고 현황'!$U$4:$U$189,'구매 입고 현황'!$E$4:$E$189,$X3,'구매 입고 현황'!$L$4:$L$189,Z$2) -> 0 | AA3: =SUMIFS('구매 입고 현황'!$U$4:$U$189,'구매 입고 현황'!$E$4:$E$189,$X3,'구매 입고 현황'!$L$4:$L$189,AA$2) -> 0 | AB3: =SUMIFS('구매 입고 현황'!$U$4:$U$189,'구매 입고 현황'!$E$4:$E$189,$X3,'구매 입고 현황'!$L$4:$L$189,AB$2) -> 0 | AC3: =SUMIFS('구매 입고 현황'!$U$4:$U$189,'구매 입고 현황'!$E$4:$E$189,$X3,'구매 입고 현황'!$L$4:$L$189,AC$2) -> 0 | AD3: =SUMIFS('구매 입고 현황'!$U$4:$U$189,'구매 입고 현황'!$E$4:$E$189,$X3,'구매 입고 현황'!$L$4:$L$189,AD$2) -> 800000 | AE3: =SUM(Y3:AD3) -> 800000 | AF3: =AE3/$AE$46 -> 0.0011498627
A4: 2 | B4: 김민석 | C4: =SUMIFS('구매 입고 현황'!$U$4:$U$189,'구매 입고 현황'!$E$4:$E$189,$B4,'구매 입고 현황'!$H$4:$H$189,C$2) -> 0 | D4: =SUMIFS('구매 입고 현황'!$U$4:$U$189,'구매 입고 현황'!$E$4:$E$189,$B4,'구매 입고 현황'!$H$4:$H$189,D$2) -> 0 | E4: =SUMIFS('구매 입고 현황'!$U$4:$U$189,'구매 입고 현황'!$E$4:$E$189,$B4,'구매 입고 현황'!$H$4:$H$189,E$2) -> 0 | F4: =SUMIFS('구매 입고 현황'!$U$4:$U$189,'구매 입고 현황'!$E$4:$E$189,$B4,'구매 입고 현황'!$H$4:$H$189,F$2) -> 0 | G4: =SUMIFS('구매 입고 현황'!$U$4:$U$189,'구매 입고 현황'!$E$4:$E$189,$B4,'구매 입고 현황'!$H$4:$H$189,G$2) -> 5400000 | H4: =SUMIFS('구매 입고 현황'!$U$4:$U$189,'구매 입고 현황'!$E$4:$E$189,$B4,'구매 입고 현황'!$H$4:$H$189,H$2) -> 0 | I4: =SUMIFS('구매 입고 현황'!$U$4:$U$189,'구매 입고 현황'!$E$4:$E$189,$B4,'구매 입고 현황'!$H$4:$H$189,I$2) -> 0 | J4: =SUMIFS('구매 입고 현황'!$U$4:$U$189,'구매 입고 현황'!$E$4:$E$189,$B4,'구매 입고 현황'!$H$4:$H$189,J$2) -> 0 | ... T4: =SUMIFS('구매 입고 현황'!$U$4:$U$189,'구매 입고 현황'!$E$4:$E$189,$B4,'구매 입고 현황'!$H$4:$H$189,T$2) -> 0 | U4: =SUM(C4:T4) -> 5400000 | V4: =U4/$U$46 -> 0.0077975838 | W4: 2 | X4: 김민석 | Y4: =SUMIFS('구매 입고 현황'!$U$4:$U$189,'구매 입고 현황'!$E$4:$E$189,$X4,'구매 입고 현황'!$L$4:$L$189,Y$2) -> 0 | Z4: =SUMIFS('구매 입고 현황'!$U$4:$U$189,'구매 입고 현황'!$E$4:$E$189,$X4,'구매 입고 현황'!$L$4:$L$189,Z$2) -> 0 | AA4: =SUMIFS('구매 입고 현황'!$U$4:$U$189,'구매 입고 현황'!$E$4:$E$189,$X4,'구매 입고 현황'!$L$4:$L$189,AA$2) -> 0 | AB4: =SUMIFS('구매 입고 현황'!$U$4:$U$189,'구매 입고 현황'!$E$4:$E$189,$X4,'구매 입고 현황'!$L$4:$L$189,AB$2) -> 0 | AC4: =SUMIFS('구매 입고 현황'!$U$4:$U$189,'구매 입고 현황'!$E$4:$E$189,$X4,'구매 입고 현황'!$L$4:$L$189,AC$2) -> 0 | AD4: =SUMIFS('구매 입고 현황'!$U$4:$U$189,'구매 입고 현황'!$E$4:$E$189,$X4,'구매 입고 현황'!$L$4:$L$189,AD$2) -> 5400000 | AE4: =SUM(Y4:AD4) -> 5400000 | AF4: =AE4/$AE$46 -> 0.0077615735
A5: 3 | B5: 김재현 | C5: =SUMIFS('구매 입고 현황'!$U$4:$U$189,'구매 입고 현황'!$E$4:$E$189,$B5,'구매 입고 현황'!$H$4:$H$189,C$2) -> 0 | D5: =SUMIFS('구매 입고 현황'!$U$4:$U$189,'구매 입고 현황'!$E$4:$E$189,$B5,'구매 입고 현황'!$H$4:$H$189,D$2) -> 0 | E5: =SUMIFS('구매 입고 현황'!$U$4:$U$189,'구매 입고 현황'!$E$4:$E$189,$B5,'구매 입고 현황'!$H$4:$H$189,E$2) -> 0 | F5: =SUMIFS('구매 입고 현황'!$U$4:$U$189,'구매 입고 현황'!$E$4:$E$189,$B5,'구매 입고 현황'!$H$4:$H$189,F$2) -> 0 | G5: =SUMIFS('구매 입고 현황'!$U$4:$U$189,'구매 입고 현황'!$E$4:$E$189,$B5,'구매 입고 현황'!$H$4:$H$189,G$2) -> 20000000 | H5: =SUMIFS('구매 입고 현황'!$U$4:$U$189,'구매 입고 현황'!$E$4:$E$189,$B5,'구매 입고 현황'!$H$4:$H$189,H$2) -> 0 | I5: =SUMIFS('구매 입고 현황'!$U$4:$U$189,'구매 입고 현황'!$E$4:$E$189,$B5,'구매 입고 현황'!$H$4:$H$189,I$2) -> 0 | J5: =SUMIFS('구매 입고 현황'!$U$4:$U$189,'구매 입고 현황'!$E$4:$E$189,$B5,'구매 입고 현황'!$H$4:$H$189,J$2) -> 0 | ... T5: =SUMIFS('구매 입고 현황'!$U$4:$U$189,'구매 입고 현황'!$E$4:$E$189,$B5,'구매 입고 현황'!$H$4:$H$189,T$2) -> 0 | U5: =SUM(C5:T5) -> 20000000 | V5: =U5/$U$46 -> 0.02887994 | W5: 3 | X5: 김재현 | Y5: =SUMIFS('구매 입고 현황'!$U$4:$U$189,'구매 입고 현황'!$E$4:$E$189,$X5,'구매 입고 현황'!$L$4:$L$189,Y$2) -> 0 | Z5: =SUMIFS('구매 입고 현황'!$U$4:$U$189,'구매 입고 현황'!$E$4:$E$189,$X5,'구매 입고 현황'!$L$4:$L$189,Z$2) -> 0 | AA5: =SUMIFS('구매 입고 현황'!$U$4:$U$189,'구매 입고 현황'!$E$4:$E$189,$X5,'구매 입고 현황'!$L$4:$L$189,AA$2) -> 0 | AB5: =SUMIFS('구매 입고 현황'!$U$4:$U$189,'구매 입고 현황'!$E$4:$E$189,$X5,'구매 입고 현황'!$L$4:$L$189,AB$2) -> 0 | AC5: =SUMIFS('구매 입고 현황'!$U$4:$U$189,'구매 입고 현황'!$E$4:$E$189,$X5,'구매 입고 현황'!$L$4:$L$189,AC$2) -> 0 | AD5: =SUMIFS('구매 입고 현황'!$U$4:$U$189,'구매 입고 현황'!$E$4:$E$189,$X5,'구매 입고 현황'!$L$4:$L$189,AD$2) -> 20000000 | AE5: =SUM(Y5:AD5) -> 20000000 | AF5: =AE5/$AE$46 -> 0.028746568
A6: 4 | B6: 나무 | C6: =SUMIFS('구매 입고 현황'!$U$4:$U$189,'구매 입고 현황'!$E$4:$E$189,$B6,'구매 입고 현황'!$H$4:$H$189,C$2) -> 0 | D6: =SUMIFS('구매 입고 현황'!$U$4:$U$189,'구매 입고 현황'!$E$4:$E$189,$B6,'구매 입고 현황'!$H$4:$H$189,D$2) -> 0 | E6: =SUMIFS('구매 입고 현황'!$U$4:$U$189,'구매 입고 현황'!$E$4:$E$189,$B6,'구매 입고 현황'!$H$4:$H$189,E$2) -> 0 | F6: =SUMIFS('구매 입고 현황'!$U$4:$U$189,'구매 입고 현황'!$E$4:$E$189,$B6,'구매 입고 현황'!$H$4:$H$189,F$2) -> 0 | G6: =SUMIFS('구매 입고 현황'!$U$4:$U$189,'구매 입고 현황'!$E$4:$E$189,$B6,'구매 입고 현황'!$H$4:$H$189,G$2) -> 0 | H6: =SUMIFS('구매 입고 현황'!$U$4:$U$189,'구매 입고 현황'!$E$4:$E$189,$B6,'구매 입고 현황'!$H$4:$H$189,H$2) -> 0 | I6: =SUMIFS('구매 입고 현황'!$U$4:$U$189,'구매 입고 현황'!$E$4:$E$189,$B6,'구매 입고 현황'!$H$4:$H$189,I$2) -> 0 | J6: =SUMIFS('구매 입고 현황'!$U$4:$U$189,'구매 입고 현황'!$E$4:$E$189,$B6,'구매 입고 현황'!$H$4:$H$189,J$2) -> 0 | ... T6: =SUMIFS('구매 입고 현황'!$U$4:$U$189,'구매 입고 현황'!$E$4:$E$189,$B6,'구매 입고 현황'!$H$4:$H$189,T$2) -> 0 | U6: =SUM(C6:T6) -> 224250 | V6: =U6/$U$46 -> 0.00032381633 | W6: 4 | X6: 나무 | Y6: =SUMIFS('구매 입고 현황'!$U$4:$U$189,'구매 입고 현황'!$E$4:$E$189,$X6,'구매 입고 현황'!$L$4:$L$189,Y$2) -> 0 | Z6: =SUMIFS('구매 입고 현황'!$U$4:$U$189,'구매 입고 현황'!$E$4:$E$189,$X6,'구매 입고 현황'!$L$4:$L$189,Z$2) -> 0 | AA6: =SUMIFS('구매 입고 현황'!$U$4:$U$189,'구매 입고 현황'!$E$4:$E$189,$X6,'구매 입고 현황'!$L$4:$L$189,AA$2) -> 0 | AB6: =SUMIFS('구매 입고 현황'!$U$4:$U$189,'구매 입고 현황'!$E$4:$E$189,$X6,'구매 입고 현황'!$L$4:$L$189,AB$2) -> 0 | AC6: =SUMIFS('구매 입고 현황'!$U$4:$U$189,'구매 입고 현황'!$E$4:$E$189,$X6,'구매 입고 현황'!$L$4:$L$189,AC$2) -> 0 | AD6: =SUMIFS('구매 입고 현황'!$U$4:$U$189,'구매 입고 현황'!$E$4:$E$189,$X6,'구매 입고 현황'!$L$4:$L$189,AD$2) -> 224250 | AE6: =SUM(Y6:AD6) -> 224250 | AF6: =AE6/$AE$46 -> 0.0003223209
A7: 5 | B7: 대성프로파일 | C7: =SUMIFS('구매 입고 현황'!$U$4:$U$189,'구매 입고 현황'!$E$4:$E$189,$B7,'구매 입고 현황'!$H$4:$H$189,C$2) -> 0 | D7: =SUMIFS('구매 입고 현황'!$U$4:$U$189,'구매 입고 현황'!$E$4:$E$189,$B7,'구매 입고 현황'!$H$4:$H$189,D$2) -> 0 | E7: =SUMIFS('구매 입고 현황'!$U$4:$U$189,'구매 입고 현황'!$E$4:$E$189,$B7,'구매 입고 현황'!$H$4:$H$189,E$2) -> 0 | F7: =SUMIFS('구매 입고 현황'!$U$4:$U$189,'구매 입고 현황'!$E$4:$E$189,$B7,'구매 입고 현황'!$H$4:$H$189,F$2) -> 0 | G7: =SUMIFS('구매 입고 현황'!$U$4:$U$189,'구매 입고 현황'!$E$4:$E$189,$B7,'구매 입고 현황'!$H$4:$H$189,G$2) -> 0 | H7: =SUMIFS('구매 입고 현황'!$U$4:$U$189,'구매 입고 현황'!$E$4:$E$189,$B7,'구매 입고 현황'!$H$4:$H$189,H$2) -> 0 | I7: =SUMIFS('구매 입고 현황'!$U$4:$U$189,'구매 입고 현황'!$E$4:$E$189,$B7,'구매 입고 현황'!$H$4:$H$189,I$2) -> 0 | J7: =SUMIFS('구매 입고 현황'!$U$4:$U$189,'구매 입고 현황'!$E$4:$E$189,$B7,'구매 입고 현황'!$H$4:$H$189,J$2) -> 0 | ... T7: =SUMIFS('구매 입고 현황'!$U$4:$U$189,'구매 입고 현황'!$E$4:$E$189,$B7,'구매 입고 현황'!$H$4:$H$189,T$2) -> 0 | U7: =SUM(C7:T7) -> 1300000 | V7: =U7/$U$46 -> 0.0018771961 | W7: 5 | X7: 대성프로파일 | Y7: =SUMIFS('구매 입고 현황'!$U$4:$U$189,'구매 입고 현황'!$E$4:$E$189,$X7,'구매 입고 현황'!$L$4:$L$189,Y$2) -> 0 | Z7: =SUMIFS('구매 입고 현황'!$U$4:$U$189,'구매 입고 현황'!$E$4:$E$189,$X7,'구매 입고 현황'!$L$4:$L$189,Z$2) -> 0 | AA7: =SUMIFS('구매 입고 현황'!$U$4:$U$189,'구매 입고 현황'!$E$4:$E$189,$X7,'구매 입고 현황'!$L$4:$L$189,AA$2) -> 0 | AB7: =SUMIFS('구매 입고 현황'!$U$4:$U$189,'구매 입고 현황'!$E$4:$E$189,$X7,'구매 입고 현황'!$L$4:$L$189,AB$2) -> 0 | AC7: =SUMIFS('구매 입고 현황'!$U$4:$U$189,'구매 입고 현황'!$E$4:$E$189,$X7,'구매 입고 현황'!$L$4:$L$189,AC$2) -> 0 | AD7: =SUMIFS('구매 입고 현황'!$U$4:$U$189,'구매 입고 현황'!$E$4:$E$189,$X7,'구매 입고 현황'!$L$4:$L$189,AD$2) -> 1300000 | AE7: =SUM(Y7:AD7) -> 1300000 | AF7: =AE7/$AE$46 -> 0.001868527
A8: 6 | B8: 대현테크 | C8: =SUMIFS('구매 입고 현황'!$U$4:$U$189,'구매 입고 현황'!$E$4:$E$189,$B8,'구매 입고 현황'!$H$4:$H$189,C$2) -> 0 | D8: =SUMIFS('구매 입고 현황'!$U$4:$U$189,'구매 입고 현황'!$E$4:$E$189,$B8,'구매 입고 현황'!$H$4:$H$189,D$2) -> 0 | E8: =SUMIFS('구매 입고 현황'!$U$4:$U$189,'구매 입고 현황'!$E$4:$E$189,$B8,'구매 입고 현황'!$H$4:$H$189,E$2) -> 0 | F8: =SUMIFS('구매 입고 현황'!$U$4:$U$189,'구매 입고 현황'!$E$4:$E$189,$B8,'구매 입고 현황'!$H$4:$H$189,F$2) -> 0 | G8: =SUMIFS('구매 입고 현황'!$U$4:$U$189,'구매 입고 현황'!$E$4:$E$189,$B8,'구매 입고 현황'!$H$4:$H$189,G$2) -> 0 | H8: =SUMIFS('구매 입고 현황'!$U$4:$U$189,'구매 입고 현황'!$E$4:$E$189,$B8,'구매 입고 현황'!$H$4:$H$189,H$2) -> 0 | I8: =SUMIFS('구매 입고 현황'!$U$4:$U$189,'구매 입고 현황'!$E$4:$E$189,$B8,'구매 입고 현황'!$H$4:$H$189,I$2) -> 0 | J8: =SUMIFS('구매 입고 현황'!$U$4:$U$189,'구매 입고 현황'!$E$4:$E$189,$B8,'구매 입고 현황'!$H$4:$H$189,J$2) -> 0 | ... T8: =SUMIFS('구매 입고 현황'!$U$4:$U$189,'구매 입고 현황'!$E$4:$E$189,$B8,'구매 입고 현황'!$H$4:$H$189,T$2) -> 0 | U8: =SUM(C8:T8) -> 2611000 | V8: =U8/$U$46 -> 0.0037702762 | W8: 6 | X8: 대현테크 | Y8: =SUMIFS('구매 입고 현황'!$U$4:$U$189,'구매 입고 현황'!$E$4:$E$189,$X8,'구매 입고 현황'!$L$4:$L$189,Y$2) -> 0 | Z8: =SUMIFS('구매 입고 현황'!$U$4:$U$189,'구매 입고 현황'!$E$4:$E$189,$X8,'구매 입고 현황'!$L$4:$L$189,Z$2) -> 0 | AA8: =SUMIFS('구매 입고 현황'!$U$4:$U$189,'구매 입고 현황'!$E$4:$E$189,$X8,'구매 입고 현황'!$L$4:$L$189,AA$2) -> 0 | AB8: =SUMIFS('구매 입고 현황'!$U$4:$U$189,'구매 입고 현황'!$E$4:$E$189,$X8,'구매 입고 현황'!$L$4:$L$189,AB$2) -> 0 | AC8: =SUMIFS('구매 입고 현황'!$U$4:$U$189,'구매 입고 현황'!$E$4:$E$189,$X8,'구매 입고 현황'!$L$4:$L$189,AC$2) -> 0 | AD8: =SUMIFS('구매 입고 현황'!$U$4:$U$189,'구매 입고 현황'!$E$4:$E$189,$X8,'구매 입고 현황'!$L$4:$L$189,AD$2) -> 2611000 | AE8: =SUM(Y8:AD8) -> 2611000 | AF8: =AE8/$AE$46 -> 0.0037528645
A9: 7 | B9: 드림온테크 유한회사 | C9: =SUMIFS('구매 입고 현황'!$U$4:$U$189,'구매 입고 현황'!$E$4:$E$189,$B9,'구매 입고 현황'!$H$4:$H$189,C$2) -> 0 | D9: =SUMIFS('구매 입고 현황'!$U$4:$U$189,'구매 입고 현황'!$E$4:$E$189,$B9,'구매 입고 현황'!$H$4:$H$189,D$2) -> 0 | E9: =SUMIFS('구매 입고 현황'!$U$4:$U$189,'구매 입고 현황'!$E$4:$E$189,$B9,'구매 입고 현황'!$H$4:$H$189,E$2) -> 80000000 | F9: =SUMIFS('구매 입고 현황'!$U$4:$U$189,'구매 입고 현황'!$E$4:$E$189,$B9,'구매 입고 현황'!$H$4:$H$189,F$2) -> 0 | G9: =SUMIFS('구매 입고 현황'!$U$4:$U$189,'구매 입고 현황'!$E$4:$E$189,$B9,'구매 입고 현황'!$H$4:$H$189,G$2) -> 0 | H9: =SUMIFS('구매 입고 현황'!$U$4:$U$189,'구매 입고 현황'!$E$4:$E$189,$B9,'구매 입고 현황'!$H$4:$H$189,H$2) -> 0 | I9: =SUMIFS('구매 입고 현황'!$U$4:$U$189,'구매 입고 현황'!$E$4:$E$189,$B9,'구매 입고 현황'!$H$4:$H$189,I$2) -> 0 | J9: =SUMIFS('구매 입고 현황'!$U$4:$U$189,'구매 입고 현황'!$E$4:$E$189,$B9,'구매 입고 현황'!$H$4:$H$189,J$2) -> 0 | ... T9: =SUMIFS('구매 입고 현황'!$U$4:$U$189,'구매 입고 현황'!$E$4:$E$189,$B9,'구매 입고 현황'!$H$4:$H$189,T$2) -> 0 | U9: =SUM(C9:T9) -> 80000000 | V9: =U9/$U$46 -> 0.11551976 | W9: 7 | X9: 드림온테크 유한회사 | Y9: =SUMIFS('구매 입고 현황'!$U$4:$U$189,'구매 입고 현황'!$E$4:$E$189,$X9,'구매 입고 현황'!$L$4:$L$189,Y$2) -> 0 | Z9: =SUMIFS('구매 입고 현황'!$U$4:$U$189,'구매 입고 현황'!$E$4:$E$189,$X9,'구매 입고 현황'!$L$4:$L$189,Z$2) -> 0 | AA9: =SUMIFS('구매 입고 현황'!$U$4:$U$189,'구매 입고 현황'!$E$4:$E$189,$X9,'구매 입고 현황'!$L$4:$L$189,AA$2) -> 0 | AB9: =SUMIFS('구매 입고 현황'!$U$4:$U$189,'구매 입고 현황'!$E$4:$E$189,$X9,'구매 입고 현황'!$L$4:$L$189,AB$2) -> 0 | AC9: =SUMIFS('구매 입고 현황'!$U$4:$U$189,'구매 입고 현황'!$E$4:$E$189,$X9,'구매 입고 현황'!$L$4:$L$189,AC$2) -> 0 | AD9: =SUMIFS('구매 입고 현황'!$U$4:$U$189,'구매 입고 현황'!$E$4:$E$189,$X9,'구매 입고 현황'!$L$4:$L$189,AD$2) -> 80000000 | AE9: =SUM(Y9:AD9) -> 80000000 | AF9: =AE9/$AE$46 -> 0.11498627
A10: 8 | B10: 디에스테크놀러지 | C10: =SUMIFS('구매 입고 현황'!$U$4:$U$189,'구매 입고 현황'!$E$4:$E$189,$B10,'구매 입고 현황'!$H$4:$H$189,C$2) -> 0 | D10: =SUMIFS('구매 입고 현황'!$U$4:$U$189,'구매 입고 현황'!$E$4:$E$189,$B10,'구매 입고 현황'!$H$4:$H$189,D$2) -> 0 | E10: =SUMIFS('구매 입고 현황'!$U$4:$U$189,'구매 입고 현황'!$E$4:$E$189,$B10,'구매 입고 현황'!$H$4:$H$189,E$2) -> 0 | F10: =SUMIFS('구매 입고 현황'!$U$4:$U$189,'구매 입고 현황'!$E$4:$E$189,$B10,'구매 입고 현황'!$H$4:$H$189,F$2) -> 0 | G10: =SUMIFS('구매 입고 현황'!$U$4:$U$189,'구매 입고 현황'!$E$4:$E$189,$B10,'구매 입고 현황'!$H$4:$H$189,G$2) -> 0 | H10: =SUMIFS('구매 입고 현황'!$U$4:$U$189,'구매 입고 현황'!$E$4:$E$189,$B10,'구매 입고 현황'!$H$4:$H$189,H$2) -> 3300000 | I10: =SUMIFS('구매 입고 현황'!$U$4:$U$189,'구매 입고 현황'!$E$4:$E$189,$B10,'구매 입고 현황'!$H$4:$H$189,I$2) -> 0 | J10: =SUMIFS('구매 입고 현황'!$U$4:$U$189,'구매 입고 현황'!$E$4:$E$189,$B10,'구매 입고 현황'!$H$4:$H$189,J$2) -> 0 | ... T10: =SUMIFS('구매 입고 현황'!$U$4:$U$189,'구매 입고 현황'!$E$4:$E$189,$B10,'구매 입고 현황'!$H$4:$H$189,T$2) -> 0 | U10: =SUM(C10:T10) -> 3300000 | V10: =U10/$U$46 -> 0.0047651901 | W10: 8 | X10: 디에스테크놀러지 | Y10: =SUMIFS('구매 입고 현황'!$U$4:$U$189,'구매 입고 현황'!$E$4:$E$189,$X10,'구매 입고 현황'!$L$4:$L$189,Y$2) -> 0 | Z10: =SUMIFS('구매 입고 현황'!$U$4:$U$189,'구매 입고 현황'!$E$4:$E$189,$X10,'구매 입고 현황'!$L$4:$L$189,Z$2) -> 0 | AA10: =SUMIFS('구매 입고 현황'!$U$4:$U$189,'구매 입고 현황'!$E$4:$E$189,$X10,'구매 입고 현황'!$L$4:$L$189,AA$2) -> 0 | AB10: =SUMIFS('구매 입고 현황'!$U$4:$U$189,'구매 입고 현황'!$E$4:$E$189,$X10,'구매 입고 현황'!$L$4:$L$189,AB$2) -> 0 | AC10: =SUMIFS('구매 입고 현황'!$U$4:$U$189,'구매 입고 현황'!$E$4:$E$189,$X10,'구매 입고 현황'!$L$4:$L$189,AC$2) -> 0 | AD10: =SUMIFS('구매 입고 현황'!$U$4:$U$189,'구매 입고 현황'!$E$4:$E$189,$X10,'구매 입고 현황'!$L$4:$L$189,AD$2) -> 3300000 | AE10: =SUM(Y10:AD10) -> 3300000 | AF10: =AE10/$AE$46 -> 0.0047431838
A11: 9 | B11: 만능 | C11: =SUMIFS('구매 입고 현황'!$U$4:$U$189,'구매 입고 현황'!$E$4:$E$189,$B11,'구매 입고 현황'!$H$4:$H$189,C$2) -> 0 | D11: =SUMIFS('구매 입고 현황'!$U$4:$U$189,'구매 입고 현황'!$E$4:$E$189,$B11,'구매 입고 현황'!$H$4:$H$189,D$2) -> 0 | E11: =SUMIFS('구매 입고 현황'!$U$4:$U$189,'구매 입고 현황'!$E$4:$E$189,$B11,'구매 입고 현황'!$H$4:$H$189,E$2) -> 0 | F11: =SUMIFS('구매 입고 현황'!$U$4:$U$189,'구매 입고 현황'!$E$4:$E$189,$B11,'구매 입고 현황'!$H$4:$H$189,F$2) -> 0 | G11: =SUMIFS('구매 입고 현황'!$U$4:$U$189,'구매 입고 현황'!$E$4:$E$189,$B11,'구매 입고 현황'!$H$4:$H$189,G$2) -> 0 | H11: =SUMIFS('구매 입고 현황'!$U$4:$U$189,'구매 입고 현황'!$E$4:$E$189,$B11,'구매 입고 현황'!$H$4:$H$189,H$2) -> 0 | I11: =SUMIFS('구매 입고 현황'!$U$4:$U$189,'구매 입고 현황'!$E$4:$E$189,$B11,'구매 입고 현황'!$H$4:$H$189,I$2) -> 0 | J11: =SUMIFS('구매 입고 현황'!$U$4:$U$189,'구매 입고 현황'!$E$4:$E$189,$B11,'구매 입고 현황'!$H$4:$H$189,J$2) -> 0 | ... T11: =SUMIFS('구매 입고 현황'!$U$4:$U$189,'구매 입고 현황'!$E$4:$E$189,$B11,'구매 입고 현황'!$H$4:$H$189,T$2) -> 0 | U11: =SUM(C11:T11) -> 1939000 | V11: =U11/$U$46 -> 0.0027999102 | W11: 9 | X11: 만능 | Y11: =SUMIFS('구매 입고 현황'!$U$4:$U$189,'구매 입고 현황'!$E$4:$E$189,$X11,'구매 입고 현황'!$L$4:$L$189,Y$2) -> 0 | Z11: =SUMIFS('구매 입고 현황'!$U$4:$U$189,'구매 입고 현황'!$E$4:$E$189,$X11,'구매 입고 현황'!$L$4:$L$189,Z$2) -> 0 | AA11: =SUMIFS('구매 입고 현황'!$U$4:$U$189,'구매 입고 현황'!$E$4:$E$189,$X11,'구매 입고 현황'!$L$4:$L$189,AA$2) -> 0 | AB11: =SUMIFS('구매 입고 현황'!$U$4:$U$189,'구매 입고 현황'!$E$4:$E$189,$X11,'구매 입고 현황'!$L$4:$L$189,AB$2) -> 0 | AC11: =SUMIFS('구매 입고 현황'!$U$4:$U$189,'구매 입고 현황'!$E$4:$E$189,$X11,'구매 입고 현황'!$L$4:$L$189,AC$2) -> 0 | AD11: =SUMIFS('구매 입고 현황'!$U$4:$U$189,'구매 입고 현황'!$E$4:$E$189,$X11,'구매 입고 현황'!$L$4:$L$189,AD$2) -> 1939000 | AE11: =SUM(Y11:AD11) -> 1939000 | AF11: =AE11/$AE$46 -> 0.0027869798
A12: 10 | B12: 메카전자 | C12: =SUMIFS('구매 입고 현황'!$U$4:$U$189,'구매 입고 현황'!$E$4:$E$189,$B12,'구매 입고 현황'!$H$4:$H$189,C$2) -> 7040000 | D12: =SUMIFS('구매 입고 현황'!$U$4:$U$189,'구매 입고 현황'!$E$4:$E$189,$B12,'구매 입고 현황'!$H$4:$H$189,D$2) -> 0 | E12: =SUMIFS('구매 입고 현황'!$U$4:$U$189,'구매 입고 현황'!$E$4:$E$189,$B12,'구매 입고 현황'!$H$4:$H$189,E$2) -> 0 | F12: =SUMIFS('구매 입고 현황'!$U$4:$U$189,'구매 입고 현황'!$E$4:$E$189,$B12,'구매 입고 현황'!$H$4:$H$189,F$2) -> 0 | G12: =SUMIFS('구매 입고 현황'!$U$4:$U$189,'구매 입고 현황'!$E$4:$E$189,$B12,'구매 입고 현황'!$H$4:$H$189,G$2) -> 33325280 | H12: =SUMIFS('구매 입고 현황'!$U$4:$U$189,'구매 입고 현황'!$E$4:$E$189,$B12,'구매 입고 현황'!$H$4:$H$189,H$2) -> 0 | I12: =SUMIFS('구매 입고 현황'!$U$4:$U$189,'구매 입고 현황'!$E$4:$E$189,$B12,'구매 입고 현황'!$H$4:$H$189,I$2) -> 0 | J12: =SUMIFS('구매 입고 현황'!$U$4:$U$189,'구매 입고 현황'!$E$4:$E$189,$B12,'구매 입고 현황'!$H$4:$H$189,J$2) -> 0 | ... T12: =SUMIFS('구매 입고 현황'!$U$4:$U$189,'구매 입고 현황'!$E$4:$E$189,$B12,'구매 입고 현황'!$H$4:$H$189,T$2) -> 0 | U12: =SUM(C12:T12) -> 40365280 | V12: =U12/$U$46 -> 0.058287343 | W12: 10 | X12: 메카전자 | Y12: =SUMIFS('구매 입고 현황'!$U$4:$U$189,'구매 입고 현황'!$E$4:$E$189,$X12,'구매 입고 현황'!$L$4:$L$189,Y$2) -> 0 | Z12: =SUMIFS('구매 입고 현황'!$U$4:$U$189,'구매 입고 현황'!$E$4:$E$189,$X12,'구매 입고 현황'!$L$4:$L$189,Z$2) -> 0 | AA12: =SUMIFS('구매 입고 현황'!$U$4:$U$189,'구매 입고 현황'!$E$4:$E$189,$X12,'구매 입고 현황'!$L$4:$L$189,AA$2) -> 0 | AB12: =SUMIFS('구매 입고 현황'!$U$4:$U$189,'구매 입고 현황'!$E$4:$E$189,$X12,'구매 입고 현황'!$L$4:$L$189,AB$2) -> 0 | AC12: =SUMIFS('구매 입고 현황'!$U$4:$U$189,'구매 입고 현황'!$E$4:$E$189,$X12,'구매 입고 현황'!$L$4:$L$189,AC$2) -> 0 | AD12: =SUMIFS('구매 입고 현황'!$U$4:$U$189,'구매 입고 현황'!$E$4:$E$189,$X12,'구매 입고 현황'!$L$4:$L$189,AD$2) -> 40365280 | AE12: =SUM(Y12:AD12) -> 40365280 | AF12: =AE12/$AE$46 -> 0.058018164
A13: 11 | B13: 미래로 | C13: =SUMIFS('구매 입고 현황'!$U$4:$U$189,'구매 입고 현황'!$E$4:$E$189,$B13,'구매 입고 현황'!$H$4:$H$189,C$2) -> 0 | D13: =SUMIFS('구매 입고 현황'!$U$4:$U$189,'구매 입고 현황'!$E$4:$E$189,$B13,'구매 입고 현황'!$H$4:$H$189,D$2) -> 0 | E13: =SUMIFS('구매 입고 현황'!$U$4:$U$189,'구매 입고 현황'!$E$4:$E$189,$B13,'구매 입고 현황'!$H$4:$H$189,E$2) -> 0 | F13: =SUMIFS('구매 입고 현황'!$U$4:$U$189,'구매 입고 현황'!$E$4:$E$189,$B13,'구매 입고 현황'!$H$4:$H$189,F$2) -> 0 | G13: =SUMIFS('구매 입고 현황'!$U$4:$U$189,'구매 입고 현황'!$E$4:$E$189,$B13,'구매 입고 현황'!$H$4:$H$189,G$2) -> 0 | H13: =SUMIFS('구매 입고 현황'!$U$4:$U$189,'구매 입고 현황'!$E$4:$E$189,$B13,'구매 입고 현황'!$H$4:$H$189,H$2) -> 0 | I13: =SUMIFS('구매 입고 현황'!$U$4:$U$189,'구매 입고 현황'!$E$4:$E$189,$B13,'구매 입고 현황'!$H$4:$H$189,I$2) -> 0 | J13: =SUMIFS('구매 입고 현황'!$U$4:$U$189,'구매 입고 현황'!$E$4:$E$189,$B13,'구매 입고 현황'!$H$4:$H$189,J$2) -> 0 | ... T13: =SUMIFS('구매 입고 현황'!$U$4:$U$189,'구매 입고 현황'!$E$4:$E$189,$B13,'구매 입고 현황'!$H$4:$H$189,T$2) -> 0 | U13: =SUM(C13:T13) -> 993409 | V13: =U13/$U$46 -> 0.0014344796 | W13: 11 | X13: 미래로 | Y13: =SUMIFS('구매 입고 현황'!$U$4:$U$189,'구매 입고 현황'!$E$4:$E$189,$X13,'구매 입고 현황'!$L$4:$L$189,Y$2) -> 0 | Z13: =SUMIFS('구매 입고 현황'!$U$4:$U$189,'구매 입고 현황'!$E$4:$E$189,$X13,'구매 입고 현황'!$L$4:$L$189,Z$2) -> 0 | AA13: =SUMIFS('구매 입고 현황'!$U$4:$U$189,'구매 입고 현황'!$E$4:$E$189,$X13,'구매 입고 현황'!$L$4:$L$189,AA$2) -> 0 | AB13: =SUMIFS('구매 입고 현황'!$U$4:$U$189,'구매 입고 현황'!$E$4:$E$189,$X13,'구매 입고 현황'!$L$4:$L$189,AB$2) -> 0 | AC13: =SUMIFS('구매 입고 현황'!$U$4:$U$189,'구매 입고 현황'!$E$4:$E$189,$X13,'구매 입고 현황'!$L$4:$L$189,AC$2) -> 0 | AD13: =SUMIFS('구매 입고 현황'!$U$4:$U$189,'구매 입고 현황'!$E$4:$E$189,$X13,'구매 입고 현황'!$L$4:$L$189,AD$2) -> 993409 | AE13: =SUM(Y13:AD13) -> 993409 | AF13: =AE13/$AE$46 -> 0.001427855
A14: 12 | B14: 바이슨 | C14: =SUMIFS('구매 입고 현황'!$U$4:$U$189,'구매 입고 현황'!$E$4:$E$189,$B14,'구매 입고 현황'!$H$4:$H$189,C$2) -> 0 | D14: =SUMIFS('구매 입고 현황'!$U$4:$U$189,'구매 입고 현황'!$E$4:$E$189,$B14,'구매 입고 현황'!$H$4:$H$189,D$2) -> 0 | E14: =SUMIFS('구매 입고 현황'!$U$4:$U$189,'구매 입고 현황'!$E$4:$E$189,$B14,'구매 입고 현황'!$H$4:$H$189,E$2) -> 0 | F14: =SUMIFS('구매 입고 현황'!$U$4:$U$189,'구매 입고 현황'!$E$4:$E$189,$B14,'구매 입고 현황'!$H$4:$H$189,F$2) -> 0 | G14: =SUMIFS('구매 입고 현황'!$U$4:$U$189,'구매 입고 현황'!$E$4:$E$189,$B14,'구매 입고 현황'!$H$4:$H$189,G$2) -> 0 | H14: =SUMIFS('구매 입고 현황'!$U$4:$U$189,'구매 입고 현황'!$E$4:$E$189,$B14,'구매 입고 현황'!$H$4:$H$189,H$2) -> 0 | I14: =SUMIFS('구매 입고 현황'!$U$4:$U$189,'구매 입고 현황'!$E$4:$E$189,$B14,'구매 입고 현황'!$H$4:$H$189,I$2) -> 0 | J14: =SUMIFS('구매 입고 현황'!$U$4:$U$189,'구매 입고 현황'!$E$4:$E$189,$B14,'구매 입고 현황'!$H$4:$H$189,J$2) -> 0 | ... T14: =SUMIFS('구매 입고 현황'!$U$4:$U$189,'구매 입고 현황'!$E$4:$E$189,$B14,'구매 입고 현황'!$H$4:$H$189,T$2) -> 5544000 | U14: =SUM(C14:T14) -> 5544000 | V14: =U14/$U$46 -> 0.0080055194 | W14: 12 | X14: 바이슨 | Y14: =SUMIFS('구매 입고 현황'!$U$4:$U$189,'구매 입고 현황'!$E$4:$E$189,$X14,'구매 입고 현황'!$L$4:$L$189,Y$2) -> 0 | Z14: =SUMIFS('구매 입고 현황'!$U$4:$U$189,'구매 입고 현황'!$E$4:$E$189,$X14,'구매 입고 현황'!$L$4:$L$189,Z$2) -> 0 | AA14: =SUMIFS('구매 입고 현황'!$U$4:$U$189,'구매 입고 현황'!$E$4:$E$189,$X14,'구매 입고 현황'!$L$4:$L$189,AA$2) -> 0 | AB14: =SUMIFS('구매 입고 현황'!$U$4:$U$189,'구매 입고 현황'!$E$4:$E$189,$X14,'구매 입고 현황'!$L$4:$L$189,AB$2) -> 0 | AC14: =SUMIFS('구매 입고 현황'!$U$4:$U$189,'구매 입고 현황'!$E$4:$E$189,$X14,'구매 입고 현황'!$L$4:$L$189,AC$2) -> 0 | AD14: =SUMIFS('구매 입고 현황'!$U$4:$U$189,'구매 입고 현황'!$E$4:$E$189,$X14,'구매 입고 현황'!$L$4:$L$189,AD$2) -> 5544000 | AE14: =SUM(Y14:AD14) -> 5544000 | AF14: =AE14/$AE$46 -> 0.0079685488
... A45: 43 | B45: 화인테크폴리머 | C45: =SUMIFS('구매 입고 현황'!$U$4:$U$189,'구매 입고 현황'!$E$4:$E$189,$B45,'구매 입고 현황'!$H$4:$H$189,C$2) -> 0 | D45: =SUMIFS('구매 입고 현황'!$U$4:$U$189,'구매 입고 현황'!$E$4:$E$189,$B45,'구매 입고 현황'!$H$4:$H$189,D$2) -> 0 | E45: =SUMIFS('구매 입고 현황'!$U$4:$U$189,'구매 입고 현황'!$E$4:$E$189,$B45,'구매 입고 현황'!$H$4:$H$189,E$2) -> 270000 | F45: =SUMIFS('구매 입고 현황'!$U$4:$U$189,'구매 입고 현황'!$E$4:$E$189,$B45,'구매 입고 현황'!$H$4:$H$189,F$2) -> 0 | G45: =SUMIFS('구매 입고 현황'!$U$4:$U$189,'구매 입고 현황'!$E$4:$E$189,$B45,'구매 입고 현황'!$H$4:$H$189,G$2) -> 0 | H45: =SUMIFS('구매 입고 현황'!$U$4:$U$189,'구매 입고 현황'!$E$4:$E$189,$B45,'구매 입고 현황'!$H$4:$H$189,H$2) -> 0 | I45: =SUMIFS('구매 입고 현황'!$U$4:$U$189,'구매 입고 현황'!$E$4:$E$189,$B45,'구매 입고 현황'!$H$4:$H$189,I$2) -> 0 | J45: =SUMIFS('구매 입고 현황'!$U$4:$U$189,'구매 입고 현황'!$E$4:$E$189,$B45,'구매 입고 현황'!$H$4:$H$189,J$2) -> 0 | ... T45: =SUMIFS('구매 입고 현황'!$U$4:$U$189,'구매 입고 현황'!$E$4:$E$189,$B45,'구매 입고 현황'!$H$4:$H$189,T$2) -> 1825000 | U45: =SUM(C45:T45) -> 2095000 | V45: =U45/$U$46 -> 0.0030251737 | W45: 43 | X45: 화인테크폴리머 | Y45: =SUMIFS('구매 입고 현황'!$U$4:$U$189,'구매 입고 현황'!$E$4:$E$189,$X45,'구매 입고 현황'!$L$4:$L$189,Y$2) -> 0 | Z45: =SUMIFS('구매 입고 현황'!$U$4:$U$189,'구매 입고 현황'!$E$4:$E$189,$X45,'구매 입고 현황'!$L$4:$L$189,Z$2) -> 0 | AA45: =SUMIFS('구매 입고 현황'!$U$4:$U$189,'구매 입고 현황'!$E$4:$E$189,$X45,'구매 입고 현황'!$L$4:$L$189,AA$2) -> 0 | AB45: =SUMIFS('구매 입고 현황'!$U$4:$U$189,'구매 입고 현황'!$E$4:$E$189,$X45,'구매 입고 현황'!$L$4:$L$189,AB$2) -> 0 | AC45: =SUMIFS('구매 입고 현황'!$U$4:$U$189,'구매 입고 현황'!$E$4:$E$189,$X45,'구매 입고 현황'!$L$4:$L$189,AC$2) -> 0 | AD45: =SUMIFS('구매 입고 현황'!$U$4:$U$189,'구매 입고 현황'!$E$4:$E$189,$X45,'구매 입고 현황'!$L$4:$L$189,AD$2) -> 2095000 | AE45: =SUM(Y45:AD45) -> 2095000 | AF45: =AE45/$AE$46 -> 0.003011203
B46: 매입 합계 | C46: =SUM(C3:C45) -> 97578370 | D46: =SUM(D3:D45) -> 0 | E46: =SUM(E3:E45) -> 192964710 | F46: =SUM(F3:F45) -> 90329985 | G46: =SUM(G3:G45) -> 2.0141316e+08 | H46: =SUM(H3:H45) -> 48432790 | I46: =SUM(I3:I45) -> 7446000 | J46: =SUM(J3:J45) -> 0 | ... V46: =SUM(V3:V45) -> 1 | X46: 매입 합계 | Y46: =SUM(Y3:Y45) -> 3213000 | Z46: =SUM(Z3:Z45) -> 880000 | AA46: =SUM(AA3:AA45) -> 0 | AB46: =SUM(AB3:AB45) -> 0 | AC46: =SUM(AC3:AC45) -> 0 | AD46: =SUM(AD3:AD45) -> 6.9164222e+08 | AE46: =SUM(AE3:AE45) -> 6.9573522e+08 | AF46: =SUM(AF3:AF45) -> 1
P48: 인터모빌리티 | R48: 인터모빌리티 | S48: 동화FA
B49: 수주 금액 (원) | C49: 423083700 | D49: 3942000 | E49: 350710750 | F49: 197810000 | G49: 351015169 | H49: 161717800 | I49: 270000000 | J49: 140000000 | K49: 2350000 | L49: 1300000 | M49: =M50*M51 -> 11087755 | N49: =N50*N51 -> 0 | O49: =O50*O51 -> 0 | P49: =36585000 -> 36585000 | R49: =26161000 -> 26161000 | S49: 50000000 | T49: =T46 -> 9049000 | U49: =SUM(C49:T49) -> 2.0348122e+09
B50: 수주 금액 (달러) | M50: 7573.5
B51: 적용 환율 (원) | M51: 1464.02
B52: (수주-매입) 이익 (원) | C52: =C49-C46 -> 325505330 | D52: =D49-D46 -> 3942000 | E52: =E49-E46 -> 157746040 | F52: =F49-F46 -> 1.0748001e+08 | G52: =G49-G46 -> 1.4960201e+08 | H52: =H49-H46 -> 113285010 | I52: =I49-I46 -> 262554000 | J52: =J49-J46 -> 140000000 | ... T52: =T49-T46 -> 0 | U52: =SUM(C52:T52) -> 1.34229e+09
B53: 이익율 (%) | C53: =C52/C49 -> 0.76936391 | D53: =D52/D49 -> 1 | E53: =E52/E49 -> 0.44978958 | F53: =F52/F49 -> 0.54334975 | G53: =G52/G49 -> 0.42619813 | H53: =H52/H49 -> 0.70051046 | I53: =I52/I49 -> 0.97242222 | J53: =J52/J49 -> 1 | ... U53: =U52/U49 -> 0.65966283
B55: 1. 구매 입고 현황 자료 작성시 표 내용 자동 업데이트 | X55: 1. 구매 입고 현황 자료 작성시 표 내용 자동 업데이트
B56: 2. 신규 업체 추가시 수동으로 목록 추가 | X56: 2. 신규 업체 추가시 수동으로 목록 추가
B57: 3. PO추가시 수동으로 목록 추가

Sheet 구매 입고 현황
A1: 비업시스 구매 입고 현황
K2: 45930 | M2: =SUBTOTAL(9,M4:M189) -> 6199 | O2: =SUBTOTAL(9,O4:O189) -> 656513351 | U2: =SUBTOTAL(9,U4:U189) -> 6.9573522e+08 | AB2: =SUBTOTAL(9,AB4:AB189) -> 6.9573522e+08 | AC2: =SUBTOTAL(9,AC4:AC189) -> 64359922 | AD2: =SUBTOTAL(9,AD4:AD189) -> 7.6009514e+08
A3: 순번 | B3: 구분 | C3: 계정과목 | D3: 발주 일자 (서명일 기준) | E3: 공급업체 | F3: 물품공급요청서 계약번호 | G3: 고객사 | H3: 고객사 PO번호 (계약번호) | I3: 프로젝트 (차량) | J3: 제 목 | K3: 품 목 | L3: 현 황 | M3: 발주 수량 | N3: 발주 단가 | O3: 발주 금액 | P3: 금액 단위 | Q3: 예상 납기일 | R3: 납기 | S3: 거래명세서 수취 여부 | T3: 입고 일자 (계약 종료일) | U3: 입고 금액 (원) | V3: 환율 | W3: 결제 조건 | X3: 결제 요청일 | Y3: 세금계산서 발행일 | Z3: 결제 완료일 | AA3: 부가세 및 공제 (%) | AB3: 결제 금액 (원) | AC3: 부가세 및 공제 (원) | AD3: 결제 총 금액 (원) | AE3: 비고 | AF3: 자료 서버 경로
A4: 1 | B4: 프리랜서 | C4: 인건비 | D4: 45392 | E4: 이동진 | F4: 제BEUP KNK24-0410-1호 | G4: 지아이씨 | H4: GIC CSP24-0524-2호 | I4: 홍콩MTR 333량 | J4: 방송장치 하드웨어 및 문서 | K4: 하드웨어 구매 및 테스트절차정리 | L4: 결제완료 | M4: 1 | O4: 5000000 | P4: 원 | Q4: 45657 | T4: 45644 | U4: =O4*V4 -> 5000000 | V4: 1 | W4: 구매등완료후 | Y4: - | Z4: 45657 | AA4: -0.033 | AB4: =U4 -> 5000000 | AC4: =AB4*AA4 -> -165000 | AD4: =SUM(AB4:AC4) -> 4835000 | AE4: 사업소득세 3.3% 공제 | AF4: 1_BEUPSYS\5-1_업체구매요청서\1_부품구매요청서및계약서\프리렌서계약_이동진\GIC CSP24-0524-2호_PSR-Hub외9종생산
A5: 2 | B5: 구매 | C5: 원자재 | D5: 45413 | E5: 일렉콤티에스 | F5: BEUPIDOM-20240501 | G5: 지아이씨 | H5: GIC CSP24-0409-1호 | I5: 홍콩MTR 333량 | J5: 홍콩 생산1차분 83종 자재 | K5: 홍콩 생산1차분 83종 자재 선금 (30%) | L5: 결제완료 | M5: 1 | O5: 6874012.7 | P5: 원 | T5: 45428 | U5: =O5*V5 -> 6874012.7 | V5: 1 | W5: 선금 30% | Z5: 45428 | AA5: 0.1 | AB5: =U5 -> 6874012.7 | AC5: =AB5*AA5 -> 687401.27 | AD5: =SUM(AB5:AC5) -> 7561414 | AE5: 네이버 게시판 자료
A6: 3 | B6: 구매 | C6: 원자재 | D6: 45413 | E6: 일렉콤티에스 | F6: BEUPIDOM-20240501 | G6: 지아이씨 | H6: GIC CSP24-0409-1호 | I6: 홍콩MTR 333량 | J6: 홍콩 생산1차분 83종 자재 | K6: 홍콩 생산1차분 83종 자재 납품 (70%) | L6: 결제완료 | M6: 1 | O6: 16039357 | P6: 원 | T6: 45436 | U6: =O6*V6 -> 16039357 | V6: 1 | W6: 잔금 70% | Z6: 45436 | AA6: 0.1 | AB6: =U6 -> 16039357 | AC6: =AB6*AA6 -> 1603935.7 | AD6: =SUM(AB6:AC6) -> 17643293 | AE6: 네이버 게시판 자료
A7: 4 | B7: 구매 | C7: 원자재 | D7: 45414 | E7: 앤츠 | F7: BEUPIDOM-20240502 | G7: 지아이씨 | H7: GIC CSP24-0409-1호 | I7: 홍콩MTR 333량 | J7: LEDC BOARD 외 | K7: LEDC BOARD 외 선금 (30%) | L7: 결제완료 | M7: 1 | O7: 18780000 | P7: 원 | T7: 45429 | U7: =O7*V7 -> 18780000 | V7: 1 | W7: 선금 30% | Z7: 45431 | AA7: 0.1 | AB7: =U7 -> 18780000 | AC7: =AB7*AA7 -> 1878000 | AD7: =SUM(AB7:AC7) -> 20658000 | AE7: 네이버 게시판 자료
A8: 5 | B8: 구매 | C8: 원자재 | D8: 45414 | E8: 앤츠 | F8: BEUPIDOM-20240502 | G8: 지아이씨 | H8: GIC CSP24-0409-1호 | I8: 홍콩MTR 333량 | J8: LEDC BOARD 외 | K8: LEDC BOARD 외 납품 (70%) | L8: 결제완료 | M8: 1 | O8: 43820000 | P8: 원 | T8: 45505 | U8: =O8*V8 -> 43820000 | V8: 1 | W8: 잔금 70% | Z8: 45506 | AA8: 0.1 | AB8: =U8 -> 43820000 | AC8: =AB8*AA8 -> 4382000 | AD8: =SUM(AB8:AC8) -> 48202000 | AE8: 네이버 게시판 자료
A9: 6 | B9: 구매 | C9: 임가공 | D9: 45415 | E9: 메카전자 | F9: BEUPIDOM-20240503 | G9: 지아이씨 | H9: GIC CSP24-0409-1호 | I9: 홍콩MTR 333량 | J9: MRX REV1.2 생산 외 | K9: MRX REV1.2 생산 외 선금 (30%) | L9: 결제완료 | M9: 1 | O9: 2112000 | P9: 원 | T9: 45431 | U9: =O9*V9 -> 2112000 | V9: 1 | W9: 선금 30% | Z9: 45431 | AA9: 0.1 | AB9: =U9 -> 2112000 | AC9: =AB9*AA9 -> 211200 | AD9: =SUM(AB9:AC9) -> 2323200 | AE9: 네이버 게시판 자료
A10: 7 | B10: 구매 | C10: 임가공 | D10: 45415 | E10: 메카전자 | F10: BEUPIDOM-20240503 | G10: 지아이씨 | H10: GIC CSP24-0409-1호 | I10: 홍콩MTR 333량 | J10: MRX REV1.2 생산 외 | K10: MRX REV1.2 생산 외 납품 (70%) | L10: 결제완료 | M10: 1 | O10: 4928000 | P10: 원 | T10: 45456 | U10: =O10*V10 -> 4928000 | V10: 1 | W10: 잔금 70% | Z10: 45457 | AA10: 0.1 | AB10: =U10 -> 4928000 | AC10: =AB10*AA10 -> 492800 | AD10: =SUM(AB10:AC10) -> 5420800 | AE10: 네이버 게시판 자료
A11: 8 | B11: 구매 | C11: 원자재 | D11: 45432 | E11: 에쎈 | F11: BEUPIDOM-20240504 | G11: 지아이씨 | H11: GIC CSP24-0409-1호 | I11: 홍콩MTR 333량 | J11: EIDS LCD 강화유리 | K11: 27인치 3T AG 강화유리 | L11: 결제완료 | M11: 50 | N11: 45500 | O11: =M11*N11 -> 2275000 | P11: 원 | U11: =O11*V11 -> 2275000 | V11: 1 | Z11: 45440 | AA11: 0.1 | AB11: =U11 -> 2275000 | AC11: =AB11*AA11 -> 227500 | AD11: =SUM(AB11:AC11) -> 2502500 | AE11: 네이버 게시판 자료
A12: 9 | B12: 구매 | C12: 원자재 | D12: 45435 | E12: 파츠맨 | F12: BEUPIDOM-20240505 | G12: 지아이씨 | H12: GIC CSP24-0524-1호 | I12: 홍콩MTR 333량 | J12: 홍콩 방송장치 11종 보드 부품 | K12: 홍콩 방송장치 11종 보드 부품 선금 (38%) | L12: 결제완료 | M12: 1 | O12: 16197119 | P12: 원 | T12: 45440 | U12: =O12*V12 -> 16197119 | V12: 1 | W12: 선금 약 38% | Z12: 45440 | AA12: 0.1 | AB12: =U12 -> 16197119 | AC12: =AB12*AA12 -> 1619711.9 | AD12: =SUM(AB12:AC12) -> 17816831 | AE12: 네이버 게시판 자료
A13: 10 | B13: 구매 | C13: 원자재 | D13: 45435 | E13: 파츠맨 | F13: BEUPIDOM-20240505 | G13: 지아이씨 | H13: GIC CSP24-0524-1호 | I13: 홍콩MTR 333량 | J13: 홍콩 방송장치 11종 보드 부품 | K13: 홍콩 방송장치 11종 보드 부품 납품 (62%) | L13: 결제완료 | M13: 1 | O13: 26496461 | P13: 원 | T13: 45497 | U13: =O13*V13 -> 26496461 | V13: 1 | W13: 잔금 약 62% | Z13: 45497 | AA13: 0.1 | AB13: =U13 -> 26496461 | AC13: =AB13*AA13 -> 2649646.1 | AD13: =SUM(AB13:AC13) -> 29146107 | AE13: 네이버 게시판 자료
A14: 11 | B14: 구매 | C14: 원자재 | D14: 45435 | E14: 태신전자 | F14: BEUPIDOM-20240506 | G14: 지아이씨 | H14: GIC CSP24-0524-1호 | I14: 홍콩MTR 333량 | J14: 홍콩 방송장치 11종 PCB | K14: 홍콩 방송장치 11종 PCB 선금 (30%) | L14: 결제완료 | M14: 1 | O14: =6213300*0.3 -> 1863990 | P14: 원 | T14: 45436 | U14: =O14*V14 -> 1863990 | V14: 1 | W14: 선금 30% | Z14: 45436 | AA14: 0.1 | AB14: =U14 -> 1863990 | AC14: =AB14*AA14 -> 186399 | AD14: =SUM(AB14:AC14) -> 2050389 | AE14: 네이버 게시판 자료
A15: 12 | B15: 구매 | C15: 원자재 | D15: 45435 | E15: 태신전자 | F15: BEUPIDOM-20240506 | G15: 지아이씨 | H15: GIC CSP24-0524-1호 | I15: 홍콩MTR 333량 | J15: 홍콩 방송장치 11종 PCB | K15: 홍콩 방송장치 11종 PCB 납품 (70%) | L15: 결제완료 | M15: 1 | O15: =6213300*0.7 -> 4349310 | P15: 원 | T15: 45462 | U15: =O15*V15 -> 4349310 | V15: 1 | W15: 잔금 70% | Z15: 45462 | AA15: 0.1 | AB15: =U15 -> 4349310 | AC15: =AB15*AA15 -> 434931 | AD15: =SUM(AB15:AC15) -> 4784241 | AE15: 네이버 게시판 자료
A16: 13 | B16: 구매 | C16: 원자재 | D16: 45453 | E16: 한톨브릿지 | F16: BEUPIDOM-20240601 | G16: 지아이씨 | H16: GIC CSP24-0524-2호 | I16: 홍콩MTR 333량 | J16: AC494 TOOL 및 자재 | K16: AC494-IPP-SUK 외 | L16: 결제완료 | M16: 1 | O16: 24200 | P16: $ | R16: 발주후 4주내 | U16: =O16*V16 -> 30474085 | V16: 1259.2597 | W16: 선금 100% | AA16: 0.1 | AB16: =U16 -> 30474085 | AC16: =AB16*AA16 -> 3047408.5 | AD16: =SUM(AB16:AC16) -> 33521494 | AE16: 네이버 게시판 자료, 환율(1259.25973), AUDIOCODES 지급
A17: 14 | B17: 구매 | C17: 원자재 | D17: 45453 | E17: 이엔엠테크놀러지 | F17: BEUPIDOM-20240602 | G17: 지아이씨 | H17: GIC CSP24-0923-1호 | I17: 홍콩MTR 333량 | J17: congatec BOARD | K17: TC570/i3-1115GRE 외 | L17: 결제완료 | M17: 1 | O17: 2409000 | P17: 원 | T17: 45462 | U17: =O17*V17 -> 2409000 | V17: 1 | Z17: 45462 | AA17: 0.1 | AB17: =U17 -> 2409000 | AC17: =AB17*AA17 -> 240900 | AD17: =SUM(AB17:AC17) -> 2649900 | AE17: 네이버 게시판 자료
A18: 15 | B18: 외주 | C18: 개발 | D18: 45458 | E18: 드림온테크 유한회사 | F18: 제BEUP KNK24-0615-1호 | G18: 지아이씨 | H18: GIC CSP24-0524-1호 | I18: 홍콩MTR 333량 | J18: NVR/CTM H/W개발 계약 | K18: NVR/CTM H/W개발 계약 선금 (40%) | L18: 결제완료 | M18: 1 | O18: 32000000 | P18: 원 | S18: O | T18: 45469 | U18: =O18*V18 -> 32000000 | V18: 1 | W18: 선금 40% | Z18: 45470 | AA18: 0.1 | AB18: =U18 -> 32000000 | AC18: =AB18*AA18 -> 3200000 | AD18: =SUM(AB18:AC18) -> 35200000 | AF18: 1_BEUPSYS\5-1_업체구매요청서\1_부품구매요청서및계약서\드림온테크 유한회사\240524_GIC CSP24-0524-1호_MOP외2종생산
A19: 16 | B19: 외주 | C19: 개발 | D19: 45458 | E19: 드림온테크 유한회사 | F19: 제BEUP KNK24-0615-1호 | G19: 지아이씨 | H19: GIC CSP24-0524-1호 | I19: 홍콩MTR 333량 | J19: NVR/CTM H/W개발 계약 | K19: NVR/CTM H/W개발 계약 1차 (30%) | L19: 결제완료 | M19: 1 | O19: 24000000 | P19: 원 | S19: O | T19: 45622 | U19: =O19*V19 -> 24000000 | V19: 1 | W19: 중도금(중간결과물 NVR 3대 전달) 30% | Y19: 45622 | Z19: 45625 | AA19: 0.1 | AB19: =U19 -> 24000000 | AC19: =AB19*AA19 -> 2400000 | AD19: =SUM(AB19:AC19) -> 26400000 | AF19: 1_BEUPSYS\5-1_업체구매요청서\1_부품구매요청서및계약서\드림온테크 유한회사\240524_GIC CSP24-0524-1호_MOP외2종생산
A20: 17 | B20: 외주 | C20: 개발 | D20: 45458 | E20: 드림온테크 유한회사 | F20: 제BEUP KNK24-0615-1호 | G20: 지아이씨 | H20: GIC CSP24-0524-1호 | I20: 홍콩MTR 333량 | J20: NVR/CTM H/W개발 계약 | K20: NVR/CTM H/W개발 계약 2차 (30%) | L20: 결제완료 | M20: 1 | O20: 24000000 | P20: 원 | S20: O | T20: 45681 | U20: =O20*V20 -> 24000000 | V20: 1 | W20: 잔금 30% | X20: 45693 | Z20: 45694 | AA20: 0.1 | AB20: =U20 -> 24000000 | AC20: =AB20*AA20 -> 2400000 | AD20: =SUM(AB20:AC20) -> 26400000 | AF20: 1_BEUPSYS\5-1_업체구매요청서\1_부품구매요청서및계약서\드림온테크 유한회사\240524_GIC CSP24-0524-1호_MOP외2종생산
A21: 18 | B21: 구매 | C21: 원자재 | D21: 45474 | E21: 이젠티에스 | F21: BEUPIDOM-20240701 | G21: 지아이씨 | H21: GIC CSP24-0923-1호 | I21: 홍콩MTR 333량 | J21: TSC-50/IC | K21: TSC-50/IC | L21: 결제완료 | M21: 70 | N21: 6000 | O21: =M21*N21 -> 420000 | P21: 원 | U21: =O21*V21 -> 420000 | V21: 1 | Z21: 45474 | AA21: 0.1 | AB21: =U21 -> 420000 | AC21: =AB21*AA21 -> 42000 | AD21: =SUM(AB21:AC21) -> 462000 | AE21: 네이버 게시판 자료
A22: 19 | B22: 구매 | C22: 원자재 | D22: 45475 | E22: 파이오닉스 | F22: BEUPIDOM-20240702 | G22: 지아이씨 | H22: GIC CSP24-0913-1호 | I22: 홍콩MTR 333량 | J22: CH7517A-BF1 | K22: CH7517A-BF1 | L22: 결제완료 | M22: 140 | N22: 4.9 | O22: =M22*N22 -> 686 | P22: $ | U22: =O22*V22 -> 941260.6 | V22: 1372.1 | AA22: 0.1 | AB22: =U22 -> 941260.6 | AC22: =AB22*AA22 -> 94126.06 | AD22: =SUM(AB22:AC22) -> 1035386.7 | AE22: 네이버 게시판 자료
A23: 20 | B23: 구매 | C23: 기타 | D23: 45475 | E23: 파이오닉스 | F23: - | G23: 지아이씨 | H23: GIC CSP24-0913-1호 | I23: 홍콩MTR 333량 | J23: Production H/C | K23: Production H/C | L23: 결제완료 | M23: 1 | N23: 150 | O23: =M23*N23 -> 150 | P23: $ | U23: =O23*V23 -> 205815 | V23: 1372.1 | AA23: 0.1 | AB23: =U23 -> 205815 | AC23: =AB23*AA23 -> 20581.5 | AD23: =SUM(AB23:AC23) -> 226396.5 | AE23: 네이버 게시판 자료
A24: 21 | B24: 구매 | C24: 기타 | D24: 45475 | E24: 파이오닉스 | F24: - | G24: 지아이씨 | H24: GIC CSP24-0913-1호 | I24: 홍콩MTR 333량 | J24: 운송비 | K24: 운송비 | L24: 결제완료 | M24: 1 | N24: 124980 | O24: =M24*N24 -> 124980 | P24: 원 | U24: =O24*V24 -> 124980 | V24: 1 | AA24: 0.1 | AB24: =U24 -> 124980 | AC24: =AB24*AA24 -> 12498 | AD24: =SUM(AB24:AC24) -> 137478 | AE24: 네이버 게시판 자료
A25: 22 | B25: 구매 | C25: 원자재 | D25: 45476 | E25: 티렉스아이앤씨 | F25: BEUPIDOM-20240703 | G25: 지아이씨 | H25: GIC CSP24-0923-1호 | I25: 홍콩MTR 333량 | J25: LVDS Cable 외 | K25: LVDS Cable 외 | L25: 결제완료 | M25: 1 | O25: 1680000 | P25: 원 | U25: =O25*V25 -> 1680000 | V25: 1 | AA25: 0.1 | AB25: =U25 -> 1680000 | AC25: =AB25*AA25 -> 168000 | AD25: =SUM(AB25:AC25) -> 1848000 | AE25: 네이버 게시판 자료
A26: 23 | B26: 구매 | C26: 원자재 | D26: 45477 | E26: 이엔엠테크놀러지 | F26: BEUPIDOM-20240704 | G26: 지아이씨 | H26: GIC CSP24-0923-1호 | I26: 홍콩MTR 333량 | J26: congatec BOARD | K26: TC170/i7-6600U 외 | L26: 결제완료 | M26: 1 | O26: 1626700 | P26: 원 | U26: =O26*V26 -> 1626700 | V26: 1 | Z26: 45471 | AA26: 0.1 | AB26: =U26 -> 1626700 | AC26: =AB26*AA26 -> 162670 | AD26: =SUM(AB26:AC26) -> 1789370 | AE26: 네이버 게시판 자료
A27: 24 | B27: 구매 | C27: 원자재 | D27: 45495 | E27: 유니퀘스트 | F27: 제BEUP JDS24-0722-1호 | G27: 지아이씨 | H27: GIC CSP24-0524-1호 | I27: 홍콩MTR 333량 | J27: SSD 64GB BGA TLC SATA | K27: SM619GECDFSTCX59C | L27: 결제완료 | M27: 180 | N27: 27.5 | O27: =M27*N27 -> 4950 | P27: $ | Q27: 45635 | R27: 발주 후 20주내 | T27: 확인불가 | U27: =O27*V27 -> 6637950 | V27: 1341 | W27: 입금 후 1주일 내 물품발송 환율은 납품 시 고시가로 | Z27: 45545 | AA27: 0.1 | AB27: =U27 -> 6637950 | AC27: =AB27*AA27 -> 663795 | AD27: =SUM(AB27:AC27) -> 7301745 | AE27: 네이버 게시판 자료, $4,950 | AF27: 1_BEUPSYS\5-1_업체구매요청서\1_부품구매요청서및계약서\유니퀘스트㈜\240524_GIC CSP24-0524-1호_MOP외2종생산
A28: 25 | B28: 구매 | C28: 원자재 | D28: 45488 | E28: 화인테크폴리머 | F28: - | G28: - | H28: 없음 | I28: 홍콩MTR 333량 | J28: 실리콘 시트 | K28: 난연 SILICONE 백색 (도번: R1D013805) | L28: 결제완료 | M28: 1 | N28: 800000 | O28: =M28*N28 -> 800000 | P28: 원 | U28: =O28*V28 -> 800000 | V28: 1 | AA28: 0.1 | AB28: =U28 -> 800000 | AC28: =AB28*AA28 -> 80000 | AD28: =SUM(AB28:AC28) -> 880000 | AE28: 누락
A29: 26 | B29: 구매 | C29: 원자재 | D29: 45488 | E29: 화인테크폴리머 | F29: - | G29: - | H29: 없음 | I29: 홍콩MTR 333량 | J29: EPDM SEALING FOAM | K29: EPDM SEALING FOAM 1T*5*614 | L29: 결제완료 | M29: 100 | N29: 950 | O29: =M29*N29 -> 95000 | P29: 원 | U29: =O29*V29 -> 95000 | V29: 1 | AA29: 0.1 | AB29: =U29 -> 95000 | AC29: =AB29*AA29 -> 9500 | AD29: =SUM(AB29:AC29) -> 104500 | AE29: 누락
A30: 27 | B30: 구매 | C30: 원자재 | D30: 45488 | E30: 화인테크폴리머 | F30: - | G30: - | H30: 없음 | I30: 홍콩MTR 333량 | J30: EPDM SEALING FOAM | K30: EPDM SEALING FOAM 1T*5*342 | L30: 결제완료 | M30: 100 | N30: 550 | O30: =M30*N30 -> 55000 | P30: 원 | U30: =O30*V30 -> 55000 | V30: 1 | AA30: 0.1 | AB30: =U30 -> 55000 | AC30: =AB30*AA30 -> 5500 | AD30: =SUM(AB30:AC30) -> 60500 | AE30: 누락
A31: 28 | B31: 구매 | C31: 원자재 | D31: 45488 | E31: 화인테크폴리머 | F31: - | G31: - | H31: 없음 | I31: 홍콩MTR 333량 | J31: SPK GASKET | K31: SPEAKER EPDM GASKET 6T*41*71 | L31: 결제완료 | M31: 50 | N31: 1500 | O31: =M31*N31 -> 75000 | P31: 원 | U31: =O31*V31 -> 75000 | V31: 1 | AA31: 0.1 | AB31: =U31 -> 75000 | AC31: =AB31*AA31 -> 7500 | AD31: =SUM(AB31:AC31) -> 82500 | AE31: 누락
A32: 29 | B32: 구매 | C32: 원자재 | D32: 45488 | E32: 화인테크폴리머 | F32: - | G32: - | H32: 없음 | I32: 홍콩MTR 333량 | J32: 금형 | K32: 금형 | L32: 결제완료 | M32: 1 | N32: 800000 | O32: =M32*N32 -> 800000 | P32: 원 | U32: =O32*V32 -> 800000 | V32: 1 | AA32: 0.1 | AB32: =U32 -> 800000 | AC32: =AB32*AA32 -> 80000 | AD32: =SUM(AB32:AC32) -> 880000 | AE32: 누락
A33: 30 | B33: 구매 | C33: 원자재 | D33: 45496 | E33: 이송이엠씨 | F33: - | G33: - | H33: 없음 | I33: 홍콩MTR 333량 | J33: 도전성 원단 (먼지필터) | K33: SM-W18B (1000mm*100M/RL) | L33: 결제완료 | M33: 1 | N33: 1500000 | O33: =M33*N33 -> 1500000 | P33: 원 | U33: =O33*V33 -> 1500000 | V33: 1 | W33: 첫거래 선금 | AA33: 0.1 | AB33: =U33 -> 1500000 | AC33: =AB33*AA33 -> 150000 | AD33: =SUM(AB33:AC33) -> 1650000 | AE33: 누락
A34: 31 | B34: 구매 | C34: 원자재 | D34: 45496 | E34: 이송이엠씨 | F34: - | G34: - | H34: 없음 | I34: 홍콩MTR 333량 | J34: 폼가스켓 | K34: SF050020R-C-NB-A (W5*T2*L1000mm) | L34: 결제완료 | M34: 100 | N34: 1800 | O34: =M34*N34 -> 180000 | P34: 원 | U34: =O34*V34 -> 180000 | V34: 1 | W34: 첫거래 선금 | AA34: 0.1 | AB34: =U34 -> 180000 | AC34: =AB34*AA34 -> 18000 | AD34: =SUM(AB34:AC34) -> 198000 | AE34: 누락
A35: 32 | B35: 구매 | C35: 장비 | D35: 45525 | E35: 아이닉스 | F35: 제BEUP JDS24-0821-1호 | G35: 지아이씨 | H35: GIC CSP24-0524-2호 | I35: 홍콩MTR 333량 | J35: Coding 공구 | K35: Coding Pliers 894-301 | L35: 결제완료 | M35: 1 | O35: 788000 | P35: 원 | Q35: 45553 | R35: 발주 후 4주내 | S35: O | T35: 45539 | U35: =O35*V35 -> 788000 | V35: 1 | W35: 납품 후 지급 | Y35: 45539 | Z35: 45569 | AA35: 0.1 | AB35: =U35 -> 788000 | AC35: =AB35*AA35 -> 78800 | AD35: =SUM(AB35:AC35) -> 866800 | AF35: 1_BEUPSYS\5-1_업체구매요청서\1_부품구매요청서및계약서\아이닉스\GIC CSP24-0524-2호_PSR-Hub외9종생산
A36: 33 | B36: 구매 | C36: 원자재 | D36: 45532 | E36: 파츠맨 | F36: 제BEUP JDS24-0828-2호 | G36: 지아이씨 | H36: GIC CSP24-0524-2호 | I36: 홍콩MTR 333량 | J36: 2024년 8월 부자재류 | K36: 2024년 8월 부자재류 | L36: 결제완료 | M36: 1 | O36: 982500 | P36: 원 | Q36: 45542 | R36: 발주 후 10일 | S36: O | T36: 45532 | U36: =O36*V36 -> 982500 | V36: 1 | W36: 물품납기시 | Y36: 45532 | Z36: 45545 | AA36: 0.1 | AB36: =U36 -> 982500 | AC36: =AB36*AA36 -> 98250 | AD36: =SUM(AB36:AC36) -> 1080750 | AF36: 1_BEUPSYS\5-1_업체구매요청서\1_부품구매요청서및계약서\파츠맨\GIC CSP24-0524-2호_PSR-Hub외9종생산\8월자재진행
A37: 34 | B37: 구매 | C37: 임가공 | D37: 45541 | E37: 아이리코 | F37: 제BEUP JDS24-0828-1호 | G37: 지아이씨 | H37: GIC CSP24-0524-2호 | I37: 홍콩MTR 333량 | J37: PCB 코팅 | K37: HK향 PCB코팅 10종 | L37: 결제완료 | M37: 1 | O37: 8274400 | P37: 원 | Q37: 45681 | R37: 발주 후 20주내 | S37: O | T37: 45534 | U37: =O37*V37 -> 8274400 | V37: 1 | W37: 제작완료시 지급 | Y37: 45535 | Z37: 45545 | AA37: 0.1 | AB37: =U37 -> 8274400 | AC37: =AB37*AA37 -> 827440 | AD37: =SUM(AB37:AC37) -> 9101840 | AF37: 1_BEUPSYS\5-1_업체구매요청서\1_부품구매요청서및계약서\아이리코(I RICCO)\241016_GIC CSP24-0524-2호_PSR-Hub외9종생산\Board 코팅
A38: 35 | B38: 구매 | C38: 임가공 | D38: 45544 | E38: 일성 | F38: 제BEUP JDS24-0522-1호 | G38: 지아이씨 | H38: GIC CSP24-0524-2호 | I38: 홍콩MTR 333량 | J38: 홍콩 PBA 11종 조립 | K38: 홍콩 PBA 11종 조립 선금 (30%) | L38: 결제완료 | M38: 1 | O38: 9015600 | P38: 원 | Q38: 45684 | R38: 발주 후 20주내 | S38: O | T38: 45427 | U38: =O38*V38 -> 9015600 | V38: 1 | W38: 선금 30% | Y38: - | Z38: 45440 | AA38: 0.1 | AB38: =U38 -> 9015600 | AC38: =AB38*AA38 -> 901560 | AD38: =SUM(AB38:AC38) -> 9917160 | AF38: 1_BEUPSYS\5-1_업체구매요청서\1_부품구매요청서및계약서\(주)일성\GIC CSP24-0524-2호_PSR-Hub외9종생산
A39: 36 | B39: 구매 | C39: 임가공 | D39: 45544 | E39: 일성 | F39: 제BEUP JDS24-0522-1호 | G39: 지아이씨 | H39: GIC CSP24-0524-2호 | I39: 홍콩MTR 333량 | J39: 홍콩 PBA 11종 조립 | K39: 홍콩 PBA 11종 조립 1차 납품 (40%) | L39: 결제완료 | M39: 1 | O39: 12020800 | P39: 원 | Q39: 45684 | R39: 발주 후 20주내 | S39: O | T39: 45516 | U39: =O39*V39 -> 12020800 | V39: 1 | W39: 1차 납품 40% | Y39: 45534 | Z39: 45548 | AA39: 0.1 | AB39: =U39 -> 12020800 | AC39: =AB39*AA39 -> 1202080 | AD39: =SUM(AB39:AC39) -> 13222880 | AF39: 1_BEUPSYS\5-1_업체구매요청서\1_부품구매요청서및계약서\(주)일성\GIC CSP24-0524-2호_PSR-Hub외9종생산
A40: 37 | B40: 구매 | C40: 임가공 | D40: 45544 | E40: 일성 | F40: 제BEUP JDS24-0522-1호 | G40: 지아이씨 | H40: GIC CSP24-0524-2호 | I40: 홍콩MTR 333량 | J40: 홍콩 PBA 11종 조립 | K40: 홍콩 PBA 11종 조립 2차 납품 (30%) | L40: 결제완료 | M40: 1 | O40: 9015600 | P40: 원 | Q40: 45684 | R40: 발주 후 20주내 | S40: O | T40: 45585 | U40: =O40*V40 -> 9015600 | V40: 1 | W40: 2차 납품 30% | Y40: 45596 | Z40: 45604 | AA40: 0.1 | AB40: =U40 -> 9015600 | AC40: =AB40*AA40 -> 901560 | AD40: =SUM(AB40:AC40) -> 9917160 | AF40: 1_BEUPSYS\5-1_업체구매요청서\1_부품구매요청서및계약서\(주)일성\GIC CSP24-0524-2호_PSR-Hub외9종생산
...

Sheet 참고
A1: 발주예정
A2: 발주완료
A3: 발주취소 | I3: 공급업체
A4: 입고완료 | I4: 고은효 | J4: 1
A5: 결제완료 | I5: 김민석 | J5: 2
B6: 품목 | C6: 수량 | D6: 단가 | E6: 금액 | I6: 김재현 | J6: 3
B7: PCB | C7: 200 | D7: 1670 | E7: =C7*D7 -> 334000 | I7: 나무 | M7: 1
B8: SMD | C8: 10 | D8: 40100 | E8: =C8*D8 -> 401000 | I8: 대성프로파일
B9: 수삽 | E9: =C9*D9 -> 0 | I9: 대현테크 | J9: 4
B10: 자재 | E10: =C10*D10 -> 0 | I10: 드림온테크 유한회사 | J10: 5
D11: =SUM(D7:D10) -> 41770 | E11: =SUM(E7:E10) -> 735000 | I11: 디에스테크놀러지 | J11: 6
I12: 만능
C13: 80 | D13: =D11 -> 41770 | E13: =C13*D13 -> 3341600 | I13: 메카전자 | J13: 7
I14: 미래로 | J14: 8
I15: 바이슨 | J15: 9
B16: Z:\1_BEUPSYS\5-1_업체구매요청서\1_부품구매요청서및계약서\㈜메카전자\GIC CSP24-0913-1호 NVRCTMMSR 3종생산\ZEUSCPU생산 | I16: 박진호 | J16: 10
I17: 세일엔지니어링 | J17: 11
I18: 아이닉스 | J18: 12
D19: 7561414 | E19: =D19/11*10 -> 6874012.7 | I19: 아이리코 | J19: 13
D20: 17643293 | E20: =D20/11*10 -> 16039357 | I20: 앤츠 | J20: 14
E21: =SUM(E19:E20) -> 22913370 | I21: 에쎈 | J21: 15
I22: 엔에스티정보통신 | J22: 16
I23: 우석케미칼 | J23: 17
I24: 위존
E25: 6874012.7 | I25: 유니퀘스트 | J25: 18
E26: 16039357 | I26: 유로
I27: 유에스케이 | J27: 19
I28: 이노웍스코리아 | J28: 20
I29: 이동진 | J29: 21
I30: 이송이엠씨 | J30: 22
C31: =D31/D33 -> 0.37938067 | D31: 16197119 | I31: 이엔엠테크놀러지 | J31: 23
C32: =D32/D33 -> 0.62061933 | D32: 26496461 | I32: 이예준 | J32: 24
C33: =D33/D35 -> 8624.9657 | D33: =SUM(D31:D32) -> 42693580 | I33: 이젠티에스 | J33: 25
I34: 이지파워 | J34: 26
D35: 4950 | I35: 일렉콤티에스 | J35: 27
D36: 6637950 | I36: 일성 | J36: 28
D37: =D36/D35 -> 1341 | I37: 캐드존 | J37: 29
I38: 태신전자 | J38: 30
I39: 텍시트코리아 | J39: 31
D40: 33521494 | E40: =D40/11*10 -> 30474085 | I40: 티렉스아이앤씨 | J40: 32
...
